Workbook

Sheet Medicaid (2)
B1: Medicaid
B2: Methodology: The BEA gives us historical data on total Medicaid spending and federal Medicaid spending (in the form of grants to states). In order to project federal and state Medicaid spending separately, we need to know the federal share of total Medicaid spending (the FMAP). In Table 1, we calculate our quarterly FMAP using the ratio of federal to total spending from the BEA data in the historical period. Our projection of the FMAP (without the effects of the American Rescue Plan) is determined as follows: from 2021 Q3 to 2022 Q3 (when we assume the enhanced FMAP from pandemic legislation turns off because our guess of the end of the public health emergency), we take the average of the 2020 Q4 and 2021 Q1 FMAPs; in 2022 Q3 and onwards, we take the average of FY 2019 quarters (2018 Q4 - 2019 Q3). Our projection of the FMAP (accounting for the effects of ARP) is determined differently, incorporating a temporary increase in the FMAP from the expansion of ACA coverage, the 100% FMAP for urban, indian, and Hawaiian organizations, and a temporary increase in the FMAP for expanding HCBS (all from ARP). We take the sum of the values of these changes as a share of total pre-ARP medicaid to estimate their effects on the FMAP. We add these effects for each quarter to get the post-ARP FMAP. In Table 2, we calculate the annual growth rate of total Medicaid spending in the projection period. We back out projected annual total Medicaid spending by dividing CBO's projected federal Medicaid outlays by the annual FMAP (defined as the average of the quarterly FMAP by fiscal year), and use this to get the annual growth rate of total Medicaid spending. In Table 3, we project forward the quarterly total Medicaid from BEA using the deannualized growth rate from Table 2, and use our projected quarterly FMAP to back out quarterly federal and state Medicaid spending. | V2: Quarterly FMAP = Federal Medicaid grants/ Total Medicaid spending Annual FMAP = Average Quarterly FMAP for the Fiscal Year (Q4-Q3) Total Medicaid in fiscal year = CBO projection of Medicaid Outlays/ Annual FMAP Total Medicaid annual growth rate =(Total Medicaid_t / Total Medicaid_t-1) -1 Total Medicaid projection = Total Medicaid spending*(1+Total Medicaid Annual Growth Rate)^(0.25) + add factor FMAP projection = Previous FY FMAP + CBO FMAP effects from ARP Federal Medicaid Projection = Total Medicaid projection * FMAP projection State Medicaid Projection = Total Medicaid projection - Federal Medicaid Projection
B7: NIPA Data (Billions) | D7: HISTORY | AC7: PROJECTION
D8: 2018 | E8: 2019 | I8: 2020 | M8: 2021 | Q8: 2022 | V8: 2023 | Z8: 2024 | AC8: 2025 | AG8: 2026 | AK8: 2027
D9: Q4 | E9: Q1 | F9: Q2 | G9: Q3 | H9: Q4 | I9: Q1 | J9: Q2 | K9: Q3 | L9: Q4 | M9: Q1 | N9: Q2 | O9: Q3 | P9: Q4 | Q9: Q1 | R9: Q2 | S9: Q3 | T9: Q4 | U9: Q1 | V9: Q2 | W9: Q3 | X9: Q4 | Y9: Q1 | Z9: Q2 | AA9: Q3 | AB9: Q4 | AC9: Q1 | AD9: Q2 | AE9: Q3 | AF9: Q4 | AG9: Q1 | AH9: Q2 | AI9: Q3 | AJ9: Q4 | AK9: Q1 | AL9: Q2 | AM9: Q3 | AN9: Q4
B10: Total Medicaid Spending | C10: yptmd | D10: ='[1]Haver Pivoted'!GO13 -> 589.5 | E10: ='[1]Haver Pivoted'!GP13 -> 598.7 | F10: ='[1]Haver Pivoted'!GQ13 -> 614.4 | G10: ='[1]Haver Pivoted'!GR13 -> 622.4 | H10: ='[1]Haver Pivoted'!GS13 -> 620.6 | I10: ='[1]Haver Pivoted'!GT13 -> 606.5 | J10: ='[1]Haver Pivoted'!GU13 -> 654.6 | K10: ='[1]Haver Pivoted'!GV13 -> 690.8 | ... AC10: ='[1]Haver Pivoted'!HN13 -> 957.6
B11: Federal Medicaid Grants | C11: gfeghdx | D11: ='[1]Haver Pivoted'!GO40 -> 391.921 | E11: ='[1]Haver Pivoted'!GP40 -> 405.368 | F11: ='[1]Haver Pivoted'!GQ40 -> 414.196 | G11: ='[1]Haver Pivoted'!GR40 -> 418.686 | H11: ='[1]Haver Pivoted'!GS40 -> 416.185 | I11: ='[1]Haver Pivoted'!GT40 -> 422.89 | J11: ='[1]Haver Pivoted'!GU40 -> 502.906 | K11: ='[1]Haver Pivoted'!GV40 -> 484.48 | ... AC11: ='[1]Haver Pivoted'!HN40 -> 647.03
B12: Federal Share (FMAP) | D12: =D11/D10 -> 0.6648363 | E12: =E11/E10 -> 0.67708034 | F12: =F11/F10 -> 0.67414714 | G12: =G11/G10 -> 0.67269602 | H12: =H11/H10 -> 0.67061714 | I12: =I11/I10 -> 0.69726298 | J12: =J11/J10 -> 0.76826459 | K12: =K11/K10 -> 0.70133179 | ... AC12: =AC11/AC10 -> 0.67567878 | AD12: =AVERAGE(Z12:AC12) -> 0.68404219 | AE12: =AVERAGE(AA12:AD12) -> 0.6852255 | AF12: =AVERAGE(AB12:AE12) -> 0.68460003 | AG12: =AVERAGE(AC12:AF12) -> 0.68238662 | AH12: =AVERAGE(AD12:AG12) -> 0.68406358 | AI12: =AVERAGE(AE12:AH12) -> 0.68406893 | AJ12: =AVERAGE(AF12:AI12) -> 0.68377979 | AK12: =AVERAGE(AG12:AJ12) -> 0.68357473 | ... AN12: =AVERAGE(AJ12:AM12) -> 0.68376252
B15: Table 2
B16: Fiscal Years (Billions) | C16: 2020 | D16: 2021 | E16: 2022 | F16: 2023 | G16: 2024 | H16: 2025 | I16: 2026 | J16: 2027 | K16: 2028
B17: January 2025 CBO Projection of Federal Medicaid Outlays | C17: 458.468 | D17: 520.588 | E17: 591.949 | F17: 615.772 | G17: 617.517 | H17: 655.87 | I17: 695.209 | J17: 737.62 | K17: 766.587 | L17: 803.17 | M17: 836.602 | N17: 870.994 | O17: 910.184 | P17: 947.565 | Q17: 985.659 | R17: 1025.287
B18: Annual FMAP | C18: =AVERAGE(H12:K12) -> 0.70936913 | D18: =AVERAGE(L12:O12) -> 0.72156224 | E18: =AVERAGE(P12:S12) -> 0.74374551 | F18: =AVERAGE(T12:W12) -> 0.70641986 | G18: =AVERAGE(X12:AA12) -> 0.69142242 | H18: =AVERAGE(Y12:AB12) -> 0.68607934 | I18: =AVERAGE(AB12:AE12) -> 0.68460003 | J18: =AVERAGE(AA12:AI12) -> 0.68458296
B19: Total Medicaid (Federal/FMAP) | C19: =C17/C18 -> 646.30385 | D19: =D17/D18 -> 721.47345 | E19: =E17/E18 -> 795.90262 | F19: =F17/F18 -> 871.67991 | G19: =G17/G18 -> 893.11105 | H19: =H17/H18 -> 955.96816 | I19: =I17/I18 -> 1015.4966 | J19: =J17/J18 -> 1077.4735 | K19: =K17/K18 -> #DIV/0!
B20: Total Medicaid Annual Growth Rate | D20: =D19/C19-1 -> 0.1163069 | E20: =E19/D19-1 -> 0.10316273 | F20: =F19/E19-1 -> 0.095209244 | G20: =G19/F19-1 -> 0.024586019 | H20: =H19/G19-1 -> 0.070379954 | I20: =I19/H19-1 -> 0.062270318 | J20: =J19/I19-1 -> 0.061031127 | K20: =K19/J19-1 -> #DIV/0!
B23: Table 3
B24: Quarterly Projection (Billions) | D24: HISTORY | AC24: PROJECTION
D25: 2018 | E25: 2019 | I25: 2020 | M25: 2021 | Q25: 2022 | V25: 2023 | Z25: 2024 | AC25: 2025 | AG25: 2026 | AK25: 2027
D26: Q4 | E26: Q1 | F26: Q2 | G26: Q3 | H26: Q4 | I26: Q1 | J26: Q2 | K26: Q3 | L26: Q4 | M26: Q1 | N26: Q2 | O26: Q3 | P26: Q4 | Q26: Q1 | R26: Q2 | S26: Q3 | T26: Q4 | U26: Q1 | V26: Q2 | W26: Q3 | X26: Q4 | Y26: Q1 | Z26: Q2 | AA26: Q3 | AB26: Q4 | AC26: Q1 | AD26: Q2 | AE26: Q3 | AF26: Q4 | AG26: Q1 | AH26: Q2 | AI26: Q3 | AJ26: Q4 | AK26: Q1 | AL26: Q2 | AM26: Q3 | AN26: Q4
B27: Total Medicaid | D27: =D10 -> 589.5 | E27: =E10 -> 598.7 | F27: =F10 -> 614.4 | G27: =G10 -> 622.4 | H27: =H10 -> 620.6 | I27: =I10 -> 606.5 | J27: =J10 -> 654.6 | K27: =K10 -> 690.8 | ... AC27: =AC10 -> 957.6 | AD27: =AC27*(1+$H$20)^0.25+AD28 -> 969.02169 | AE27: =AD27*(1+$H$20)^0.25+AE28 -> 985.63925 | AF27: =AE27*(1+$I$20)^0.25+AF28 -> 1000.6374 | AG27: =AF27*(1+$I$20)^0.25+AG28 -> 1015.8639 | AH27: =AG27*(1+$I$20)^0.25+AH28 -> 1031.322 | AI27: =AH27*(1+$I$20)^0.25+AI28 -> 1047.0153 | AJ27: =AI27*(1+$J$20)^0.25+AJ28 -> 1062.6373 | AK27: =AJ27*(1+$J$20)^0.25+AK28 -> 1078.4924 | AL27: =AK27*(1+$J$20)^0.25+AL28 -> 1094.5841 | AM27: =AL27*(1+$J$20)^0.25+AM28 -> 1110.9158 | AN27: =AM27*(1+$K$20)^0.25+AN28 -> #DIV/0! | AO27: *note that the medicaid annual growth rate has to be switched to the new fy in q4
B28: Add factor for total medicaid | AC28: 26 | AD28: -5
B29: Federal Medicaid | D29: =D10*D12 -> 391.921 | E29: =E10*E12 -> 405.368 | F29: =F10*F12 -> 414.196 | G29: =G10*G12 -> 418.686 | H29: =H10*H12 -> 416.185 | I29: =I10*I12 -> 422.89 | J29: =J10*J12 -> 502.906 | K29: =K10*K12 -> 484.48 | ... Q29: =Q10*Q12 -> 589.927 | R29: =R27*R12 -> 585.746 | S29: =S27*S12 -> 617.889 | T29: =T27*T12 -> 611.68 | U29: =U27*U12 -> 632.66 | V29: =V27*V12 -> 628.887 | W29: =W27*W12 -> 585.984 | X29: =X27*X12 -> 612.034 | Y29: =Y27*Y12 -> 618.727 | ... AN29: =AN27*AN12 -> #DIV/0!
B30: State Medicaid | D30: =D27-D29 -> 197.579 | E30: =E27-E29 -> 193.332 | F30: =F27-F29 -> 200.204 | G30: =G27-G29 -> 203.714 | H30: =H27-H29 -> 204.415 | I30: =I27-I29 -> 183.61 | J30: =J27-J29 -> 151.694 | K30: =K27-K29 -> 206.32 | ... AN30: =AN27-AN29 -> #DIV/0!
B39: CBO Medicaid ARP Score | F39: 2021 | G39: 2022 | H39: 2023 | I39: 2024 | J39: 2025 | K39: 2025 | L39: 2027 | M39: 2028 | N39: 2029 | O39: 2030 | P39: 2031
B40: Coverage of Covid-19 vaccinations and treatments | F40: 287 | G40: 534 | H40: 247 | I40: 63
B41: Coverage for pregnant women | F41: 0 | G41: 0 | H41: 756 | I41: 1249 | J41: 1417 | K41: 1522 | L41: 1107
B42: Bundled community-based mobile crisis intervention | F42: 0 | G42: 5 | H42: 77 | I42: 307 | J42: 332 | K42: 270 | L42: 25 | M42: 32 | N42: 40 | O42: 49 | P42: 58
B43: Temporary increase in FMAP for expanding ACA coverage | F43: 0 | G43: 0 | H43: 3768 | I43: 3428 | J43: 2176 | K43: 2304 | L43: 2129 | M43: 1335 | N43: 478 | O43: 531 | P43: 212
B44: 100% FMAP for urban, Indian and Hawaiian organizations | F44: 38 | G44: 81 | H44: 43
B45: Sunset of limit on maximum rebate | I45: -184 | J45: -1830 | K45: -2406 | L45: -2419 | M45: -2467 | N45: -2531 | O45: -2667 | P45: -2809
B46: Temporary increase in FMAP for expanding HCBS | F46: 6524 | G46: 6143
B47: Strike Teams for nursing facilities | F47: 50 | G47: 175 | H47: 25
B48: DSH allotments during public health emergency | F48: 829 | G48: 844
B49: Total ARP Medicaid Provisions | F49: =SUM(F40:F48) -> 7728 | G49: =SUM(G40:G48) -> 7782 | H49: =SUM(H40:H48) -> 4916 | I49: =SUM(I40:I48) -> 4863 | J49: =SUM(J40:J48) -> 2095 | K49: =SUM(K40:K48) -> 1690 | L49: =SUM(L40:L48) -> 842 | M49: =SUM(M40:M48) -> -1100 | ... P49: =SUM(P40:P48) -> -2539
B50: FMAP Provisions | F50: =F46+F44+F43 -> 6562 | G50: =G46+G44+G43 -> 6224 | H50: =H46+H44+H43 -> 3811 | I50: =I46+I44+I43 -> 3428 | J50: =J46+J44+J43 -> 2176 | K50: =K46+K44+K43 -> 2304 | L50: =L46+L44+L43 -> 2129 | M50: =M46+M44+M43 -> 1335 | ... P50: =P46+P44+P43 -> 212 | Q50: Probably some of the $ for the Medicaid expansions is increase in actual Medicaid, but this is good enough for now
B51: FMAP Effects | F51: =(F50/1000)/M27 -> 0.0093091219 | G51: =(G50/F50)*F51 -> 0.0088296212 | H51: =(H50/G50)*G51+H52 -> 0.0054064406 | I51: =(I50/H50)*H51+I52 -> 0.0048631011 | J51: =J52 -> 0 | K51: =K52 -> 0 | L51: =L52 -> 0 | Q51: Rough estimate of impact on FMAP
B52: End of public health emergency

Sheet Guide to the FIM Spreadsheet
B10: Guide to the FIM Forecast Spreadsheet
B12: Sheets:
B13: Checklist (New Quarter Release) | C13: Checklist of steps to follow when the BEA releases its advance estimate of a new quarter's data
B14: Checklist (Monthly Revision) | C14: Checklist of steps to follow for BEA's two revisions of a quarter's data
B15: Checklist (CBO Budget Release) | C15: Checklist of steps to follow when the CBO releases a new Ten-Year Economic and Budget Projections
B16: Revisions | C16: A comparison of BEA's revisions for the latest quarter of data to the last release's data
B17: Forecast Comparison | C17: This sheet shows how our forecast has changed since the last update.
B18: Monthly Personal Income ("Month" MPI) | C18: Monthly BEA Personal Income data we use to help us forecast the upcoming quarter of data before BEA's advance estimate comes out.
B19: Forecast | C19: Our projection for the components of the FIM, calling from our forecast sheets; this is what we read into the code.
B20: Historical Overrides | C20: Calls from the Grants forecast sheet. We override BEA data for 2020 consumption grants because BEA puts it all in the first quarter; we spread it out over four. This also is read into the code.
B21: MPC | C21: MPCs for the spending out of our forecast variables, where applicable. We edit them here and the sheet is read into the code.
B22: Component Sheets (Grants, Medicare, Social Benefits, etc.) | C22: Each of these sheets generates our forecast for one (or a few) of the variables that we read into the code in the forecast sheet. This is the main part of the workbook that you will edit each update.
B23: Haver Pivoted | C23: BEA data read in from Haver; called by Revisions and the component sheets to generate our forecasts. We copy and paste updated data into this sheet each time there's a new BEA release. It is very important that the order of variables in this sheet does not change, so that the formulas in other sheets call the correct row.
B24: Cares Act Scores | C24: This is the CBO ten-year score for three pieces of Covid legislation not incorporated in CBO's March 2020 baseline. It's mainly CARES. Generally you won't touch this.
... B29: Deflators | C29: The deflators we use, for reference. Similar to the MPC sheet I think we should either delete or edit for the whole FIM in here.
B31: Conventions (please stick to these when editing the sheet to keep things organized)
B32: Italicized rows in the forecast spreadsheets are called by "forecast" and read into the code; they are the "final output" of each sheet.
B33: All CBO references have a comment with where to find the data that's copy pasted in so we can verify/find it again. I write the name of the release, table and row. It is important to keep these up to date so there isn't confusion about where the numbers come from, since they are hard-coded!
B34: NEVER drag forward a formula without checking how the row's formulas work-- at the moment, sometimes they change within a row.
B35: Any rows with haver codes next to the variable call from Haver Pivoted in the historical period.
B36: Year-quarters in all the main tables of the forecast sheets are in the same columns across sheets (i.e. 2021 Q2 is in column N across sheets for the main forecast tables).

Sheet Checklist (New Quarter Release)
A1: Checklist | B1: Methodology | C1: How to execute | D1: Done?
A2: Setting up
A3: Prepare the Revisions sheet | B3: This sheet allows us to see how the raw inputs to the FIM have changed; it can help us parse out which changes to our forecast are due to BEA data and which are due to our own formulas. | C3: In the Revisions sheet, copy paste the "Current Update" column into the "Last Update" column (make sure you paste it hard-coded using Paste Values). Relabel the columns with the quarter and which revision they represent (initial release, first revision, or second revision). | D3: no
A4: Prepare the Forecast Comparison and Forecast sheets | B4: The forecast comparison sheet shows us how much our forecast (what is read into the code) has changed since the last update, in level and percent differences. | C4: Copy paste the forecast table from the most recent update (Paste Values Only) into the "Previous Forecast" table. In both the forecast and forecast comparison sheets, delete the first column so that the forecast comparison sheet contains the upcoming quarter of data and the forecast going forward. | D4: yes | E4: yes
A5: Prepare this month's spreadsheet for a new quarter of data to be read in from Haver. | B5: This is a somewhat complicated part of a new quarter update. Most rows change their formulas from the historical to projection period, so you have to carefully pull forward the historical period to include the new quarter of data. | C5: In each component sheet, drag forward EVERY row that calls Haver Pivoted (you can identify those by the haver codes written next to the variable name) or depends on Haver Pivoted data forward one column into the upcoming quarter. Please change the color formatting and labeling of the historical versus projection periods accordingly to avoid confusion. The new quarters will show either nothing or a #REF error; ignore this. The cells will fill with the new data that we read in when BEA releases the new quarter. DOUBLE CHECK your work-- it is important to ensure that every row that needs to be pulled forward, is. | D5: yes | E5: yes
A6: Prepare the Revisions sheet for the new quarter | B6: This sheet we only use for monthly revisions, and not for a new quarter release. However we do need to update what quarter in Haver Pivoted is called in the "Current Update" column. | C6: Clear contents in the Last Update column. Change the formula in the first cell that calls Haver Pivoted in the Current Update column to call from one column over in Haver Pivoted (this is where the next quarter's data will be when we read in the new data). Drag the changed formula down the whole column. Don't worry about DIV0 or REF errors, everything will fill in when Haver Pivoted is updated. | D6: no
A7: Prepare the Historical Overrides and deflators_override sheets | B7: We have a few overrides to historical data that we include in these sheets | C7: In the Historical Overrides sheet, add the new quarter to the last column and drag the formulas to the right. In the deflators_override sheet, delete the first column. Add a new quarter to the last column and drag the formula over to the right. (all the quarters in this sheet should be in the forecast period) | D7: yes | E7: yes
A8: Read the BEA news release for the new quarter | B8: The BEA's news release can be really helpful for broadly understanding the BEA's released data for the new quarter, which affects the assumptions we make about the components of the FIM. The technical note is the most useful for detailed information. You'll want to take note of GDP growth, as well as any large components that they note. Sometimes the BEA tables can be useful for finding specific values too. | C8: https://www.bea.gov/news/current-releases | D8: yes
A9: Pulling in the new data from Haver | B9: We pull in the latest historical BEA data by running a script to replace the data in Haver Pivoted. This will autofill the spreadsheets where we make our forecast assumptions with the new BEA data. This will also autofill the "Current Update" column in Revisions. | C9: Run fim/data-raw/haver-pull.R. This script automatically pastes new data into the "Haver Pivoted" sheet. The order of the Haver codes should be preserved each update. If you need to pull more variables from Haver make sure they're at the bottom. | D9: yes
A10: Update unemployment rate and state and local employment and construction numbers | B10: We use these to gauge our forecast for state purchases. | C10: Update the table in the Federal and State Purchases sheet by dragging the formula to the next column. The formulas call cells from "data/monthly_state_employment.xlsx" which is created from "data-raw/haver-pull.R" | D10: yes
A11: Monthly Personal Income Sheet | B11: Before the BEA releases data on a quarter, we can use their monthly estimates of "Effects of Selected Federal Pandemic Response Programs on Personal Income" to inform our assumptions about the quarter. Don't forget another PCE at the bottom! Drag over cells in yellow before copy pasting (the yellow cell should be the first forecast). | C11: If this table has been released, create a new sheet called "Month" MPI with the table. You don't need to include the month to month changes, just the levels. It's helpful to highlight the rows in the table that are relevant to us.
A12: Looking over and editing our forecast
A13: Forecast Comparison | B13: Take a look at the forecast comparison sheet. How much has our forecast changed? Are there any components that have changed considerably, that we need to pay attention to?
A14: Component Sheets | B14: Look through each component forecast to see if anything looks strange/hugely different. This is where the archived forecast from last month comes in handy-- you can compare our forecast of this quarter to the data we've just pulled in to track why our forecast has changed. Check formulas, etc.
A15: Show Louise | B15: Walk Louise through the changes-- she typically makes some adjustments to the forecast. Once she signs off on the spreadsheet, you'll run the code to calculate the FIM.
A16: Calculating contributions
A17: At the top of the fiscal_impact script, set overwrite files to TRUE. This will automatically save the forecast sheet for this update in its archival folder (results/update month/input_data).
A18: Calculating the FIM | B18: The fiscal_impact script (the main script we use to calcualte the FIM) has five sections: Wrangle data-- here, we read in historical data from the BEA and the latest CBO Ten Year Baseline projections. We prep the historical data to be merged with our forecast by adjusting the BEA categories into the components we use for the FIM (see forecast sheet for those components). We also use the CBO projections to calculate the CBO's potential GDP growth projection for use later in the script. Projection-- in this section we read in the "forecast" sheet from this spreadsheet, merge it with the historical data we cleaned in the previous section, and combine the medicaid and medicare variables into categories of "health outlays", since they have the same MPC and don't need to be kept separate. We keep them apart in the spreadsheet because it's easier to combine them in the code rather than across worksheets. Consumption-- this is where a lot of the FIM methodology gets executed. First we subtract the counterfactual version of the components from our actual forecasted components to get the difference between actual spending and counterfactual spending; then we spread out spending of the net for each component using our MPCs. Contribution-- here we annualize the components and turn them into the GDP growth contributions by dividing by the lag of GDP and adjusting for inflation; then we rename a few variables and sum them into the final FIM categories. Comparison-- this section creates a table and plots with last month's FIM, this month's FIM, and the differences between them. | C18: Open up the fim R project by clicking on the "fim.Rproj" file. Type "CTRL + SHIFT + L" to load the fim package. Open fiscal_impact.R. This is the main script that we use to calculate the FIM.
A19: Generating comparison tables between the previous and new FIMs | B19: The comparison section of fiscal_impact.R renders the update-comparison.rmd file which generates graphs comparing last month and this month's components of the FIM. These help us to check for errors and see how much our forecast has changed since the last update. It outputs to results/{this-month-year}/update-comparison-{this-month-year}.html and a copy named index.html is created in the parent directory. It's called index.html so that GitHub knows to use it as a github site. Once you finish running fiscal_impact.R you should commit and push your changes to GitHub. Then make sure that the most recent version of index.html is published at https://github.com/Hutchins-Center/fim (you can find this link under the about page on the FIM's github repo (Hutchins-Center/fim). Share updated link and go through this with Louise. | C19: This step is automated when running fiscal_impact.R
A20: Finalizing update | B20: Once you finalize the update make sure to commit any changes and push them. I recommend labeling this commit '{Year-Quarter} Update finalized' so you can always return to that point in time in the commit history if needed. | C20: git add . git commit -m '{Year-Quarter} Update finalized git push Or your prefferd method for commiting/pushing
A21: When the update is finished, set the top of the fiscal_impact script, set overwrite files to FALSE. This will prevent the saved archival forecast from the update from being overwritten if you change the FIM at all within the same month as the most recent update.
A22: Publishing the FIM
A23: Drafting the text | C23: Former write ups can be found in Hutchins Center Documents/Projects/Fiscal Impact/Write Ups
A24: Fact checking | B24: A different RA should go through the text of the write up and confirm every number/statement using the FIM output files and graphics. | C24: The fim-interactive-month-year.xlsx file and fim-month-year.xlsx files are a good place to look (make sure they are the most up to date version!) and also look at the FIM interactive graphic that we are posting to ensure that our write up is consistent with it.
A25: Wordpress | B25: The FIM interactive and write up is posted on the Brookings website through Wordpress. | C25: See Hutchins Center Documents/Projects/Fiscal Impact/Updating the FIM Website.docx
A26: Newsletter | B26: We send out a newsletter alerting people that the FIM is updated. This gets updated in Hubspot. We typically use a shorter version of the full write up that's posted on the website for this. | C26: Typically an RA will make the initial cut and then run it by David and Stephanie. Ask an RA or someone from Comms to onboard you for using Hubspot if you haven't already. We don't send the email ourselves-- first email a test email to Taylor Kelly from Comms, and once it's approved and edited, Comms will send it out for us.

Sheet Checklist (Monthly Revision)
A1: Checklist | B1: Methodology | C1: How to execute | D1: Done?
A2: Setting up
A3: Prepare the Revisions sheet | B3: This sheet allows us to see how the raw inputs to the FIM have changed; it can help us parse out which changes to our forecast are due to BEA data revisions and which are due to our own formulas. (We don't do this.) | C3: In the Revisions sheet, copy paste the "Current Update" column into the "Last Update" column (make sure you paste it hard-coded using Paste Values). Relabel the columns with the quarter and which revision they represent (initial release, first revision, or second revision). | D3: no
A4: Prepare the Forecast Comparison sheet | B4: This sheet shows us how much our forecast (what is read into the code) has changed since the last update, in level and percent differences. | C4: Copy paste the forecast table from the most recent update (Past Values Only) into the "Previous Forecast" table. Keep the formulas in the first table so the data from Haver can be pulled in. | D4: yes | E4: yes
C5: Drag forward Construction (cpgs), Federal Corporate Income Taxes (gfrcp), and State Corporate Income Taxes (gsrcp) if initial revision (data comes in one month late) ex: February, May, August, November | D5: no | E5: yes
A6: Read the BEA news release for the revision | B6: The BEA's news release can be really helpful for broadly understanding what data has changed between revisions and why, which affects the assumptions we make about the components of the FIM. The technical note is the most useful for detailed information. You'll want to take note of GDP growth, as well as any relevant explanations for revisions. In a new quarter this will be more extensive. Sometimes the BEA tables can be useful for finding specific values too. | C6: https://www.bea.gov/news/current-releases | D6: yes
A7: Pulling in the new data from Haver | B7: We pull in the latest historical BEA data by running a script to replace the data in Haver Pivoted. This will autofill the spreadsheets where we make our forecast assumptions with the new BEA data. This will also autofill the "Current Update" column in Revisions. | C7: Run fim/data-raw/haver-pull.R. This script automatically pastes new data into the "Haver Pivoted" sheet. The order of the Haver codes should be preserved each update. If you need to pull more variables from Haver make sure they're at the bottom. Make sure to close the forecast spreadsheet before running! | D7: no
A8: Update unemployment rate and state and local employment and construction numbers | B8: We use these to gauge our forecast for state purchases. | C8: Update the table in the Federal and State Purchases sheet by searching the lasgova, lalgova, and cpgs Haver codes, and entering in the most recent month of data. Note: We don't really look at this | D8: no
A9: Revisions Sheet | B9: This sheet provides a quick look at how the BEA revised the variables that we use to make our forecast, and where they are used. It is helpful to anticipate changes in our forecast where the data automatically updates, and to consider when we decide whether to change our forecast assumptions sheet by sheet. | C9: Look through the revisions sheet. Which variables have changed, and which sheets are they called by? What are the biggest changes? Anything surprising? Go over this with Louise, and take note of what has changed to adjust our forecast sheets accordingly. | D9: no
A10: Monthly Personal Income Sheet | B10: Before the BEA releases data on a quarter, we can use their monthly estimates of "Effects of Selected Federal Pandemic Response Programs on Personal Income" to inform our assumptions about the quarter. | C10: If this table has been released, create a new sheet called "Month" MPI with the table. You don't need to include the month to month changes, just the levels. It's helpful to highlight the rows in the table that are relevant to us. | D10: no
A11: Looking over and editing our forecast
A12: Revisions Sheet | B12: Start with the Revisions sheet. How has BEA revised the data? How should we expect our forecast of each component to change, given their revision?
A13: Forecast Comparison Sheet | B13: Take a look at the forecast comparison sheet. How much has our forecast changed? Are there any components that have changed considerably, that we need to pay attention to? Anything unexpected, given what we saw in the Revisions sheet?
A14: Component Sheets | B14: Look through each component forecast to see if anything looks strange/hugely different. This is where the archived forecast from last month comes in handy-- you can compare our forecast of this quarter to the data we've just pulled in to track why our forecast has changed. Check formulas, etc.
A15: Show Louise | B15: Walk Louise through the changes-- she typically makes some adjustments to the forecast. Once she signs off on the spreadsheet, you'll run the code to calculate the FIM.
A16: Calculating contributions
A17: At the top of the fiscal_impact script, set overwrite files to TRUE. This will automatically save the forecast sheet for this update in its archival folder.
A18: Calculating the FIM | B18: The fiscal_impact script (the main script we use to calcualte the FIM) has five sections: Wrangle data-- here, we read in historical data from the BEA and the latest CBO Ten Year Baseline projections. We prep the historical data to be merged with our forecast by adjusting the BEA categories into the components we use for the FIM (see forecast sheet for those components). We also use the CBO projections to calculate the CBO's potential GDP growth projection for use later in the script. Projection-- in this section we read in the "forecast" sheet from this spreadsheet, merge it with the historical data we cleaned in the previous section, and combine the medicaid and medicare variables into categories of "health outlays", since they have the same MPC and don't need to be kept separate. We keep them apart in the spreadsheet because it's easier to combine them in the code rather than across worksheets. Consumption-- this is where a lot of the FIM methodology gets executed. First we subtract the counterfactual version of the components from our actual forecasted components to get the difference between actual spending and counterfactual spending; then we spread out spending of the net for each component using our MPCs. Contribution-- here we annualize the components and turn them into the GDP growth contributions by dividing by the lag of GDP and adjusting for inflation; then we rename a few variables and sum them into the final FIM categories. Comparison-- this section creates a table and plots with last month's FIM, this month's FIM, and the differences between them. | C18: Open up the fim R project by clicking on the "fim.Rproj" file. Type "CTRL + SHIFT + L" to load the fim package. Open fiscal_impact.R. This is the main script that we use to calculate the FIM.
A19: Generating comparison tables between the previous and new FIMs | B19: The comparison section of fiscal_impact.R renders the update-comparison.rmd file which generates graphs comparing last month and this month's components of the FIM. These help us to check for errors and see how much our forecast has changed since the last update. It outputs to results/{this-month-year}/update-comparison-{this-month-year}.html and a copy named index.html is created in the parent directory. It's called index.html so that GitHub knows to use it as a github site. Once you finish running fiscal_impact.R you should commit and push your changes to GitHub. Then make sure that the most recent version of index.html is published at https://github.com/Hutchins-Center/fim (you can find this link under the about page on the FIM's github repo (Hutchins-Center/fim). Share updated link and go through this with Louise. | C19: This step is automated when running fiscal_impact.R
A20: Finalizing update | B20: Once you finalize the update make sure to commit any changes and push them. I recommend labeling this commit '{Year-Quarter} Update finalized' so you can always return to that point in time in the commit history if needed. | C20: git add . git commit -m '{Year-Quarter} Update finalized git push Or your prefferd method for commiting/pushing
A21: When the update is finished, set the top of the fiscal_impact script, set overwrite files to FALSE. This will prevent the saved archival forecast from the update from being overwritten if you change the FIM at all within the same month as the most recent update.
A22: Publishing the FIM
A23: Drafting the text | B23: For a revision, we'll typically just edit the write up from the first release of quarterly data. | C23: Former write ups can be found in Hutchins Center Documents/Projects/Fiscal Impact/Write Ups
A24: Fact checking | B24: A different RA should go through the text of the write up and confirm every number/statement using the FIM output files and graphics. | C24: The fim-interactive-month-year.xlsx file and fim-month-year.xlsx files are a good place to look (make sure they are the most up to date version!) and also look at the FIM interactive graphic that we are posting to ensure that our write up is consistent with it.
A25: Wordpress | B25: The FIM interactive and write up is posted on the Brookings website through Wordpress. | C25: See Hutchins Center Documents/Projects/Fiscal Impact/Updating the FIM Website.docx
A26: Newsletter | B26: We send out a newsletter alerting people that the FIM is updated. This gets updated in Hubspot. We typically use a shorter version of the full write up that's posted on the website for this. | C26: Typically an RA will make the initial cut and then run it by David and Stephanie. Ask an RA or someone from Comms to onboard you for using Hubspot if you haven't already. We don't send the email ourselves-- first email a test email to Taylor Kelly from Comms, and once it's approved and edited, Comms will send it out for us.

Sheet Revisions
A1: Sheet Using | B1: Variable | C1: Haver Code | D1: Last Update | E1: Current Update | F1: Change
C2: ='Haver Pivoted'!A1 -> name | D2: 2024 Q1 initial update | E2: 2024 Q1 first revision | F2: Percentage point | G2: percent
B3: GDP | C3: ='Haver Pivoted'!A2 -> gdp | D3: 27610.1 | E3: ='Haver Pivoted'!HH2 -> 27967.7 | F3: =E3-D3 -> 357.6 | G3: =F3/D3 -> 0.012951782
B4: Real GDP | C4: ='Haver Pivoted'!A3 -> gdph | D4: 22490.7 | E4: ='Haver Pivoted'!HH3 -> 22780.9 | F4: =E4-D4 -> 290.2 | G4: =F4/D4 -> 0.012903111
B5: GDP Deflator | C5: ='Haver Pivoted'!A4 -> jgdp | D5: 122.792 | E5: ='Haver Pivoted'!HH4 -> 122.785 | F5: =E5-D5 -> -0.007 | G5: =F5/D5 -> -5.7006971e-05
B6: Consumption | C6: ='Haver Pivoted'!A5 -> c | D6: 18679.5 | E6: ='Haver Pivoted'!HH5 -> 18929 | F6: =E6-D6 -> 249.5 | G6: =F6/D6 -> 0.013356889
B7: Real Consumption | C7: ='Haver Pivoted'!A6 -> ch | D7: 15461.4 | E7: ='Haver Pivoted'!HH6 -> 15646.7 | F7: =E7-D7 -> 185.3 | G7: =F7/D7 -> 0.011984684
B8: Consumption Deflator | C8: ='Haver Pivoted'!A7 -> jc | D8: 120.814 | E8: ='Haver Pivoted'!HH7 -> 120.983 | F8: =E8-D8 -> 0.169 | G8: =F8/D8 -> 0.0013988445
B9: Federal Purchases Deflator | C9: ='Haver Pivoted'!A8 -> jgf | D9: 120.097 | E9: ='Haver Pivoted'!HH8 -> 120.759 | F9: =E9-D9 -> 0.662 | G9: =F9/D9 -> 0.005512211
B10: State Purchases Deflator | C10: ='Haver Pivoted'!A9 -> jgs | D10: 127.717 | E10: ='Haver Pivoted'!HH9 -> 126.041 | F10: =E10-D10 -> -1.676 | G10: =F10/D10 -> -0.013122764
B11: Consumption Grants Deflator | C11: ='Haver Pivoted'!A10 -> jgse | D11: 127.176 | E11: ='Haver Pivoted'!HH10 -> 124.699 | F11: =E11-D11 -> -2.477 | G11: =F11/D11 -> -0.019476945
B12: Investment Grants Deflator | C12: ='Haver Pivoted'!A11 -> jgsi | D12: 130.567 | E12: ='Haver Pivoted'!HH11 -> 132.668 | F12: =E12-D12 -> 2.101 | G12: =F12/D12 -> 0.016091355
A13: Medicare | B13: Medicare | C13: ='Haver Pivoted'!A12 -> yptmr | D13: 946.3 | E13: ='Haver Pivoted'!HH12 -> 1019.9 | F13: =E13-D13 -> 73.6 | G13: =F13/D13 -> 0.077776604
A14: Medicaid | B14: Total Medicaid Spending | C14: ='Haver Pivoted'!A13 -> yptmd | D14: 880.6 | E14: ='Haver Pivoted'!HH13 -> 867.2 | F14: =E14-D14 -> -13.4 | G14: =F14/D14 -> -0.015216898
A15: Unemployment Insurance | B15: Unemployment Insurance (NIPA Definition) | C15: ='Haver Pivoted'!A14 -> yptu | D15: 21 | E15: ='Haver Pivoted'!HH14 -> 34.7 | F15: =E15-D15 -> 13.7 | G15: =F15/D15 -> 0.65238095
B16: Social Benefits | C16: ='Haver Pivoted'!A15 -> gtfp | D16: 3987.8 | E16: ='Haver Pivoted'!HH15 -> 4147.5 | F16: =E16-D16 -> 159.7 | G16: =F16/D16 -> 0.040047144
B17: Personal Payments | C17: ='Haver Pivoted'!A16 -> ypog | D17: 131.2 | E17: ='Haver Pivoted'!HH16 -> 136 | F17: =E17-D17 -> 4.8 | G17: =F17/D17 -> 0.036585366
B18: Personal Taxes | C18: ='Haver Pivoted'!A17 -> yptx | D18: 2765.3 | E18: ='Haver Pivoted'!HH17 -> 2866 | F18: =E18-D18 -> 100.7 | G18: =F18/D18 -> 0.036415579
B19: Production Taxes | C19: ='Haver Pivoted'!A18 -> ytpi | D19: 1830.7 | E19: ='Haver Pivoted'!HH18 -> 1896.2 | F19: =E19-D19 -> 65.5 | G19: =F19/D19 -> 0.035778664
B20: Corporate Taxes | C20: ='Haver Pivoted'!A19 -> yctlg | D20: 566.7 | E20: ='Haver Pivoted'!HH19 -> 617.8 | F20: =E20-D20 -> 51.1 | G20: =F20/D20 -> 0.090171166
B21: Government purchases | C21: ='Haver Pivoted'!A20 -> g | D21: 4794.8 | E21: ='Haver Pivoted'!HH20 -> 4756.4 | F21: =E21-D21 -> -38.4 | G21: =F21/D21 -> -0.0080086761
B22: Social Insurance Payment | C22: ='Haver Pivoted'!A21 -> grcsi | D22: 1823.3 | E22: ='Haver Pivoted'!HH21 -> 1839.3 | F22: =E22-D22 -> 16 | G22: =F22/D22 -> 0.0087752975
B23: Consumption Deflator | C23: ='Haver Pivoted'!A22 -> dc | D23: 120.814 | E23: ='Haver Pivoted'!HH22 -> 120.978 | F23: =E23-D23 -> 0.164 | G23: =F23/D23 -> 0.0013574586
A24: Purchases | B24: Federal Purchases (NIPA consistent) | C24: ='Haver Pivoted'!A23 -> gf | D24: 1791.9 | E24: ='Haver Pivoted'!HH23 -> 1780.9 | F24: =E24-D24 -> -11 | G24: =F24/D24 -> -0.0061387354
A25: Purchases | B25: State Purchases (NIPA consistent) | C25: ='Haver Pivoted'!A24 -> gs | D25: 3002.9 | E25: ='Haver Pivoted'!HH24 -> 2975.5 | F25: =E25-D25 -> -27.4 | G25: =F25/D25 -> -0.009124513
B26: Real Federal Purchases | C26: ='Haver Pivoted'!A25 -> gfh | D26: 1492.3 | E26: ='Haver Pivoted'!HH25 -> 1474.8 | F26: =E26-D26 -> -17.5 | G26: =F26/D26 -> -0.011726865
B27: Real State Purchases | C27: ='Haver Pivoted'!A26 -> gsh | D27: 2351.4 | E27: ='Haver Pivoted'!HH26 -> 2360.8 | F27: =E27-D27 -> 9.4 | G27: =F27/D27 -> 0.0039976184
A28: Taxes | B28: Federal Personal Income Taxes | C28: gfrpt | D28: 2188.7 | E28: ='Haver Pivoted'!HH27 -> 2260.5 | F28: =E28-D28 -> 71.8 | G28: =F28/D28 -> 0.032804861
A29: Taxes | B29: Federal Production Taxes | C29: gfrpri | D29: 171.6 | E29: ='Haver Pivoted'!HH28 -> 172.2 | F29: =E29-D29 -> 0.6 | G29: =F29/D29 -> 0.0034965035
A30: Taxes | B30: Federal Corporate Income Taxes | C30: gfrcp | D30: 418 | E30: ='Haver Pivoted'!HH29 -> 451.9 | F30: =E30-D30 -> 33.9 | G30: =F30/D30 -> 0.081100478
A31: Taxes | B31: Federal Social Insurance | C31: gfrs | D31: 1801.4 | E31: ='Haver Pivoted'!HH30 -> 1818 | F31: =E31-D31 -> 16.6 | G31: =F31/D31 -> 0.009215055
A32: Social Benefits | B32: Federal Social Benefits | C32: ='Haver Pivoted'!A31 -> gftfp | D32: 2930.1 | E32: ='Haver Pivoted'!HH31 -> 3078 | F32: =E32-D32 -> 147.9 | G32: =F32/D32 -> 0.050476093
A33: Grants | B33: Gross Consumption Grants (BEA includes Medicaid grants; we deal with them separately) | C33: ='Haver Pivoted'!A32 -> gfeg | D33: 918.5 | E33: ='Haver Pivoted'!HH32 -> 915.6 | F33: =E33-D33 -> -2.9 | G33: =F33/D33 -> -0.0031573217
A34: Taxes | B34: State Personal Income Taxes | C34: ='Haver Pivoted'!A33 -> gsrpt | D34: 576.6 | E34: ='Haver Pivoted'!HH33 -> 605.5 | F34: =E34-D34 -> 28.9 | G34: =F34/D34 -> 0.050121401
A35: Taxes | B35: State Production Taxes | C35: ='Haver Pivoted'!A34 -> gsrpri | D35: 1659.2 | E35: ='Haver Pivoted'!HH34 -> 1724 | F35: =E35-D35 -> 64.8 | G35: =F35/D35 -> 0.039054966
A36: Taxes | B36: State Corporate Income Taxes | C36: ='Haver Pivoted'!A35 -> gsrcp | D36: 148.7 | E36: ='Haver Pivoted'!HH35 -> 165.9 | F36: =E36-D36 -> 17.2 | G36: =F36/D36 -> 0.11566913
A37: Taxes | B37: State Social Insurance | C37: ='Haver Pivoted'!A36 -> gsrs | D37: 21.9 | E37: ='Haver Pivoted'!HH36 -> 21.2 | F37: =E37-D37 -> -0.7 | G37: =F37/D37 -> -0.03196347
A38: Social Benefits | B38: State Social Benefits | C38: ='Haver Pivoted'!A37 -> gstfp | D38: 1057.6 | E38: ='Haver Pivoted'!HH37 -> 1069.4 | F38: =E38-D38 -> 11.8 | G38: =F38/D38 -> 0.011157337
B39: State Expenditures | C39: ='Haver Pivoted'!A38 -> gset | D39: 3985.3 | E39: ='Haver Pivoted'!HH38 -> 3944.8 | F39: =E39-D39 -> -40.5 | G39: =F39/D39 -> -0.010162347
B40: Health Grants | C40: ='Haver Pivoted'!A39 -> gfeghhx | D40: 622.957 | E40: ='Haver Pivoted'!HH39 -> 617.139 | F40: =E40-D40 -> -5.818 | G40: =F40/D40 -> -0.0093393284
...

Sheet Checklist (CBO Budget Release)
A1: Checklist | B1: Methodology | C1: How to execute | D1: Done?
A2: Pull updated CBO projections data | B2: Approximately every quarter, the CBO releases new Ten-Year Budget and Economic Projections. We use these to update our projections for GDP and inflation, and in a number of the forecast sheets. When the new projections come out, we incorporate them into the sheet and code, and then wait to release the updated FIM until the next monthly update. The inst/extdata/projections.xlsx workbook is updated with the new CBO numbers. The data-raw/projections.R script cleans them to be readable in R. | C2: Update CBO data in inst/extdata/projections.xlsx. Refer to the dictionary sheet to figure out which lines of the CBO update correspond to the Haver codes. Open the FIM project by clicking on the "fim.Rproj" file. Run data-raw/projections.R | D2: yes
A3: Prepare the Forecast Comparison sheet | B3: This sheet shows us how much our forecast (what is read into the code) has changed since the last update, in level and percent differences. | C3: Copy past the forecast table from the most recent update (Past Values Only) into the "Previous Forecast" table.
A4: Updating the spreadsheet | B4: Throughout the forecast spreadsheets, we use CBO projections to forecast certain FIM components. Every row taken from CBO will be marked as such, with comments indicating which update, table and row the numbers are from to make it easier to find. Replace the CBO numbers with the new forecast, and make sure to change the comments so that they reflect the new row #s. Copy paste the old table/old rows near the table from last update's forecast sheet for comparison. Then, we go through each part of the sheet that uses CBO with Louise, and decide how we want to change the forecast or simply update the old CBO rows with new CBO projections, based on the CBO revisions. Make sure to label the old and new CBO numbers clearly! | C4: You may need to download the latest files at: https://www.cbo.gov/data/budget-economic-data We pull data from the following sheets: "10-Year Budget Projections", "Economic Projections", and "Revenue Projections, by Category"
A5: Run the code | B5: Run fiscal_impact.R (the main FIM script). The output will incorporate both the CBO changes to the spreadsheet and the new inflation and GDP forecast. | C5: Run fiscal_impact.R
A6: Look at the comparison graphs | B6: Fiscal_impact.R runs and knits compare-update.Rmd. Go over the changes from the last update that are due to the CBO with Louise. Make sure everything looks normal. These changes will be published along with the next monthly update. | C6: Look at the output of index.html

Sheet Haver Pivoted
A1: name | B1: 1970 Q1 | C1: 1970 Q2 | D1: 1970 Q3 | E1: 1970 Q4 | F1: 1971 Q1 | G1: 1971 Q2 | H1: 1971 Q3 | I1: 1971 Q4 | J1: 1972 Q1 | K1: 1972 Q2 | L1: 1972 Q3 | M1: 1972 Q4 | N1: 1973 Q1 | O1: 1973 Q2 | P1: 1973 Q3 | Q1: 1973 Q4 | R1: 1974 Q1 | S1: 1974 Q2 | T1: 1974 Q3 | U1: 1974 Q4 | V1: 1975 Q1 | W1: 1975 Q2 | X1: 1975 Q3 | Y1: 1975 Q4 | Z1: 1976 Q1 | AA1: 1976 Q2 | AB1: 1976 Q3 | AC1: 1976 Q4 | AD1: 1977 Q1 | AE1: 1977 Q2 | AF1: 1977 Q3 | AG1: 1977 Q4 | AH1: 1978 Q1 | AI1: 1978 Q2 | AJ1: 1978 Q3 | AK1: 1978 Q4 | AL1: 1979 Q1 | AM1: 1979 Q2 | AN1: 1979 Q3 | AO1: 1979 Q4 | AP1: 1980 Q1 | AQ1: 1980 Q2 | AR1: 1980 Q3 | AS1: 1980 Q4 | AT1: 1981 Q1 | AU1: 1981 Q2 | AV1: 1981 Q3 | AW1: 1981 Q4 | AX1: 1982 Q1 | AY1: 1982 Q2 | AZ1: 1982 Q3 | BA1: 1982 Q4 | BB1: 1983 Q1 | BC1: 1983 Q2 | BD1: 1983 Q3 | BE1: 1983 Q4 | BF1: 1984 Q1 | BG1: 1984 Q2 | BH1: 1984 Q3 | BI1: 1984 Q4 | BJ1: 1985 Q1 | BK1: 1985 Q2 | BL1: 1985 Q3 | BM1: 1985 Q4 | BN1: 1986 Q1 | BO1: 1986 Q2 | BP1: 1986 Q3 | BQ1: 1986 Q4 | BR1: 1987 Q1 | BS1: 1987 Q2 | BT1: 1987 Q3 | BU1: 1987 Q4 | BV1: 1988 Q1 | BW1: 1988 Q2 | BX1: 1988 Q3 | BY1: 1988 Q4 | BZ1: 1989 Q1 | CA1: 1989 Q2 | CB1: 1989 Q3 | CC1: 1989 Q4 | CD1: 1990 Q1 | CE1: 1990 Q2 | CF1: 1990 Q3 | CG1: 1990 Q4 | CH1: 1991 Q1 | CI1: 1991 Q2 | CJ1: 1991 Q3 | CK1: 1991 Q4 | CL1: 1992 Q1 | CM1: 1992 Q2 | CN1: 1992 Q3 | CO1: 1992 Q4 | CP1: 1993 Q1 | CQ1: 1993 Q2 | CR1: 1993 Q3 | CS1: 1993 Q4 | CT1: 1994 Q1 | CU1: 1994 Q2 | CV1: 1994 Q3 | CW1: 1994 Q4 | CX1: 1995 Q1 | CY1: 1995 Q2 | CZ1: 1995 Q3 | DA1: 1995 Q4 | DB1: 1996 Q1 | DC1: 1996 Q2 | DD1: 1996 Q3 | DE1: 1996 Q4 | DF1: 1997 Q1 | DG1: 1997 Q2 | DH1: 1997 Q3 | DI1: 1997 Q4 | DJ1: 1998 Q1 | DK1: 1998 Q2 | DL1: 1998 Q3 | DM1: 1998 Q4 | DN1: 1999 Q1 | DO1: 1999 Q2 | DP1: 1999 Q3 | DQ1: 1999 Q4 | DR1: 2000 Q1 | DS1: 2000 Q2 | DT1: 2000 Q3 | DU1: 2000 Q4 | DV1: 2001 Q1 | DW1: 2001 Q2 | DX1: 2001 Q3 | DY1: 2001 Q4 | DZ1: 2002 Q1 | EA1: 2002 Q2 | EB1: 2002 Q3 | EC1: 2002 Q4 | ED1: 2003 Q1 | EE1: 2003 Q2 | EF1: 2003 Q3 | EG1: 2003 Q4 | EH1: 2004 Q1 | EI1: 2004 Q2 | EJ1: 2004 Q3 | EK1: 2004 Q4 | EL1: 2005 Q1 | EM1: 2005 Q2 | EN1: 2005 Q3 | EO1: 2005 Q4 | EP1: 2006 Q1 | EQ1: 2006 Q2 | ER1: 2006 Q3 | ES1: 2006 Q4 | ET1: 2007 Q1 | EU1: 2007 Q2 | EV1: 2007 Q3 | EW1: 2007 Q4 | EX1: 2008 Q1 | EY1: 2008 Q2 | EZ1: 2008 Q3 | FA1: 2008 Q4 | FB1: 2009 Q1 | FC1: 2009 Q2 | FD1: 2009 Q3 | FE1: 2009 Q4 | FF1: 2010 Q1 | FG1: 2010 Q2 | FH1: 2010 Q3 | FI1: 2010 Q4 | FJ1: 2011 Q1 | FK1: 2011 Q2 | FL1: 2011 Q3 | FM1: 2011 Q4 | FN1: 2012 Q1 | FO1: 2012 Q2 | FP1: 2012 Q3 | FQ1: 2012 Q4 | FR1: 2013 Q1 | FS1: 2013 Q2 | FT1: 2013 Q3 | FU1: 2013 Q4 | FV1: 2014 Q1 | FW1: 2014 Q2 | FX1: 2014 Q3 | FY1: 2014 Q4 | FZ1: 2015 Q1 | GA1: 2015 Q2 | GB1: 2015 Q3 | GC1: 2015 Q4 | GD1: 2016 Q1 | GE1: 2016 Q2 | GF1: 2016 Q3 | GG1: 2016 Q4 | GH1: 2017 Q1 | GI1: 2017 Q2 | GJ1: 2017 Q3 | GK1: 2017 Q4 | GL1: 2018 Q1 | GM1: 2018 Q2 | GN1: 2018 Q3 | GO1: 2018 Q4 | GP1: 2019 Q1 | GQ1: 2019 Q2 | GR1: 2019 Q3 | GS1: 2019 Q4 | GT1: 2020 Q1 | GU1: 2020 Q2 | GV1: 2020 Q3 | GW1: 2020 Q4 | GX1: 2021 Q1 | GY1: 2021 Q2 | GZ1: 2021 Q3 | HA1: 2021 Q4 | HB1: 2022 Q1 | HC1: 2022 Q2 | HD1: 2022 Q3 | HE1: 2022 Q4 | HF1: 2023 Q1 | HG1: 2023 Q2 | HH1: 2023 Q3 | HI1: 2023 Q4 | HJ1: 2024 Q1 | HK1: 2024 Q2 | HL1: 2024 Q3 | HM1: 2024 Q4 | HN1: 2025 Q1
A2: gdp | B2: 1051.2 | C2: 1067.4 | D2: 1086.1 | E2: 1088.6 | F2: 1135.2 | G2: 1156.3 | H2: 1177.7 | I2: 1190.3 | J2: 1230.6 | K2: 1266.4 | L2: 1290.6 | M2: 1328.9 | N2: 1377.5 | O2: 1413.9 | P2: 1433.8 | Q2: 1476.3 | R2: 1491.2 | S2: 1530.1 | T2: 1560 | U2: 1599.7 | V2: 1616.1 | W2: 1651.9 | X2: 1709.8 | Y2: 1761.8 | Z2: 1820.5 | AA2: 1852.3 | AB2: 1886.6 | AC2: 1934.3 | AD2: 1988.6 | AE2: 2055.9 | AF2: 2118.5 | AG2: 2164.3 | AH2: 2202.8 | AI2: 2331.6 | AJ2: 2395.1 | AK2: 2476.9 | AL2: 2526.6 | AM2: 2591.2 | AN2: 2667.6 | AO2: 2723.9 | AP2: 2789.8 | AQ2: 2797.4 | AR2: 2856.5 | AS2: 2985.6 | AT2: 3124.2 | AU2: 3162.5 | AV2: 3260.6 | AW2: 3280.8 | AX2: 3274.3 | AY2: 3332 | AZ2: 3366.3 | BA2: 3402.6 | BB2: 3473.4 | BC2: 3578.8 | BD2: 3689.2 | BE2: 3794.7 | BF2: 3908.1 | BG2: 4009.6 | BH2: 4084.3 | BI2: 4148.6 | BJ2: 4230.2 | BK2: 4294.9 | BL2: 4386.8 | BM2: 4444.1 | BN2: 4507.9 | BO2: 4545.3 | BP2: 4607.7 | BQ2: 4657.6 | BR2: 4722.2 | BS2: 4806.2 | BT2: 4884.6 | BU2: 5008 | BV2: 5073.4 | BW2: 5190 | BX2: 5282.8 | BY2: 5399.5 | BZ2: 5511.3 | CA2: 5612.5 | CB2: 5695.4 | CC2: 5747.2 | CD2: 5872.7 | CE2: 5960 | CF2: 6015.1 | CG2: 6004.7 | CH2: 6035.2 | CI2: 6126.9 | CJ2: 6205.9 | CK2: 6264.5 | CL2: 6363.1 | CM2: 6470.8 | CN2: 6566.6 | CO2: 6680.8 | CP2: 6729.5 | CQ2: 6808.9 | CR2: 6882.1 | CS2: 7013.7 | CT2: 7115.7 | CU2: 7246.9 | CV2: 7331.1 | CW2: 7455.3 | CX2: 7522.3 | CY2: 7581 | CZ2: 7683.1 | DA2: 7772.6 | DB2: 7868.5 | DC2: 8032.8 | DD2: 8131.4 | DE2: 8259.8 | DF2: 8362.7 | DG2: 8518.8 | DH2: 8662.8 | DI2: 8765.9 | DJ2: 8866.5 | DK2: 8969.7 | DL2: 9121.1 | DM2: 9294 | DN2: 9411.7 | DO2: 9526.2 | DP2: 9686.6 | DQ2: 9900.2 | DR2: 10002.2 | DS2: 10247.7 | DT2: 10318.2 | DU2: 10435.7 | DV2: 10470.2 | DW2: 10599 | DX2: 10598 | DY2: 10660.5 | DZ2: 10783.5 | EA2: 10887.5 | EB2: 10984 | EC2: 11061.4 | ED2: 11174.1 | EE2: 11312.8 | EF2: 11566.7 | EG2: 11772.2 | EH2: 11923.4 | EI2: 12112.8 | EJ2: 12305.3 | EK2: 12527.2 | EL2: 12767.3 | EM2: 12922.7 | EN2: 13142.6 | EO2: 13324.2 | EP2: 13599.2 | EQ2: 13753.4 | ER2: 13870.2 | ES2: 14039.6 | ET2: 14215.7 | EU2: 14402.1 | EV2: 14564.1 | EW2: 14715.1 | EX2: 14706.5 | EY2: 14865.7 | EZ2: 14899 | FA2: 14608.2 | FB2: 14430.9 | FC2: 14381.2 | FD2: 14448.9 | FE2: 14651.2 | FF2: 14764.6 | FG2: 14980.2 | FH2: 15141.6 | FI2: 15309.5 | FJ2: 15351.4 | FK2: 15557.5 | FL2: 15647.7 | FM2: 15842.3 | FN2: 16068.8 | FO2: 16207.1 | FP2: 16319.5 | FQ2: 16420.4 | FR2: 16648.2 | FS2: 16728.7 | FT2: 16953.8 | FU2: 17192 | FV2: 17197.7 | FW2: 17518.5 | FX2: 17804.2 | FY2: 17912.1 | FZ2: 18063.5 | GA2: 18279.8 | GB2: 18401.6 | GC2: 18435.1 | GD2: 18525.9 | GE2: 18711.7 | GF2: 18892.6 | GG2: 19089.4 | GH2: 19280.1 | GI2: 19438.6 | GJ2: 19692.6 | GK2: 20037.1 | GL2: 20328.6 | GM2: 20580.9 | GN2: 20798.7 | GO2: 20917.9 | GP2: 21111.6 | GQ2: 21397.9 | GR2: 21717.2 | GS2: 21933.2 | GT2: 21727.7 | GU2: 19935.4 | GV2: 21684.6 | GW2: 22068.8 | GX2: 22656.8 | GY2: 23368.9 | GZ2: 23922 | HA2: 24777 | HB2: 25215.5 | HC2: 25805.8 | HD2: 26272 | HE2: 26734.3 | HF2: 27164.4 | HG2: 27453.8 | HH2: 27967.7 | HI2: 28297 | HJ2: 28624.1 | HK2: 29016.7 | HL2: 29374.9 | HM2: 29723.9 | HN2: 29962
A3: gdph | B3: 5300.7 | C3: 5308.2 | D3: 5357.1 | E3: 5299.7 | F3: 5443.6 | G3: 5473.1 | H3: 5518.1 | I3: 5531 | J3: 5632.6 | K3: 5760.5 | L3: 5814.9 | M3: 5912.2 | N3: 6058.5 | O3: 6124.5 | P3: 6092.3 | Q3: 6150.1 | R3: 6097.3 | S3: 6111.8 | T3: 6054 | U3: 6030.5 | V3: 5957 | W3: 5999.6 | X3: 6102.3 | Y3: 6184.5 | Z3: 6323.6 | AA3: 6370 | AB3: 6404.9 | AC3: 6451.2 | AD3: 6527.7 | AE3: 6654.5 | AF3: 6774.5 | AG3: 6774.6 | AH3: 6796.3 | AI3: 7058.9 | AJ3: 7129.9 | AK3: 7225.8 | AL3: 7238.7 | AM3: 7246.5 | AN3: 7300.3 | AO3: 7318.5 | AP3: 7341.6 | AQ3: 7190.3 | AR3: 7181.7 | AS3: 7315.7 | AT3: 7459 | AU3: 7403.7 | AV3: 7492.4 | AW3: 7410.8 | AX3: 7295.6 | AY3: 7328.9 | AZ3: 7300.9 | BA3: 7303.8 | BB3: 7400.1 | BC3: 7568.5 | BD3: 7719.7 | BE3: 7880.8 | BF3: 8034.8 | BG3: 8173.7 | BH3: 8252.5 | BI3: 8320.2 | BJ3: 8400.8 | BK3: 8474.8 | BL3: 8604.2 | BM3: 8668.2 | BN3: 8749.1 | BO3: 8788.5 | BP3: 8872.6 | BQ3: 8920.2 | BR3: 8986.4 | BS3: 9083.3 | BT3: 9162 | BU3: 9319.3 | BV3: 9367.5 | BW3: 9490.6 | BX3: 9546.2 | BY3: 9673.4 | BZ3: 9771.7 | CA3: 9846.3 | CB3: 9919.2 | CC3: 9938.8 | CD3: 10047.4 | CE3: 10083.9 | CF3: 10090.6 | CG3: 9998.7 | CH3: 9951.9 | CI3: 10029.5 | CJ3: 10080.2 | CK3: 10115.3 | CL3: 10236.4 | CM3: 10347.4 | CN3: 10449.7 | CO3: 10558.6 | CP3: 10576.3 | CQ3: 10637.8 | CR3: 10688.6 | CS3: 10834 | CT3: 10939.1 | CU3: 11087.4 | CV3: 11152.2 | CW3: 11279.9 | CX3: 11320 | CY3: 11353.7 | CZ3: 11450.3 | DA3: 11528.1 | DB3: 11614.4 | DC3: 11808.1 | DD3: 11914.1 | DE3: 12037.8 | DF3: 12115.5 | DG3: 12317.2 | DH3: 12471 | DI3: 12577.5 | DJ3: 12703.7 | DK3: 12821.3 | DL3: 12982.8 | DM3: 13191.7 | DN3: 13315.6 | DO3: 13426.7 | DP3: 13604.8 | DQ3: 13828 | DR3: 13878.1 | DS3: 14130.9 | DT3: 14145.3 | DU3: 14229.8 | DV3: 14183.1 | DW3: 14271.7 | DX3: 14214.5 | DY3: 14253.6 | DZ3: 14372.8 | EA3: 14460.8 | EB3: 14519.6 | EC3: 14537.6 | ED3: 14614.1 | EE3: 14743.6 | EF3: 14988.8 | EG3: 15162.8 | EH3: 15248.7 | EI3: 15366.9 | EJ3: 15512.6 | EK3: 15670.9 | EL3: 15844.7 | EM3: 15922.8 | EN3: 16047.6 | EO3: 16136.7 | EP3: 16353.8 | EQ3: 16396.2 | ER3: 16420.7 | ES3: 16561.9 | ET3: 16611.7 | EU3: 16713.3 | EV3: 16809.6 | EW3: 16915.2 | EX3: 16843 | EY3: 16943.3 | EZ3: 16854.3 | FA3: 16485.4 | FB3: 16298.3 | FC3: 16269.1 | FD3: 16326.3 | FE3: 16502.8 | FF3: 16582.7 | FG3: 16743.2 | FH3: 16872.3 | FI3: 16960.9 | FJ3: 16920.6 | FK3: 17035.1 | FL3: 17031.3 | FM3: 17222.6 | FN3: 17367 | FO3: 17444.5 | FP3: 17469.7 | FQ3: 17489.9 | FR3: 17662.4 | FS3: 17709.7 | FT3: 17860.5 | FU3: 18016.1 | FV3: 17954 | FW3: 18185.9 | FX3: 18406.9 | FY3: 18500 | FZ3: 18666.6 | GA3: 18782.2 | GB3: 18857.4 | GC3: 18892.2 | GD3: 19001.7 | GE3: 19062.7 | GF3: 19197.9 | GG3: 19304.4 | GH3: 19398.3 | GI3: 19506.9 | GJ3: 19660.8 | GK3: 19882.4 | GL3: 20044.1 | GM3: 20150.5 | GN3: 20276.2 | GO3: 20304.9 | GP3: 20431.6 | GQ3: 20602.3 | GR3: 20843.3 | GS3: 20985.4 | GT3: 20693.2 | GU3: 19056.6 | GV3: 20548.8 | GW3: 20771.7 | GX3: 21058.4 | GY3: 21389 | GZ3: 21571.4 | HA3: 21960.4 | HB3: 21903.9 | HC3: 21919.2 | HD3: 22066.8 | HE3: 22249.5 | HF3: 22403.4 | HG3: 22539.4 | HH3: 22780.9 | HI3: 22960.6 | HJ3: 23053.5 | HK3: 23223.9 | HL3: 23400.3 | HM3: 23542.3 | HN3: 23512.7
A4: jgdp | B4: 19.823 | C4: 20.109 | D4: 20.274 | E4: 20.539 | F4: 20.85 | G4: 21.13 | H4: 21.343 | I4: 21.52 | J4: 21.865 | K4: 21.999 | L4: 22.198 | M4: 22.45 | N4: 22.735 | O4: 23.111 | P4: 23.553 | Q4: 23.961 | R4: 24.446 | S4: 24.989 | T4: 25.759 | U4: 26.541 | V4: 27.141 | W4: 27.534 | X4: 28.021 | Y4: 28.489 | Z4: 28.8 | AA4: 29.088 | AB4: 29.459 | AC4: 29.96 | AD4: 30.443 | AE4: 30.925 | AF4: 31.351 | AG4: 31.875 | AH4: 32.397 | AI4: 33.043 | AJ4: 33.626 | AK4: 34.291 | AL4: 34.931 | AM4: 35.775 | AN4: 36.522 | AO4: 37.188 | AP4: 38.001 | AQ4: 38.903 | AR4: 39.77 | AS4: 40.825 | AT4: 41.907 | AU4: 42.694 | AV4: 43.524 | AW4: 44.243 | AX4: 44.877 | AY4: 45.473 | AZ4: 46.104 | BA4: 46.571 | BB4: 46.943 | BC4: 47.291 | BD4: 47.794 | BE4: 48.151 | BF4: 48.626 | BG4: 49.063 | BH4: 49.506 | BI4: 49.852 | BJ4: 50.363 | BK4: 50.66 | BL4: 50.997 | BM4: 51.262 | BN4: 51.515 | BO4: 51.695 | BP4: 51.941 | BQ4: 52.25 | BR4: 52.554 | BS4: 52.911 | BT4: 53.32 | BU4: 53.72 | BV4: 54.135 | BW4: 54.676 | BX4: 55.345 | BY4: 55.854 | BZ4: 56.392 | CA4: 57.002 | CB4: 57.425 | CC4: 57.817 | CD4: 58.447 | CE4: 59.101 | CF4: 59.612 | CG4: 60.067 | CH4: 60.651 | CI4: 61.088 | CJ4: 61.557 | CK4: 61.915 | CL4: 62.162 | CM4: 62.533 | CN4: 62.833 | CO4: 63.275 | CP4: 63.652 | CQ4: 64.027 | CR4: 64.349 | CS4: 64.727 | CT4: 65.058 | CU4: 65.369 | CV4: 65.717 | CW4: 66.083 | CX4: 66.46 | CY4: 66.785 | CZ4: 67.084 | DA4: 67.401 | DB4: 67.712 | DC4: 67.988 | DD4: 68.318 | DE4: 68.607 | DF4: 68.915 | DG4: 69.258 | DH4: 69.464 | DI4: 69.713 | DJ4: 69.783 | DK4: 69.964 | DL4: 70.235 | DM4: 70.424 | DN4: 70.615 | DO4: 70.934 | DP4: 71.207 | DQ4: 71.581 | DR4: 72.058 | DS4: 72.491 | DT4: 72.945 | DU4: 73.341 | DV4: 73.843 | DW4: 74.335 | DX4: 74.56 | DY4: 74.801 | DZ4: 74.998 | EA4: 75.295 | EB4: 75.633 | EC4: 76.073 | ED4: 76.482 | EE4: 76.746 | EF4: 77.185 | EG4: 77.633 | EH4: 78.191 | EI4: 78.825 | EJ4: 79.323 | EK4: 79.936 | EL4: 80.55 | EM4: 81.137 | EN4: 81.905 | EO4: 82.557 | EP4: 83.135 | EQ4: 83.871 | ER4: 84.486 | ES4: 84.806 | ET4: 85.655 | EU4: 86.201 | EV4: 86.568 | EW4: 86.982 | EX4: 87.359 | EY4: 87.678 | EZ4: 88.361 | FA4: 88.511 | FB4: 88.536 | FC4: 88.418 | FD4: 88.474 | FE4: 88.798 | FF4: 89.018 | FG4: 89.431 | FH4: 89.755 | FI4: 90.27 | FJ4: 90.71 | FK4: 91.363 | FL4: 91.84 | FM4: 91.951 | FN4: 92.495 | FO4: 92.881 | FP4: 93.459 | FQ4: 93.869 | FR4: 94.204 | FS4: 94.474 | FT4: 94.989 | FU4: 95.477 | FV4: 95.84 | FW4: 96.343 | FX4: 96.762 | FY4: 96.8 | FZ4: 96.742 | GA4: 97.302 | GB4: 97.536 | GC4: 97.527 | GD4: 97.468 | GE4: 98.108 | GF4: 98.372 | GG4: 98.884 | GH4: 99.389 | GI4: 99.656 | GJ4: 100.174 | GK4: 100.78 | GL4: 101.428 | GM4: 102.14 | GN4: 102.586 | GO4: 103.005 | GP4: 103.332 | GQ4: 103.855 | GR4: 104.196 | GS4: 104.543 | GT4: 105.001 | GU4: 104.651 | GV4: 105.574 | GW4: 106.293 | GX4: 107.645 | GY4: 109.278 | GZ4: 110.931 | HA4: 112.836 | HB4: 115.16 | HC4: 117.76 | HD4: 119.073 | HE4: 120.173 | HF4: 121.247 | HG4: 121.809 | HH4: 122.785 | HI4: 123.247 | HJ4: 124.168 | HK4: 124.942 | HL4: 125.543 | HM4: 126.27 | HN4: 127.441
