Workbook

Sheet Oct 2025
A1: date | B1: id | C1: recession | D1: federal_purchases_deflator_growth | E1: consumption_grants_deflator_growth | F1: investment_grants_deflator_growth | G1: state_purchases_deflator_growth | H1: consumption_deflator_growth | I1: real_potential_gdp_growth | J1: gdp | K1: consumption | L1: uncertainty | M1: federal_purchases | N1: consumption_grants | O1: investment_grants | P1: state_purchases | Q1: federal_non_corporate_taxes | R1: state_non_corporate_taxes | S1: federal_corporate_taxes | T1: supply_side_ira | U1: state_corporate_taxes | V1: federal_social_benefits | W1: state_social_benefits | X1: rebate_checks | Y1: rebate_checks_arp | Z1: federal_ui | AA1: state_ui | AB1: federal_subsidies | AC1: federal_aid_to_small_businesses_arp | AD1: federal_other_direct_aid_arp | AE1: federal_other_vulnerable_arp | AF1: federal_student_loans | AG1: state_subsidies | AH1: federal_health_outlays | AI1: state_health_outlays | AJ1: post_mpc_federal_non_corporate_taxes | AK1: post_mpc_state_non_corporate_taxes | AL1: post_mpc_federal_corporate_taxes | AM1: post_mpc_state_corporate_taxes | AN1: post_mpc_federal_social_benefits | AO1: post_mpc_state_social_benefits | AP1: post_mpc_rebate_checks | AQ1: post_mpc_rebate_checks_arp | AR1: post_mpc_federal_ui | AS1: post_mpc_state_ui | AT1: post_mpc_federal_subsidies | AU1: post_mpc_federal_aid_to_small_businesses_arp | AV1: post_mpc_federal_other_vulnerable_arp | AW1: post_mpc_federal_student_loans | AX1: post_mpc_state_subsidies | AY1: post_mpc_federal_health_outlays | AZ1: post_mpc_state_health_outlays
A2: 1970 Q1 | B2: historical | C2: 1 | D2: 0.013203927 | E2: 0.019889412 | F2: 0.025154004 | G2: 0.021142316 | H2: 0.011057396 | I2: 0.0081228798 | J2: 1051.2 | K2: 631.7 | L2: 0 | M2: 133.6 | N2: 0 | O2: 5.576 | P2: 114.3 | Q2: 153.6 | R2: 85.7 | S2: 27 | T2: 0 | U2: 3.8 | V2: 38.4 | W2: 9.7 | X2: 0 | Y2: 0 | Z2: 0 | AA2: 2.9 | AB2: 4.7 | AC2: 0 | AD2: 0 | AE2: 0 | AF2: 0 | AG2: 0 | AH2: 7 | AI2: 5 | AJ2: -18.432 | AK2: -10.284 | AL2: -0.9 | AM2: -0.12666667 | AN2: 8.64 | AO2: 2.1825 | AP2: 0 | AQ2: 0 | AR2: 0 | AS2: 0.9135 | AT2: 0.23265 | AU2: 0 | AV2: 0 | AW2: 0 | AX2: 0 | AY2: 1.575 | AZ2: 1.125
A3: 1970 Q2 | B3: historical | C3: 1 | D3: 0.013203927 | E3: 0.019889412 | F3: 0.025154004 | G3: 0.021142316 | H3: 0.011057396 | I3: 0.0081228798 | J3: 1067.4 | K3: 641.6 | L3: 0 | M3: 131.8 | N3: 0 | O3: 5.228 | P3: 117.4 | Q3: 154.9 | R3: 87.6 | S3: 27 | T3: 0 | U3: 3.7 | V3: 46.4 | W3: 10.3 | X3: 0 | Y3: 0 | Z3: 0 | AA3: 3.9 | AB3: 4.8 | AC3: 0 | AD3: 0 | AE3: 0 | AF3: 0 | AG3: 0 | AH3: 7.2 | AI3: 5.3 | AJ3: -37.02 | AK3: -20.796 | AL3: -1.8 | AM3: -0.25 | AN3: 19.08 | AO3: 4.5 | AP3: 0 | AQ3: 0 | AR3: 0 | AS3: 2.142 | AT3: 0.438525 | AU3: 0 | AV3: 0 | AW3: 0 | AX3: 0 | AY3: 3.195 | AZ3: 2.3175
A4: 1970 Q3 | B4: historical | C4: 1 | D4: 0.017097349 | E4: 0.017640395 | F4: 0.019341512 | G4: 0.018077874 | H4: 0.0097665192 | I4: 0.0078517882 | J4: 1086.1 | K4: 653.5 | L4: 0 | M4: 132.4 | N4: 0 | O4: 4.816 | P4: 122.2 | Q4: 150.4 | R4: 89.7 | S4: 27.9 | T4: 0 | U4: 3.8 | V4: 45 | W4: 11 | X4: 0 | Y4: 0 | Z4: 0 | AA4: 4.6 | AB4: 4.7 | AC4: 0 | AD4: 0 | AE4: 0 | AF4: 0 | AG4: 0 | AH4: 7.3 | AI4: 5.6 | AJ4: -45.852 | AK4: -26.418 | AL4: -2.73 | AM4: -0.37666667 | AN4: 29.205 | AO4: 6.975 | AP4: 0 | AQ4: 0 | AR4: 0 | AS4: 2.9385 | AT4: 0.6282 | AU4: 0 | AV4: 0 | AW4: 0 | AX4: 0 | AY4: 4.8375 | AZ4: 3.5775
A5: 1970 Q4 | B5: historical | C5: 1 | D5: 0.01270328 | E5: 0.016857506 | F5: 0.025422168 | G5: 0.018971012 | H5: 0.012946451 | I5: 0.0077535197 | J5: 1088.6 | K5: 660.2 | L5: 0 | M5: 133.5 | N5: 0 | O5: 4.9 | P5: 125.2 | Q5: 151 | R5: 91.5 | S5: 26.6 | T5: 0 | U5: 3.6 | V5: 46.9 | W5: 11.6 | X5: 0 | Y5: 0 | Z5: 0 | AA5: 5.4 | AB5: 4.8 | AC5: 0 | AD5: 0 | AE5: 0 | AF5: 0 | AG5: 0 | AH5: 7.5 | AI5: 5.9 | AJ5: -54.678 | AK5: -32.142 | AL5: -3.6166667 | AM5: -0.49666667 | AN5: 39.7575 | AO5: 9.585 | AP5: 0 | AQ5: 0 | AR5: 0 | AS5: 3.762 | AT5: 0.8127 | AU5: 0 | AV5: 0 | AW5: 0 | AX5: 0 | AY5: 6.525 | AZ5: 4.905
A6: 1971 Q1 | B6: historical | C6: -1 | D6: 0.031684239 | E6: 0.02455427 | F6: 0.016827355 | G6: 0.022713732 | H6: 0.009498707 | I6: 0.0079515544 | J6: 1135.2 | K6: 679.2 | L6: 0 | M6: 133.3 | N6: 0 | O6: 5.464 | P6: 128.6 | Q6: 152.6 | R6: 94.1 | S6: 29.9 | T6: 0 | U6: 4.1 | V6: 47.5 | W6: 12.1 | X6: 0 | Y6: 0 | Z6: 0 | AA6: 5.7 | AB6: 4.7 | AC6: 0 | AD6: 0 | AE6: 0 | AF6: 0 | AG6: 0 | AH6: 7.8 | AI6: 6.2 | AJ6: -63.966 | AK6: -38.052 | AL6: -4.6133333 | AM6: -0.63333333 | AN6: 41.805 | AO6: 10.125 | AP6: 0 | AQ6: 0 | AR6: 0 | AS6: 4.392 | AT6: 0.970425 | AU6: 0 | AV6: 0 | AW6: 0 | AX6: 0 | AY6: 6.705 | AZ6: 5.175
A7: 1971 Q2 | B7: historical | C7: -1 | D7: 0.018657303 | E7: 0.018775759 | F7: 0.015959953 | G7: 0.018058691 | H7: 0.011379871 | I7: 0.0084001388 | J7: 1156.3 | K7: 693.2 | L7: 0 | M7: 134.3 | N7: 0 | O7: 6.312 | P7: 131.9 | Q7: 154 | R7: 97 | S7: 30.7 | T7: 0 | U7: 4.2 | V7: 53.6 | W7: 12.5 | X7: 0 | Y7: 0 | Z7: 0 | AA7: 6.3 | AB7: 4.8 | AC7: 0 | AD7: 0 | AE7: 0 | AF7: 0 | AG7: 0 | AH7: 8 | AI7: 6.6 | AJ7: -73.386 | AK7: -44.202 | AL7: -5.6366667 | AM7: -0.77333333 | AN7: 43.425 | AO7: 10.62 | AP7: 0 | AQ7: 0 | AR7: 0 | AS7: 4.986 | AT7: 1.133325 | AU7: 0 | AV7: 0 | AW7: 0 | AX7: 0 | AY7: 6.885 | AZ7: 5.4675
A8: 1971 Q3 | B8: historical | C8: -1 | D8: 0.014508412 | E8: 0.015058436 | F8: 0.010897919 | G8: 0.014090551 | H8: 0.0098392596 | I8: 0.008583691 | J8: 1177.7 | K8: 705.6 | L8: 0 | M8: 135.6 | N8: 0 | O8: 5.756 | P8: 134.2 | Q8: 155.7 | R8: 100 | S8: 29.8 | T8: 0 | U8: 4.4 | V8: 52.8 | W8: 12.7 | X8: 0 | Y8: 0 | Z8: 0 | AA8: 6.3 | AB8: 4.5 | AC8: 0 | AD8: 0 | AE8: 0 | AF8: 0 | AG8: 0 | AH8: 8.1 | AI8: 6.9 | AJ8: -82.914 | AK8: -50.556 | AL8: -6.63 | AM8: -0.92 | AN8: 45.18 | AO8: 11.0025 | AP8: 0 | AQ8: 0 | AR8: 0 | AS8: 5.3505 | AT8: 1.28115 | AU8: 0 | AV8: 0 | AW8: 0 | AX8: 0 | AY8: 7.065 | AZ8: 5.76
A9: 1971 Q4 | B9: historical | C9: -1 | D9: 0.020437142 | E9: 0.0090781607 | F9: 0.017317507 | G9: 0.010932431 | H9: 0.0061740305 | I9: 0.0085645031 | J9: 1190.3 | K9: 721.7 | L9: 0 | M9: 134.7 | N9: 0 | O9: 5.644 | P9: 137.4 | Q9: 158.2 | R9: 103.2 | S9: 30.1 | T9: 0 | U9: 4.5 | V9: 53.6 | W9: 13 | X9: 0 | Y9: 0 | Z9: 0 | AA9: 6.3 | AB9: 4.6 | AC9: 0 | AD9: 0 | AE9: 0 | AF9: 0 | AG9: 0 | AH9: 8.3 | AI9: 7.3 | AJ9: -92.658 | AK9: -57.12 | AL9: -7.6333333 | AM9: -1.07 | AN9: 46.6875 | AO9: 11.3175 | AP9: 0 | AQ9: 0 | AR9: 0 | AS9: 5.499 | AT9: 1.4355 | AU9: 0 | AV9: 0 | AW9: 0 | AX9: 0 | AY9: 7.245 | AZ9: 6.075
A10: 1972 Q1 | B10: historical | C10: -1 | D10: 0.041298082 | E10: 0.025234055 | F10: 0.01279522 | G10: 0.02239587 | H10: 0.0105465 | I10: 0.0082781457 | J10: 1230.6 | K10: 738.9 | L10: 0 | M10: 141.4 | N10: 0 | O10: 5.668 | P10: 140.8 | Q10: 175.8 | R10: 107.2 | S10: 31.8 | T10: 0 | U10: 5 | V10: 55.2 | W10: 13.4 | X10: 0 | Y10: 0 | Z10: 0 | AA10: 6.5 | AB10: 6.1 | AC10: 0 | AD10: 0 | AE10: 0 | AF10: 0 | AG10: 0 | AH10: 8.5 | AI10: 7.8 | AJ10: -95.196 | AK10: -58.842 | AL10: -8.6933333 | AM10: -1.2366667 | AN10: 48.42 | AO10: 11.61 | AP10: 0 | AQ10: 0 | AR10: 0 | AS10: 5.6655 | AT10: 1.6326 | AU10: 0 | AV10: 0 | AW10: 0 | AX10: 0 | AY10: 7.4025 | AZ10: 6.435
A11: 1972 Q2 | B11: historical | C11: -1 | D11: 0.010165609 | E11: 0.013126917 | F11: 0.0070124666 | G11: 0.01180565 | H11: 0.0057874763 | I11: 0.0078393983 | J11: 1266.4 | K11: 757.4 | L11: 0 | M11: 144.2 | N11: 0 | O11: 5.216 | P11: 142.2 | Q11: 178.6 | R11: 110.8 | S11: 32 | T11: 0 | U11: 5 | V11: 54.6 | W11: 13.6 | X11: 0 | Y11: 0 | Z11: 0 | AA11: 6.9 | AB11: 6.2 | AC11: 0 | AD11: 0 | AE11: 0 | AF11: 0 | AG11: 0.1 | AH11: 8.7 | AI11: 8 | AJ11: -97.842 | AK11: -60.69 | AL11: -9.76 | AM11: -1.4033333 | AN11: 48.645 | AO11: 11.8575 | AP11: 0 | AQ11: 0 | AR11: 0 | AS11: 5.895 | AT11: 1.82385 | AU11: 0 | AV11: 0 | AW11: 0 | AX11: 0.00495 | AY11: 7.56 | AZ11: 6.75
A12: 1972 Q3 | B12: historical | C12: -1 | D12: 0.0082207314 | E12: 0.015562284 | F12: 0.013872002 | G12: 0.015175019 | H12: 0.0087727573 | I12: 0.0075857115 | J12: 1290.6 | K12: 775.8 | L12: 0 | M12: 138.8 | N12: 0 | O12: 6.724 | P12: 145.6 | Q12: 180.1 | R12: 112.9 | S12: 33.1 | T12: 0 | U12: 5.2 | V12: 55.6 | W12: 13.9 | X12: 0 | Y12: 0 | Z12: 0 | AA12: 5.8 | AB12: 7.1 | AC12: 0 | AD12: 0 | AE12: 0 | AF12: 0 | AG12: 0.1 | AH12: 8.9 | AI12: 8.6 | AJ12: -99.882 | AK12: -62.424 | AL12: -10.863333 | AM12: -1.5766667 | AN12: 49.275 | AO12: 12.1275 | AP12: 0 | AQ12: 0 | AR12: 0 | AS12: 5.7195 | AT12: 2.0574 | AU12: 0 | AV12: 0 | AW12: 0 | AX12: 0.009225 | AY12: 7.74 | AZ12: 7.1325
A13: 1972 Q4 | B13: historical | C13: -1 | D13: 0.021743205 | E13: 0.012411593 | F13: 0.018697193 | G13: 0.013752325 | H13: 0.008135403 | I13: 0.0075459888 | J13: 1328.9 | K13: 800.5 | L13: 0 | M13: 142.2 | N13: 0 | O13: 5.7 | P13: 149.6 | Q13: 183.7 | R13: 115.7 | S13: 36.6 | T13: 0 | U13: 5.7 | V13: 66.4 | W13: 14 | X13: 0 | Y13: 0 | Z13: 0 | AA13: 5 | AB13: 7 | AC13: 0 | AD13: 0 | AE13: 0 | AF13: 0 | AG13: 0.1 | AH13: 9.2 | AI13: 8.5 | AJ13: -102.15 | AK13: -64.17 | AL13: -12.083333 | AM13: -1.7666667 | AN13: 52.155 | AO13: 12.3525 | AP13: 0 | AQ13: 0 | AR13: 0 | AS13: 5.175 | AT13: 2.2752 | AU13: 0 | AV13: 0 | AW13: 0 | AX13: 0.013275 | AY13: 7.9425 | AZ13: 7.4025
... A260: 2034 Q3 | B260: projection | C260: 0 | D260: 0.0050329839 | E260: 0.0073285833 | F260: 0.0073285833 | G260: 0.0073285833 | H260: 0.0048585564 | I260: 0.0044081166 | J260: 43010.518 | K260: 29595.737 | L260: 0 | M260: 0 | N260: 0 | O260: 0 | P260: 0 | Q260: 0 | R260: 0 | S260: 0 | T260: 0 | U260: 0 | V260: 0 | W260: 0 | X260: 0 | Y260: 0 | Z260: 0 | AA260: 0 | AB260: 0 | AC260: 0 | AD260: 0 | AE260: 0 | AF260: 0 | AG260: 0 | AH260: 0 | AI260: 0 | AJ260: 0 | AK260: 0 | AL260: 0 | AM260: 0 | AN260: 0 | AO260: 0 | AP260: 0 | AQ260: 0 | AR260: 0 | AS260: 0 | AT260: 0 | AU260: 0 | AV260: 0 | AW260: 0 | AX260: 0 | AY260: 0 | AZ260: 0

Sheet Sep 2025
A1: date | B1: id | C1: recession | D1: federal_purchases_deflator_growth | E1: consumption_grants_deflator_growth | F1: investment_grants_deflator_growth | G1: state_purchases_deflator_growth | H1: consumption_deflator_growth | I1: real_potential_gdp_growth | J1: gdp | K1: consumption | L1: uncertainty | M1: federal_purchases | N1: consumption_grants | O1: investment_grants | P1: state_purchases | Q1: federal_non_corporate_taxes | R1: state_non_corporate_taxes | S1: federal_corporate_taxes | T1: supply_side_ira | U1: state_corporate_taxes | V1: federal_social_benefits | W1: state_social_benefits | X1: rebate_checks | Y1: rebate_checks_arp | Z1: federal_ui | AA1: state_ui | AB1: federal_subsidies | AC1: federal_aid_to_small_businesses_arp | AD1: federal_other_direct_aid_arp | AE1: federal_other_vulnerable_arp | AF1: federal_student_loans | AG1: state_subsidies | AH1: federal_health_outlays | AI1: state_health_outlays | AJ1: post_mpc_federal_non_corporate_taxes | AK1: post_mpc_state_non_corporate_taxes | AL1: post_mpc_federal_corporate_taxes | AM1: post_mpc_state_corporate_taxes | AN1: post_mpc_federal_social_benefits | AO1: post_mpc_state_social_benefits | AP1: post_mpc_rebate_checks | AQ1: post_mpc_rebate_checks_arp | AR1: post_mpc_federal_ui | AS1: post_mpc_state_ui | AT1: post_mpc_federal_subsidies | AU1: post_mpc_federal_aid_to_small_businesses_arp | AV1: post_mpc_federal_other_vulnerable_arp | AW1: post_mpc_federal_student_loans | AX1: post_mpc_state_subsidies | AY1: post_mpc_federal_health_outlays | AZ1: post_mpc_state_health_outlays
A2: 1970 Q1 | B2: historical | C2: 1 | D2: 0.013203927 | E2: 0.019889412 | F2: 0.025154004 | G2: 0.021142316 | H2: 0.011057396 | I2: 0.0081228798 | J2: 1051.2 | K2: 631.7 | L2: 0 | M2: 133.6 | N2: 0 | O2: 5.576 | P2: 114.3 | Q2: 153.6 | R2: 85.7 | S2: 27 | T2: 0 | U2: 3.8 | V2: 38.4 | W2: 9.7 | X2: 0 | Y2: 0 | Z2: 0 | AA2: 2.9 | AB2: 4.7 | AC2: 0 | AD2: 0 | AE2: 0 | AF2: 0 | AG2: 0 | AH2: 7 | AI2: 5 | AJ2: -18.432 | AK2: -10.284 | AL2: -0.9 | AM2: -0.12666667 | AN2: 8.64 | AO2: 2.1825 | AP2: 0 | AQ2: 0 | AR2: 0 | AS2: 0.9135 | AT2: 0.23265 | AU2: 0 | AV2: 0 | AW2: 0 | AX2: 0 | AY2: 1.575 | AZ2: 1.125
A3: 1970 Q2 | B3: historical | C3: 1 | D3: 0.013203927 | E3: 0.019889412 | F3: 0.025154004 | G3: 0.021142316 | H3: 0.011057396 | I3: 0.0081228798 | J3: 1067.4 | K3: 641.6 | L3: 0 | M3: 131.8 | N3: 0 | O3: 5.228 | P3: 117.4 | Q3: 154.9 | R3: 87.6 | S3: 27 | T3: 0 | U3: 3.7 | V3: 46.4 | W3: 10.3 | X3: 0 | Y3: 0 | Z3: 0 | AA3: 3.9 | AB3: 4.8 | AC3: 0 | AD3: 0 | AE3: 0 | AF3: 0 | AG3: 0 | AH3: 7.2 | AI3: 5.3 | AJ3: -37.02 | AK3: -20.796 | AL3: -1.8 | AM3: -0.25 | AN3: 19.08 | AO3: 4.5 | AP3: 0 | AQ3: 0 | AR3: 0 | AS3: 2.142 | AT3: 0.438525 | AU3: 0 | AV3: 0 | AW3: 0 | AX3: 0 | AY3: 3.195 | AZ3: 2.3175
A4: 1970 Q3 | B4: historical | C4: 1 | D4: 0.017097349 | E4: 0.017640395 | F4: 0.019341512 | G4: 0.018077874 | H4: 0.0097665192 | I4: 0.0078517882 | J4: 1086.1 | K4: 653.5 | L4: 0 | M4: 132.4 | N4: 0 | O4: 4.816 | P4: 122.2 | Q4: 150.4 | R4: 89.7 | S4: 27.9 | T4: 0 | U4: 3.8 | V4: 45 | W4: 11 | X4: 0 | Y4: 0 | Z4: 0 | AA4: 4.6 | AB4: 4.7 | AC4: 0 | AD4: 0 | AE4: 0 | AF4: 0 | AG4: 0 | AH4: 7.3 | AI4: 5.6 | AJ4: -45.852 | AK4: -26.418 | AL4: -2.73 | AM4: -0.37666667 | AN4: 29.205 | AO4: 6.975 | AP4: 0 | AQ4: 0 | AR4: 0 | AS4: 2.9385 | AT4: 0.6282 | AU4: 0 | AV4: 0 | AW4: 0 | AX4: 0 | AY4: 4.8375 | AZ4: 3.5775
A5: 1970 Q4 | B5: historical | C5: 1 | D5: 0.01270328 | E5: 0.016857506 | F5: 0.025422168 | G5: 0.018971012 | H5: 0.012946451 | I5: 0.0077535197 | J5: 1088.6 | K5: 660.2 | L5: 0 | M5: 133.5 | N5: 0 | O5: 4.9 | P5: 125.2 | Q5: 151 | R5: 91.5 | S5: 26.6 | T5: 0 | U5: 3.6 | V5: 46.9 | W5: 11.6 | X5: 0 | Y5: 0 | Z5: 0 | AA5: 5.4 | AB5: 4.8 | AC5: 0 | AD5: 0 | AE5: 0 | AF5: 0 | AG5: 0 | AH5: 7.5 | AI5: 5.9 | AJ5: -54.678 | AK5: -32.142 | AL5: -3.6166667 | AM5: -0.49666667 | AN5: 39.7575 | AO5: 9.585 | AP5: 0 | AQ5: 0 | AR5: 0 | AS5: 3.762 | AT5: 0.8127 | AU5: 0 | AV5: 0 | AW5: 0 | AX5: 0 | AY5: 6.525 | AZ5: 4.905
A6: 1971 Q1 | B6: historical | C6: -1 | D6: 0.031684239 | E6: 0.02455427 | F6: 0.016827355 | G6: 0.022713732 | H6: 0.009498707 | I6: 0.0079515544 | J6: 1135.2 | K6: 679.2 | L6: 0 | M6: 133.3 | N6: 0 | O6: 5.464 | P6: 128.6 | Q6: 152.6 | R6: 94.1 | S6: 29.9 | T6: 0 | U6: 4.1 | V6: 47.5 | W6: 12.1 | X6: 0 | Y6: 0 | Z6: 0 | AA6: 5.7 | AB6: 4.7 | AC6: 0 | AD6: 0 | AE6: 0 | AF6: 0 | AG6: 0 | AH6: 7.8 | AI6: 6.2 | AJ6: -63.966 | AK6: -38.052 | AL6: -4.6133333 | AM6: -0.63333333 | AN6: 41.805 | AO6: 10.125 | AP6: 0 | AQ6: 0 | AR6: 0 | AS6: 4.392 | AT6: 0.970425 | AU6: 0 | AV6: 0 | AW6: 0 | AX6: 0 | AY6: 6.705 | AZ6: 5.175
A7: 1971 Q2 | B7: historical | C7: -1 | D7: 0.018657303 | E7: 0.018775759 | F7: 0.015959953 | G7: 0.018058691 | H7: 0.011379871 | I7: 0.0084001388 | J7: 1156.3 | K7: 693.2 | L7: 0 | M7: 134.3 | N7: 0 | O7: 6.312 | P7: 131.9 | Q7: 154 | R7: 97 | S7: 30.7 | T7: 0 | U7: 4.2 | V7: 53.6 | W7: 12.5 | X7: 0 | Y7: 0 | Z7: 0 | AA7: 6.3 | AB7: 4.8 | AC7: 0 | AD7: 0 | AE7: 0 | AF7: 0 | AG7: 0 | AH7: 8 | AI7: 6.6 | AJ7: -73.386 | AK7: -44.202 | AL7: -5.6366667 | AM7: -0.77333333 | AN7: 43.425 | AO7: 10.62 | AP7: 0 | AQ7: 0 | AR7: 0 | AS7: 4.986 | AT7: 1.133325 | AU7: 0 | AV7: 0 | AW7: 0 | AX7: 0 | AY7: 6.885 | AZ7: 5.4675
A8: 1971 Q3 | B8: historical | C8: -1 | D8: 0.014508412 | E8: 0.015058436 | F8: 0.010897919 | G8: 0.014090551 | H8: 0.0098392596 | I8: 0.008583691 | J8: 1177.7 | K8: 705.6 | L8: 0 | M8: 135.6 | N8: 0 | O8: 5.756 | P8: 134.2 | Q8: 155.7 | R8: 100 | S8: 29.8 | T8: 0 | U8: 4.4 | V8: 52.8 | W8: 12.7 | X8: 0 | Y8: 0 | Z8: 0 | AA8: 6.3 | AB8: 4.5 | AC8: 0 | AD8: 0 | AE8: 0 | AF8: 0 | AG8: 0 | AH8: 8.1 | AI8: 6.9 | AJ8: -82.914 | AK8: -50.556 | AL8: -6.63 | AM8: -0.92 | AN8: 45.18 | AO8: 11.0025 | AP8: 0 | AQ8: 0 | AR8: 0 | AS8: 5.3505 | AT8: 1.28115 | AU8: 0 | AV8: 0 | AW8: 0 | AX8: 0 | AY8: 7.065 | AZ8: 5.76
A9: 1971 Q4 | B9: historical | C9: -1 | D9: 0.020437142 | E9: 0.0090781607 | F9: 0.017317507 | G9: 0.010932431 | H9: 0.0061740305 | I9: 0.0085645031 | J9: 1190.3 | K9: 721.7 | L9: 0 | M9: 134.7 | N9: 0 | O9: 5.644 | P9: 137.4 | Q9: 158.2 | R9: 103.2 | S9: 30.1 | T9: 0 | U9: 4.5 | V9: 53.6 | W9: 13 | X9: 0 | Y9: 0 | Z9: 0 | AA9: 6.3 | AB9: 4.6 | AC9: 0 | AD9: 0 | AE9: 0 | AF9: 0 | AG9: 0 | AH9: 8.3 | AI9: 7.3 | AJ9: -92.658 | AK9: -57.12 | AL9: -7.6333333 | AM9: -1.07 | AN9: 46.6875 | AO9: 11.3175 | AP9: 0 | AQ9: 0 | AR9: 0 | AS9: 5.499 | AT9: 1.4355 | AU9: 0 | AV9: 0 | AW9: 0 | AX9: 0 | AY9: 7.245 | AZ9: 6.075
A10: 1972 Q1 | B10: historical | C10: -1 | D10: 0.041298082 | E10: 0.025234055 | F10: 0.01279522 | G10: 0.02239587 | H10: 0.0105465 | I10: 0.0082781457 | J10: 1230.6 | K10: 738.9 | L10: 0 | M10: 141.4 | N10: 0 | O10: 5.668 | P10: 140.8 | Q10: 175.8 | R10: 107.2 | S10: 31.8 | T10: 0 | U10: 5 | V10: 55.2 | W10: 13.4 | X10: 0 | Y10: 0 | Z10: 0 | AA10: 6.5 | AB10: 6.1 | AC10: 0 | AD10: 0 | AE10: 0 | AF10: 0 | AG10: 0 | AH10: 8.5 | AI10: 7.8 | AJ10: -95.196 | AK10: -58.842 | AL10: -8.6933333 | AM10: -1.2366667 | AN10: 48.42 | AO10: 11.61 | AP10: 0 | AQ10: 0 | AR10: 0 | AS10: 5.6655 | AT10: 1.6326 | AU10: 0 | AV10: 0 | AW10: 0 | AX10: 0 | AY10: 7.4025 | AZ10: 6.435
A11: 1972 Q2 | B11: historical | C11: -1 | D11: 0.010165609 | E11: 0.013126917 | F11: 0.0070124666 | G11: 0.01180565 | H11: 0.0057874763 | I11: 0.0078393983 | J11: 1266.4 | K11: 757.4 | L11: 0 | M11: 144.2 | N11: 0 | O11: 5.216 | P11: 142.2 | Q11: 178.6 | R11: 110.8 | S11: 32 | T11: 0 | U11: 5 | V11: 54.6 | W11: 13.6 | X11: 0 | Y11: 0 | Z11: 0 | AA11: 6.9 | AB11: 6.2 | AC11: 0 | AD11: 0 | AE11: 0 | AF11: 0 | AG11: 0.1 | AH11: 8.7 | AI11: 8 | AJ11: -97.842 | AK11: -60.69 | AL11: -9.76 | AM11: -1.4033333 | AN11: 48.645 | AO11: 11.8575 | AP11: 0 | AQ11: 0 | AR11: 0 | AS11: 5.895 | AT11: 1.82385 | AU11: 0 | AV11: 0 | AW11: 0 | AX11: 0.00495 | AY11: 7.56 | AZ11: 6.75
A12: 1972 Q3 | B12: historical | C12: -1 | D12: 0.0082207314 | E12: 0.015562284 | F12: 0.013872002 | G12: 0.015175019 | H12: 0.0087727573 | I12: 0.0075857115 | J12: 1290.6 | K12: 775.8 | L12: 0 | M12: 138.8 | N12: 0 | O12: 6.724 | P12: 145.6 | Q12: 180.1 | R12: 112.9 | S12: 33.1 | T12: 0 | U12: 5.2 | V12: 55.6 | W12: 13.9 | X12: 0 | Y12: 0 | Z12: 0 | AA12: 5.8 | AB12: 7.1 | AC12: 0 | AD12: 0 | AE12: 0 | AF12: 0 | AG12: 0.1 | AH12: 8.9 | AI12: 8.6 | AJ12: -99.882 | AK12: -62.424 | AL12: -10.863333 | AM12: -1.5766667 | AN12: 49.275 | AO12: 12.1275 | AP12: 0 | AQ12: 0 | AR12: 0 | AS12: 5.7195 | AT12: 2.0574 | AU12: 0 | AV12: 0 | AW12: 0 | AX12: 0.009225 | AY12: 7.74 | AZ12: 7.1325
A13: 1972 Q4 | B13: historical | C13: -1 | D13: 0.021743205 | E13: 0.012411593 | F13: 0.018697193 | G13: 0.013752325 | H13: 0.008135403 | I13: 0.0075459888 | J13: 1328.9 | K13: 800.5 | L13: 0 | M13: 142.2 | N13: 0 | O13: 5.7 | P13: 149.6 | Q13: 183.7 | R13: 115.7 | S13: 36.6 | T13: 0 | U13: 5.7 | V13: 66.4 | W13: 14 | X13: 0 | Y13: 0 | Z13: 0 | AA13: 5 | AB13: 7 | AC13: 0 | AD13: 0 | AE13: 0 | AF13: 0 | AG13: 0.1 | AH13: 9.2 | AI13: 8.5 | AJ13: -102.15 | AK13: -64.17 | AL13: -12.083333 | AM13: -1.7666667 | AN13: 52.155 | AO13: 12.3525 | AP13: 0 | AQ13: 0 | AR13: 0 | AS13: 5.175 | AT13: 2.2752 | AU13: 0 | AV13: 0 | AW13: 0 | AX13: 0.013275 | AY13: 7.9425 | AZ13: 7.4025
... A260: 2034 Q3 | B260: projection | C260: 0 | D260: 0.0050329839 | E260: 0.0073285833 | F260: 0.0073285833 | G260: 0.0073285833 | H260: 0.0048585564 | I260: 0.0044081166 | J260: 43197.275 | K260: 29805.047 | L260: 0 | M260: 0 | N260: 0 | O260: 0 | P260: 0 | Q260: 0 | R260: 0 | S260: 0 | T260: 0 | U260: 0 | V260: 0 | W260: 0 | X260: 0 | Y260: 0 | Z260: 0 | AA260: 0 | AB260: 0 | AC260: 0 | AD260: 0 | AE260: 0 | AF260: 0 | AG260: 0 | AH260: 0 | AI260: 0 | AJ260: 0 | AK260: 0 | AL260: 0 | AM260: 0 | AN260: 0 | AO260: 0 | AP260: 0 | AQ260: 0 | AR260: 0 | AS260: 0 | AT260: 0 | AU260: 0 | AV260: 0 | AW260: 0 | AX260: 0 | AY260: 0 | AZ260: 0

Sheet diff
A1: date | B1: id | C1: recession | D1: federal_purchases_deflator_growth | E1: consumption_grants_deflator_growth | F1: investment_grants_deflator_growth | G1: state_purchases_deflator_growth | H1: consumption_deflator_growth | I1: real_potential_gdp_growth | J1: gdp | K1: consumption | L1: uncertainty | M1: federal_purchases | N1: consumption_grants | O1: investment_grants | P1: state_purchases | Q1: federal_non_corporate_taxes | R1: state_non_corporate_taxes | S1: total | T1: average | U1: federal_corporate_taxes | V1: supply_side_ira | W1: state_corporate_taxes | X1: federal_social_benefits | Y1: state_social_benefits | Z1: rebate_checks | AA1: rebate_checks_arp | AB1: federal_ui | AC1: state_ui | AD1: federal_subsidies | AE1: federal_aid_to_small_businesses_arp | AF1: federal_other_direct_aid_arp | AG1: federal_other_vulnerable_arp | AH1: federal_student_loans | AI1: state_subsidies | AJ1: federal_health_outlays | AK1: state_health_outlays | AL1: post_mpc_federal_non_corporate_taxes | AM1: post_mpc_state_non_corporate_taxes | AN1: post_mpc_federal_corporate_taxes | AO1: post_mpc_state_corporate_taxes | AP1: post_mpc_federal_social_benefits | AQ1: post_mpc_state_social_benefits | AR1: post_mpc_rebate_checks | AS1: post_mpc_rebate_checks_arp | AT1: post_mpc_federal_ui | AU1: post_mpc_state_ui | AV1: post_mpc_federal_subsidies | AW1: post_mpc_federal_aid_to_small_businesses_arp | AX1: post_mpc_federal_other_vulnerable_arp | AY1: post_mpc_federal_student_loans | AZ1: post_mpc_state_subsidies | BA1: post_mpc_federal_health_outlays | BB1: post_mpc_state_health_outlays | BC1: total
A2: 1970 Q1 | B2: historical | C2: 1 | D2: ='Sep 2025'!D2- 'Oct 2025'!D2 -> 0 | E2: ='Sep 2025'!E2- 'Oct 2025'!E2 -> 0 | F2: ='Sep 2025'!F2- 'Oct 2025'!F2 -> 0 | G2: ='Sep 2025'!G2- 'Oct 2025'!G2 -> 0 | H2: ='Sep 2025'!H2- 'Oct 2025'!H2 -> 0 | I2: ='Sep 2025'!I2- 'Oct 2025'!I2 -> 0 | J2: ='Sep 2025'!J2- 'Oct 2025'!J2 -> 0 | K2: ='Sep 2025'!K2- 'Oct 2025'!K2 -> 0 | ... R2: ='Sep 2025'!R2- 'Oct 2025'!R2 -> 0 | S2: =Q2+R2 -> 0 | U2: ='Sep 2025'!S2- 'Oct 2025'!S2 -> 0 | V2: ='Sep 2025'!T2- 'Oct 2025'!T2 -> 0 | W2: ='Sep 2025'!U2- 'Oct 2025'!U2 -> 0 | X2: ='Sep 2025'!V2- 'Oct 2025'!V2 -> 0 | Y2: ='Sep 2025'!W2- 'Oct 2025'!W2 -> 0 | Z2: ='Sep 2025'!X2- 'Oct 2025'!X2 -> 0 | AA2: ='Sep 2025'!Y2- 'Oct 2025'!Y2 -> 0 | AB2: ='Sep 2025'!Z2- 'Oct 2025'!Z2 -> 0 | ... BB2: ='Sep 2025'!AZ2- 'Oct 2025'!AZ2 -> 0 | BC2: =X2+Y2+SUM(AJ2:AK2) -> 0
A3: 1970 Q2 | B3: historical | C3: 1 | D3: ='Sep 2025'!D3- 'Oct 2025'!D3 -> 0 | E3: ='Sep 2025'!E3- 'Oct 2025'!E3 -> 0 | F3: ='Sep 2025'!F3- 'Oct 2025'!F3 -> 0 | G3: ='Sep 2025'!G3- 'Oct 2025'!G3 -> 0 | H3: ='Sep 2025'!H3- 'Oct 2025'!H3 -> 0 | I3: ='Sep 2025'!I3- 'Oct 2025'!I3 -> 0 | J3: ='Sep 2025'!J3- 'Oct 2025'!J3 -> 0 | K3: ='Sep 2025'!K3- 'Oct 2025'!K3 -> 0 | ... R3: ='Sep 2025'!R3- 'Oct 2025'!R3 -> 0 | S3: =Q3+R3 -> 0 | U3: ='Sep 2025'!S3- 'Oct 2025'!S3 -> 0 | V3: ='Sep 2025'!T3- 'Oct 2025'!T3 -> 0 | W3: ='Sep 2025'!U3- 'Oct 2025'!U3 -> 0 | X3: ='Sep 2025'!V3- 'Oct 2025'!V3 -> 0 | Y3: ='Sep 2025'!W3- 'Oct 2025'!W3 -> 0 | Z3: ='Sep 2025'!X3- 'Oct 2025'!X3 -> 0 | AA3: ='Sep 2025'!Y3- 'Oct 2025'!Y3 -> 0 | AB3: ='Sep 2025'!Z3- 'Oct 2025'!Z3 -> 0 | ... BB3: ='Sep 2025'!AZ3- 'Oct 2025'!AZ3 -> 0 | BC3: =X3+Y3+SUM(AJ3:AK3) -> 0
A4: 1970 Q3 | B4: historical | C4: 1 | D4: ='Sep 2025'!D4- 'Oct 2025'!D4 -> 0 | E4: ='Sep 2025'!E4- 'Oct 2025'!E4 -> 0 | F4: ='Sep 2025'!F4- 'Oct 2025'!F4 -> 0 | G4: ='Sep 2025'!G4- 'Oct 2025'!G4 -> 0 | H4: ='Sep 2025'!H4- 'Oct 2025'!H4 -> 0 | I4: ='Sep 2025'!I4- 'Oct 2025'!I4 -> 0 | J4: ='Sep 2025'!J4- 'Oct 2025'!J4 -> 0 | K4: ='Sep 2025'!K4- 'Oct 2025'!K4 -> 0 | ... R4: ='Sep 2025'!R4- 'Oct 2025'!R4 -> 0 | S4: =Q4+R4 -> 0 | U4: ='Sep 2025'!S4- 'Oct 2025'!S4 -> 0 | V4: ='Sep 2025'!T4- 'Oct 2025'!T4 -> 0 | W4: ='Sep 2025'!U4- 'Oct 2025'!U4 -> 0 | X4: ='Sep 2025'!V4- 'Oct 2025'!V4 -> 0 | Y4: ='Sep 2025'!W4- 'Oct 2025'!W4 -> 0 | Z4: ='Sep 2025'!X4- 'Oct 2025'!X4 -> 0 | AA4: ='Sep 2025'!Y4- 'Oct 2025'!Y4 -> 0 | AB4: ='Sep 2025'!Z4- 'Oct 2025'!Z4 -> 0 | ... BB4: ='Sep 2025'!AZ4- 'Oct 2025'!AZ4 -> 0 | BC4: =X4+Y4+SUM(AJ4:AK4) -> 0
A5: 1970 Q4 | B5: historical | C5: 1 | D5: ='Sep 2025'!D5- 'Oct 2025'!D5 -> 0 | E5: ='Sep 2025'!E5- 'Oct 2025'!E5 -> 0 | F5: ='Sep 2025'!F5- 'Oct 2025'!F5 -> 0 | G5: ='Sep 2025'!G5- 'Oct 2025'!G5 -> 0 | H5: ='Sep 2025'!H5- 'Oct 2025'!H5 -> 0 | I5: ='Sep 2025'!I5- 'Oct 2025'!I5 -> 0 | J5: ='Sep 2025'!J5- 'Oct 2025'!J5 -> 0 | K5: ='Sep 2025'!K5- 'Oct 2025'!K5 -> 0 | ... R5: ='Sep 2025'!R5- 'Oct 2025'!R5 -> 0 | S5: =Q5+R5 -> 0 | U5: ='Sep 2025'!S5- 'Oct 2025'!S5 -> 0 | V5: ='Sep 2025'!T5- 'Oct 2025'!T5 -> 0 | W5: ='Sep 2025'!U5- 'Oct 2025'!U5 -> 0 | X5: ='Sep 2025'!V5- 'Oct 2025'!V5 -> 0 | Y5: ='Sep 2025'!W5- 'Oct 2025'!W5 -> 0 | Z5: ='Sep 2025'!X5- 'Oct 2025'!X5 -> 0 | AA5: ='Sep 2025'!Y5- 'Oct 2025'!Y5 -> 0 | AB5: ='Sep 2025'!Z5- 'Oct 2025'!Z5 -> 0 | ... BB5: ='Sep 2025'!AZ5- 'Oct 2025'!AZ5 -> 0 | BC5: =X5+Y5+SUM(AJ5:AK5) -> 0
A6: 1971 Q1 | B6: historical | C6: -1 | D6: ='Sep 2025'!D6- 'Oct 2025'!D6 -> 0 | E6: ='Sep 2025'!E6- 'Oct 2025'!E6 -> 0 | F6: ='Sep 2025'!F6- 'Oct 2025'!F6 -> 0 | G6: ='Sep 2025'!G6- 'Oct 2025'!G6 -> 0 | H6: ='Sep 2025'!H6- 'Oct 2025'!H6 -> 0 | I6: ='Sep 2025'!I6- 'Oct 2025'!I6 -> 0 | J6: ='Sep 2025'!J6- 'Oct 2025'!J6 -> 0 | K6: ='Sep 2025'!K6- 'Oct 2025'!K6 -> 0 | ... R6: ='Sep 2025'!R6- 'Oct 2025'!R6 -> 0 | S6: =Q6+R6 -> 0 | U6: ='Sep 2025'!S6- 'Oct 2025'!S6 -> 0 | V6: ='Sep 2025'!T6- 'Oct 2025'!T6 -> 0 | W6: ='Sep 2025'!U6- 'Oct 2025'!U6 -> 0 | X6: ='Sep 2025'!V6- 'Oct 2025'!V6 -> 0 | Y6: ='Sep 2025'!W6- 'Oct 2025'!W6 -> 0 | Z6: ='Sep 2025'!X6- 'Oct 2025'!X6 -> 0 | AA6: ='Sep 2025'!Y6- 'Oct 2025'!Y6 -> 0 | AB6: ='Sep 2025'!Z6- 'Oct 2025'!Z6 -> 0 | ... BB6: ='Sep 2025'!AZ6- 'Oct 2025'!AZ6 -> 0 | BC6: =X6+Y6+SUM(AJ6:AK6) -> 0
A7: 1971 Q2 | B7: historical | C7: -1 | D7: ='Sep 2025'!D7- 'Oct 2025'!D7 -> 0 | E7: ='Sep 2025'!E7- 'Oct 2025'!E7 -> 0 | F7: ='Sep 2025'!F7- 'Oct 2025'!F7 -> 0 | G7: ='Sep 2025'!G7- 'Oct 2025'!G7 -> 0 | H7: ='Sep 2025'!H7- 'Oct 2025'!H7 -> 0 | I7: ='Sep 2025'!I7- 'Oct 2025'!I7 -> 0 | J7: ='Sep 2025'!J7- 'Oct 2025'!J7 -> 0 | K7: ='Sep 2025'!K7- 'Oct 2025'!K7 -> 0 | ... R7: ='Sep 2025'!R7- 'Oct 2025'!R7 -> 0 | S7: =Q7+R7 -> 0 | U7: ='Sep 2025'!S7- 'Oct 2025'!S7 -> 0 | V7: ='Sep 2025'!T7- 'Oct 2025'!T7 -> 0 | W7: ='Sep 2025'!U7- 'Oct 2025'!U7 -> 0 | X7: ='Sep 2025'!V7- 'Oct 2025'!V7 -> 0 | Y7: ='Sep 2025'!W7- 'Oct 2025'!W7 -> 0 | Z7: ='Sep 2025'!X7- 'Oct 2025'!X7 -> 0 | AA7: ='Sep 2025'!Y7- 'Oct 2025'!Y7 -> 0 | AB7: ='Sep 2025'!Z7- 'Oct 2025'!Z7 -> 0 | ... BB7: ='Sep 2025'!AZ7- 'Oct 2025'!AZ7 -> 0 | BC7: =X7+Y7+SUM(AJ7:AK7) -> 0
A8: 1971 Q3 | B8: historical | C8: -1 | D8: ='Sep 2025'!D8- 'Oct 2025'!D8 -> 0 | E8: ='Sep 2025'!E8- 'Oct 2025'!E8 -> 0 | F8: ='Sep 2025'!F8- 'Oct 2025'!F8 -> 0 | G8: ='Sep 2025'!G8- 'Oct 2025'!G8 -> 0 | H8: ='Sep 2025'!H8- 'Oct 2025'!H8 -> 0 | I8: ='Sep 2025'!I8- 'Oct 2025'!I8 -> 0 | J8: ='Sep 2025'!J8- 'Oct 2025'!J8 -> 0 | K8: ='Sep 2025'!K8- 'Oct 2025'!K8 -> 0 | ... R8: ='Sep 2025'!R8- 'Oct 2025'!R8 -> 0 | S8: =Q8+R8 -> 0 | U8: ='Sep 2025'!S8- 'Oct 2025'!S8 -> 0 | V8: ='Sep 2025'!T8- 'Oct 2025'!T8 -> 0 | W8: ='Sep 2025'!U8- 'Oct 2025'!U8 -> 0 | X8: ='Sep 2025'!V8- 'Oct 2025'!V8 -> 0 | Y8: ='Sep 2025'!W8- 'Oct 2025'!W8 -> 0 | Z8: ='Sep 2025'!X8- 'Oct 2025'!X8 -> 0 | AA8: ='Sep 2025'!Y8- 'Oct 2025'!Y8 -> 0 | AB8: ='Sep 2025'!Z8- 'Oct 2025'!Z8 -> 0 | ... BB8: ='Sep 2025'!AZ8- 'Oct 2025'!AZ8 -> 0 | BC8: =X8+Y8+SUM(AJ8:AK8) -> 0
A9: 1971 Q4 | B9: historical | C9: -1 | D9: ='Sep 2025'!D9- 'Oct 2025'!D9 -> 0 | E9: ='Sep 2025'!E9- 'Oct 2025'!E9 -> 0 | F9: ='Sep 2025'!F9- 'Oct 2025'!F9 -> 0 | G9: ='Sep 2025'!G9- 'Oct 2025'!G9 -> 0 | H9: ='Sep 2025'!H9- 'Oct 2025'!H9 -> 0 | I9: ='Sep 2025'!I9- 'Oct 2025'!I9 -> 0 | J9: ='Sep 2025'!J9- 'Oct 2025'!J9 -> 0 | K9: ='Sep 2025'!K9- 'Oct 2025'!K9 -> 0 | ... R9: ='Sep 2025'!R9- 'Oct 2025'!R9 -> 0 | S9: =Q9+R9 -> 0 | U9: ='Sep 2025'!S9- 'Oct 2025'!S9 -> 0 | V9: ='Sep 2025'!T9- 'Oct 2025'!T9 -> 0 | W9: ='Sep 2025'!U9- 'Oct 2025'!U9 -> 0 | X9: ='Sep 2025'!V9- 'Oct 2025'!V9 -> 0 | Y9: ='Sep 2025'!W9- 'Oct 2025'!W9 -> 0 | Z9: ='Sep 2025'!X9- 'Oct 2025'!X9 -> 0 | AA9: ='Sep 2025'!Y9- 'Oct 2025'!Y9 -> 0 | AB9: ='Sep 2025'!Z9- 'Oct 2025'!Z9 -> 0 | ... BB9: ='Sep 2025'!AZ9- 'Oct 2025'!AZ9 -> 0 | BC9: =X9+Y9+SUM(AJ9:AK9) -> 0
A10: 1972 Q1 | B10: historical | C10: -1 | D10: ='Sep 2025'!D10- 'Oct 2025'!D10 -> 0 | E10: ='Sep 2025'!E10- 'Oct 2025'!E10 -> 0 | F10: ='Sep 2025'!F10- 'Oct 2025'!F10 -> 0 | G10: ='Sep 2025'!G10- 'Oct 2025'!G10 -> 0 | H10: ='Sep 2025'!H10- 'Oct 2025'!H10 -> 0 | I10: ='Sep 2025'!I10- 'Oct 2025'!I10 -> 0 | J10: ='Sep 2025'!J10- 'Oct 2025'!J10 -> 0 | K10: ='Sep 2025'!K10- 'Oct 2025'!K10 -> 0 | ... R10: ='Sep 2025'!R10- 'Oct 2025'!R10 -> 0 | S10: =Q10+R10 -> 0 | U10: ='Sep 2025'!S10- 'Oct 2025'!S10 -> 0 | V10: ='Sep 2025'!T10- 'Oct 2025'!T10 -> 0 | W10: ='Sep 2025'!U10- 'Oct 2025'!U10 -> 0 | X10: ='Sep 2025'!V10- 'Oct 2025'!V10 -> 0 | Y10: ='Sep 2025'!W10- 'Oct 2025'!W10 -> 0 | Z10: ='Sep 2025'!X10- 'Oct 2025'!X10 -> 0 | AA10: ='Sep 2025'!Y10- 'Oct 2025'!Y10 -> 0 | AB10: ='Sep 2025'!Z10- 'Oct 2025'!Z10 -> 0 | ... BB10: ='Sep 2025'!AZ10- 'Oct 2025'!AZ10 -> 0 | BC10: =X10+Y10+SUM(AJ10:AK10) -> 0
A11: 1972 Q2 | B11: historical | C11: -1 | D11: ='Sep 2025'!D11- 'Oct 2025'!D11 -> 0 | E11: ='Sep 2025'!E11- 'Oct 2025'!E11 -> 0 | F11: ='Sep 2025'!F11- 'Oct 2025'!F11 -> 0 | G11: ='Sep 2025'!G11- 'Oct 2025'!G11 -> 0 | H11: ='Sep 2025'!H11- 'Oct 2025'!H11 -> 0 | I11: ='Sep 2025'!I11- 'Oct 2025'!I11 -> 0 | J11: ='Sep 2025'!J11- 'Oct 2025'!J11 -> 0 | K11: ='Sep 2025'!K11- 'Oct 2025'!K11 -> 0 | ... R11: ='Sep 2025'!R11- 'Oct 2025'!R11 -> 0 | S11: =Q11+R11 -> 0 | U11: ='Sep 2025'!S11- 'Oct 2025'!S11 -> 0 | V11: ='Sep 2025'!T11- 'Oct 2025'!T11 -> 0 | W11: ='Sep 2025'!U11- 'Oct 2025'!U11 -> 0 | X11: ='Sep 2025'!V11- 'Oct 2025'!V11 -> 0 | Y11: ='Sep 2025'!W11- 'Oct 2025'!W11 -> 0 | Z11: ='Sep 2025'!X11- 'Oct 2025'!X11 -> 0 | AA11: ='Sep 2025'!Y11- 'Oct 2025'!Y11 -> 0 | AB11: ='Sep 2025'!Z11- 'Oct 2025'!Z11 -> 0 | ... BB11: ='Sep 2025'!AZ11- 'Oct 2025'!AZ11 -> 0 | BC11: =X11+Y11+SUM(AJ11:AK11) -> 0
A12: 1972 Q3 | B12: historical | C12: -1 | D12: ='Sep 2025'!D12- 'Oct 2025'!D12 -> 0 | E12: ='Sep 2025'!E12- 'Oct 2025'!E12 -> 0 | F12: ='Sep 2025'!F12- 'Oct 2025'!F12 -> 0 | G12: ='Sep 2025'!G12- 'Oct 2025'!G12 -> 0 | H12: ='Sep 2025'!H12- 'Oct 2025'!H12 -> 0 | I12: ='Sep 2025'!I12- 'Oct 2025'!I12 -> 0 | J12: ='Sep 2025'!J12- 'Oct 2025'!J12 -> 0 | K12: ='Sep 2025'!K12- 'Oct 2025'!K12 -> 0 | ... R12: ='Sep 2025'!R12- 'Oct 2025'!R12 -> 0 | S12: =Q12+R12 -> 0 | U12: ='Sep 2025'!S12- 'Oct 2025'!S12 -> 0 | V12: ='Sep 2025'!T12- 'Oct 2025'!T12 -> 0 | W12: ='Sep 2025'!U12- 'Oct 2025'!U12 -> 0 | X12: ='Sep 2025'!V12- 'Oct 2025'!V12 -> 0 | Y12: ='Sep 2025'!W12- 'Oct 2025'!W12 -> 0 | Z12: ='Sep 2025'!X12- 'Oct 2025'!X12 -> 0 | AA12: ='Sep 2025'!Y12- 'Oct 2025'!Y12 -> 0 | AB12: ='Sep 2025'!Z12- 'Oct 2025'!Z12 -> 0 | ... BB12: ='Sep 2025'!AZ12- 'Oct 2025'!AZ12 -> 0 | BC12: =X12+Y12+SUM(AJ12:AK12) -> 0
A13: 1972 Q4 | B13: historical | C13: -1 | D13: ='Sep 2025'!D13- 'Oct 2025'!D13 -> 0 | E13: ='Sep 2025'!E13- 'Oct 2025'!E13 -> 0 | F13: ='Sep 2025'!F13- 'Oct 2025'!F13 -> 0 | G13: ='Sep 2025'!G13- 'Oct 2025'!G13 -> 0 | H13: ='Sep 2025'!H13- 'Oct 2025'!H13 -> 0 | I13: ='Sep 2025'!I13- 'Oct 2025'!I13 -> 0 | J13: ='Sep 2025'!J13- 'Oct 2025'!J13 -> 0 | K13: ='Sep 2025'!K13- 'Oct 2025'!K13 -> 0 | ... R13: ='Sep 2025'!R13- 'Oct 2025'!R13 -> 0 | S13: =Q13+R13 -> 0 | U13: ='Sep 2025'!S13- 'Oct 2025'!S13 -> 0 | V13: ='Sep 2025'!T13- 'Oct 2025'!T13 -> 0 | W13: ='Sep 2025'!U13- 'Oct 2025'!U13 -> 0 | X13: ='Sep 2025'!V13- 'Oct 2025'!V13 -> 0 | Y13: ='Sep 2025'!W13- 'Oct 2025'!W13 -> 0 | Z13: ='Sep 2025'!X13- 'Oct 2025'!X13 -> 0 | AA13: ='Sep 2025'!Y13- 'Oct 2025'!Y13 -> 0 | AB13: ='Sep 2025'!Z13- 'Oct 2025'!Z13 -> 0 | ... BB13: ='Sep 2025'!AZ13- 'Oct 2025'!AZ13 -> 0 | BC13: =X13+Y13+SUM(AJ13:AK13) -> 0
... A204: 2020 Q3 | B204: historical | C204: -1 | D204: ='Sep 2025'!D204- 'Oct 2025'!D204 -> 0.00020681881 | E204: ='Sep 2025'!E204- 'Oct 2025'!E204 -> 0.0054800318 | F204: ='Sep 2025'!F204- 'Oct 2025'!F204 -> -0.00036766767 | G204: ='Sep 2025'!G204- 'Oct 2025'!G204 -> 0.0044005598 | H204: ='Sep 2025'!H204- 'Oct 2025'!H204 -> -0.00025222198 | I204: ='Sep 2025'!I204- 'Oct 2025'!I204 -> 0 | J204: ='Sep 2025'!J204- 'Oct 2025'!J204 -> 19.8 | K204: ='Sep 2025'!K204- 'Oct 2025'!K204 -> 1.2 | ... R204: ='Sep 2025'!R204- 'Oct 2025'!R204 -> 2.8 | S204: =Q204+R204 -> 3.1 | U204: ='Sep 2025'!S204- 'Oct 2025'!S204 -> -0.9 | V204: ='Sep 2025'!T204- 'Oct 2025'!T204 -> 0 | W204: ='Sep 2025'!U204- 'Oct 2025'!U204 -> 0.1 | X204: ='Sep 2025'!V204- 'Oct 2025'!V204 -> -0.3 | Y204: ='Sep 2025'!W204- 'Oct 2025'!W204 -> 0.1 | Z204: ='Sep 2025'!X204- 'Oct 2025'!X204 -> 0 | AA204: ='Sep 2025'!Y204- 'Oct 2025'!Y204 -> 0 | AB204: ='Sep 2025'!Z204- 'Oct 2025'!Z204 -> 0 | ... BB204: ='Sep 2025'!AZ204- 'Oct 2025'!AZ204 -> -0.643275 | BC204: =X204+Y204+SUM(AJ204:AK204) -> 8.5
A205: 2020 Q4 | B205: historical | C205: -1 | D205: ='Sep 2025'!D205- 'Oct 2025'!D205 -> -8.1172625e-05 | E205: ='Sep 2025'!E205- 'Oct 2025'!E205 -> -0.0082734901 | F205: ='Sep 2025'!F205- 'Oct 2025'!F205 -> 8.3439453e-05 | G205: ='Sep 2025'!G205- 'Oct 2025'!G205 -> -0.0067552712 | H205: ='Sep 2025'!H205- 'Oct 2025'!H205 -> 0.0002478701 | I205: ='Sep 2025'!I205- 'Oct 2025'!I205 -> 0 | J205: ='Sep 2025'!J205- 'Oct 2025'!J205 -> 18.4 | K205: ='Sep 2025'!K205- 'Oct 2025'!K205 -> -2.9 | ... R205: ='Sep 2025'!R205- 'Oct 2025'!R205 -> 1.2 | S205: =Q205+R205 -> 1.2 | T205: =AVERAGE(S202:S205) -> 2.825 | U205: ='Sep 2025'!S205- 'Oct 2025'!S205 -> -0.2 | V205: ='Sep 2025'!T205- 'Oct 2025'!T205 -> 0 | W205: ='Sep 2025'!U205- 'Oct 2025'!U205 -> -4.2 | X205: ='Sep 2025'!V205- 'Oct 2025'!V205 -> -0.3 | Y205: ='Sep 2025'!W205- 'Oct 2025'!W205 -> 0.6 | Z205: ='Sep 2025'!X205- 'Oct 2025'!X205 -> 0 | AA205: ='Sep 2025'!Y205- 'Oct 2025'!Y205 -> 0 | AB205: ='Sep 2025'!Z205- 'Oct 2025'!Z205 -> 0 | ... BB205: ='Sep 2025'!AZ205- 'Oct 2025'!AZ205 -> -0.045225 | BC205: =X205+Y205+SUM(AJ205:AK205) -> 9.5 | BD205: =AVERAGE(BC202:BC205) -> 7
A206: 2021 Q1 | B206: historical | C206: -1 | D206: ='Sep 2025'!D206- 'Oct 2025'!D206 -> -0.00026826521 | E206: ='Sep 2025'!E206- 'Oct 2025'!E206 -> -2.4904095e-05 | F206: ='Sep 2025'!F206- 'Oct 2025'!F206 -> -0.00031388769 | G206: ='Sep 2025'!G206- 'Oct 2025'!G206 -> -0.0001085028 | H206: ='Sep 2025'!H206- 'Oct 2025'!H206 -> 8.2307599e-05 | I206: ='Sep 2025'!I206- 'Oct 2025'!I206 -> 0 | J206: ='Sep 2025'!J206- 'Oct 2025'!J206 -> 23.9 | K206: ='Sep 2025'!K206- 'Oct 2025'!K206 -> -4 | ... R206: ='Sep 2025'!R206- 'Oct 2025'!R206 -> -4.2 | S206: =Q206+R206 -> -1 | U206: ='Sep 2025'!S206- 'Oct 2025'!S206 -> -9.9 | V206: ='Sep 2025'!T206- 'Oct 2025'!T206 -> 0 | W206: ='Sep 2025'!U206- 'Oct 2025'!U206 -> -1.5 | X206: ='Sep 2025'!V206- 'Oct 2025'!V206 -> 1.5 | Y206: ='Sep 2025'!W206- 'Oct 2025'!W206 -> 1.1 | Z206: ='Sep 2025'!X206- 'Oct 2025'!X206 -> 0 | AA206: ='Sep 2025'!Y206- 'Oct 2025'!Y206 -> 0 | AB206: ='Sep 2025'!Z206- 'Oct 2025'!Z206 -> 0 | ... BB206: ='Sep 2025'!AZ206- 'Oct 2025'!AZ206 -> -0.1107 | BC206: =X206+Y206+SUM(AJ206:AK206) -> 11
A207: 2021 Q2 | B207: historical | C207: -1 | D207: ='Sep 2025'!D207- 'Oct 2025'!D207 -> -0.00029344989 | E207: ='Sep 2025'!E207- 'Oct 2025'!E207 -> 0.00034439791 | F207: ='Sep 2025'!F207- 'Oct 2025'!F207 -> 0.00070493417 | G207: ='Sep 2025'!G207- 'Oct 2025'!G207 -> 0.00040400918 | H207: ='Sep 2025'!H207- 'Oct 2025'!H207 -> -0.0003996714 | I207: ='Sep 2025'!I207- 'Oct 2025'!I207 -> 0 | J207: ='Sep 2025'!J207- 'Oct 2025'!J207 -> 57 | K207: ='Sep 2025'!K207- 'Oct 2025'!K207 -> 11.3 | ... R207: ='Sep 2025'!R207- 'Oct 2025'!R207 -> -13.2 | S207: =Q207+R207 -> -8.9 | U207: ='Sep 2025'!S207- 'Oct 2025'!S207 -> -4.6 | V207: ='Sep 2025'!T207- 'Oct 2025'!T207 -> 0 | W207: ='Sep 2025'!U207- 'Oct 2025'!U207 -> 5.9 | X207: ='Sep 2025'!V207- 'Oct 2025'!V207 -> 0.9 | Y207: ='Sep 2025'!W207- 'Oct 2025'!W207 -> 1 | Z207: ='Sep 2025'!X207- 'Oct 2025'!X207 -> 0 | AA207: ='Sep 2025'!Y207- 'Oct 2025'!Y207 -> 0 | AB207: ='Sep 2025'!Z207- 'Oct 2025'!Z207 -> 0 | ... BB207: ='Sep 2025'!AZ207- 'Oct 2025'!AZ207 -> -0.635175 | BC207: =X207+Y207+SUM(AJ207:AK207) -> 9.5
A208: 2021 Q3 | B208: historical | C208: -1 | D208: ='Sep 2025'!D208- 'Oct 2025'!D208 -> -0.00020424903 | E208: ='Sep 2025'!E208- 'Oct 2025'!E208 -> 0.0081831697 | F208: ='Sep 2025'!F208- 'Oct 2025'!F208 -> -0.00070102817 | G208: ='Sep 2025'!G208- 'Oct 2025'!G208 -> 0.0066583342 | H208: ='Sep 2025'!H208- 'Oct 2025'!H208 -> -0.000202847 | I208: ='Sep 2025'!I208- 'Oct 2025'!I208 -> 0 | J208: ='Sep 2025'!J208- 'Oct 2025'!J208 -> 60.4 | K208: ='Sep 2025'!K208- 'Oct 2025'!K208 -> 16.8 | ... R208: ='Sep 2025'!R208- 'Oct 2025'!R208 -> -13.2 | S208: =Q208+R208 -> -10.7 | U208: ='Sep 2025'!S208- 'Oct 2025'!S208 -> 4.2 | V208: ='Sep 2025'!T208- 'Oct 2025'!T208 -> 0 | W208: ='Sep 2025'!U208- 'Oct 2025'!U208 -> 4.4 | X208: ='Sep 2025'!V208- 'Oct 2025'!V208 -> -0.1 | Y208: ='Sep 2025'!W208- 'Oct 2025'!W208 -> -0.1 | Z208: ='Sep 2025'!X208- 'Oct 2025'!X208 -> 0 | AA208: ='Sep 2025'!Y208- 'Oct 2025'!Y208 -> 0 | AB208: ='Sep 2025'!Z208- 'Oct 2025'!Z208 -> 0 | ... BB208: ='Sep 2025'!AZ208- 'Oct 2025'!AZ208 -> -0.2025 | BC208: =X208+Y208+SUM(AJ208:AK208) -> 6.7
A209: 2021 Q4 | B209: historical | C209: -1 | D209: ='Sep 2025'!D209- 'Oct 2025'!D209 -> 1.97361e-05 | E209: ='Sep 2025'!E209- 'Oct 2025'!E209 -> -0.002676098 | F209: ='Sep 2025'!F209- 'Oct 2025'!F209 -> -3.5926178e-05 | G209: ='Sep 2025'!G209- 'Oct 2025'!G209 -> -0.0022203473 | H209: ='Sep 2025'!H209- 'Oct 2025'!H209 -> 0.00017718355 | I209: ='Sep 2025'!I209- 'Oct 2025'!I209 -> 0 | J209: ='Sep 2025'!J209- 'Oct 2025'!J209 -> 36.6 | K209: ='Sep 2025'!K209- 'Oct 2025'!K209 -> -1.1 | ... R209: ='Sep 2025'!R209- 'Oct 2025'!R209 -> -8.4 | S209: =Q209+R209 -> -8.6 | T209: =AVERAGE(S206:S209) -> -7.3 | U209: ='Sep 2025'!S209- 'Oct 2025'!S209 -> 16.1 | V209: ='Sep 2025'!T209- 'Oct 2025'!T209 -> 0 | W209: ='Sep 2025'!U209- 'Oct 2025'!U209 -> 5.3 | X209: ='Sep 2025'!V209- 'Oct 2025'!V209 -> 0.4 | Y209: ='Sep 2025'!W209- 'Oct 2025'!W209 -> -1.9 | Z209: ='Sep 2025'!X209- 'Oct 2025'!X209 -> 0 | AA209: ='Sep 2025'!Y209- 'Oct 2025'!Y209 -> 0 | AB209: ='Sep 2025'!Z209- 'Oct 2025'!Z209 -> 0 | ... BB209: ='Sep 2025'!AZ209- 'Oct 2025'!AZ209 -> -0.022725 | BC209: =X209+Y209+SUM(AJ209:AK209) -> 5 | BD209: =AVERAGE(BC206:BC209) -> 8.05
A210: 2022 Q1 | B210: historical | C210: -1 | D210: ='Sep 2025'!D210- 'Oct 2025'!D210 -> -0.00023297101 | E210: ='Sep 2025'!E210- 'Oct 2025'!E210 -> -0.0012035586 | F210: ='Sep 2025'!F210- 'Oct 2025'!F210 -> -0.00031199421 | G210: ='Sep 2025'!G210- 'Oct 2025'!G210 -> -0.0010433446 | H210: ='Sep 2025'!H210- 'Oct 2025'!H210 -> 3.7058883e-05 | I210: ='Sep 2025'!I210- 'Oct 2025'!I210 -> 0 | J210: ='Sep 2025'!J210- 'Oct 2025'!J210 -> 34.8 | K210: ='Sep 2025'!K210- 'Oct 2025'!K210 -> -26.1 | ... R210: ='Sep 2025'!R210- 'Oct 2025'!R210 -> -0.1 | S210: =Q210+R210 -> 0.6 | U210: ='Sep 2025'!S210- 'Oct 2025'!S210 -> 5.4 | V210: ='Sep 2025'!T210- 'Oct 2025'!T210 -> 0 | W210: ='Sep 2025'!U210- 'Oct 2025'!U210 -> 13.9 | X210: ='Sep 2025'!V210- 'Oct 2025'!V210 -> 1.5 | Y210: ='Sep 2025'!W210- 'Oct 2025'!W210 -> -4.5 | Z210: ='Sep 2025'!X210- 'Oct 2025'!X210 -> 0 | AA210: ='Sep 2025'!Y210- 'Oct 2025'!Y210 -> 0 | AB210: ='Sep 2025'!Z210- 'Oct 2025'!Z210 -> 0 | ... BB210: ='Sep 2025'!AZ210- 'Oct 2025'!AZ210 -> -0.04995 | BC210: =X210+Y210+SUM(AJ210:AK210) -> 3.3
A211: 2022 Q2 | B211: historical | C211: -1 | D211: ='Sep 2025'!D211- 'Oct 2025'!D211 -> -2.95385e-05 | E211: ='Sep 2025'!E211- 'Oct 2025'!E211 -> -0.0013773253 | F211: ='Sep 2025'!F211- 'Oct 2025'!F211 -> 0.0009617153 | G211: ='Sep 2025'!G211- 'Oct 2025'!G211 -> -0.00097562623 | H211: ='Sep 2025'!H211- 'Oct 2025'!H211 -> -9.6361028e-05 | I211: ='Sep 2025'!I211- 'Oct 2025'!I211 -> 0 | J211: ='Sep 2025'!J211- 'Oct 2025'!J211 -> 55.5 | K211: ='Sep 2025'!K211- 'Oct 2025'!K211 -> 2.8 | ... R211: ='Sep 2025'!R211- 'Oct 2025'!R211 -> -7.1 | S211: =Q211+R211 -> -7.2 | U211: ='Sep 2025'!S211- 'Oct 2025'!S211 -> 8.5 | V211: ='Sep 2025'!T211- 'Oct 2025'!T211 -> 0 | W211: ='Sep 2025'!U211- 'Oct 2025'!U211 -> 6.8 | X211: ='Sep 2025'!V211- 'Oct 2025'!V211 -> 0.6 | Y211: ='Sep 2025'!W211- 'Oct 2025'!W211 -> -6.9 | Z211: ='Sep 2025'!X211- 'Oct 2025'!X211 -> 0 | AA211: ='Sep 2025'!Y211- 'Oct 2025'!Y211 -> 0 | AB211: ='Sep 2025'!Z211- 'Oct 2025'!Z211 -> 0 | ... BB211: ='Sep 2025'!AZ211- 'Oct 2025'!AZ211 -> -1.09485 | BC211: =X211+Y211+SUM(AJ211:AK211) -> 0.2
A212: 2022 Q3 | B212: historical | C212: -1 | D212: ='Sep 2025'!D212- 'Oct 2025'!D212 -> 0.00051058838 | E212: ='Sep 2025'!E212- 'Oct 2025'!E212 -> 0.0011702494 | F212: ='Sep 2025'!F212- 'Oct 2025'!F212 -> -0.0010777276 | G212: ='Sep 2025'!G212- 'Oct 2025'!G212 -> 0.00085182047 | H212: ='Sep 2025'!H212- 'Oct 2025'!H212 -> -0.00011964218 | I212: ='Sep 2025'!I212- 'Oct 2025'!I212 -> 0 | J212: ='Sep 2025'!J212- 'Oct 2025'!J212 -> 64.3 | K212: ='Sep 2025'!K212- 'Oct 2025'!K212 -> 16.9 | ... R212: ='Sep 2025'!R212- 'Oct 2025'!R212 -> -16.8 | S212: =Q212+R212 -> -19.7 | U212: ='Sep 2025'!S212- 'Oct 2025'!S212 -> 14.7 | V212: ='Sep 2025'!T212- 'Oct 2025'!T212 -> 0 | W212: ='Sep 2025'!U212- 'Oct 2025'!U212 -> 10.5 | X212: ='Sep 2025'!V212- 'Oct 2025'!V212 -> -1.2 | Y212: ='Sep 2025'!W212- 'Oct 2025'!W212 -> -9.5 | Z212: ='Sep 2025'!X212- 'Oct 2025'!X212 -> 0 | AA212: ='Sep 2025'!Y212- 'Oct 2025'!Y212 -> 0 | AB212: ='Sep 2025'!Z212- 'Oct 2025'!Z212 -> 0 | ... BB212: ='Sep 2025'!AZ212- 'Oct 2025'!AZ212 -> -0.28305 | BC212: =X212+Y212+SUM(AJ212:AK212) -> -3.2
A213: 2022 Q4 | B213: historical | C213: -1 | D213: ='Sep 2025'!D213- 'Oct 2025'!D213 -> -0.00046620667 | E213: ='Sep 2025'!E213- 'Oct 2025'!E213 -> 0.0059370213 | F213: ='Sep 2025'!F213- 'Oct 2025'!F213 -> 0.00021125545 | G213: ='Sep 2025'!G213- 'Oct 2025'!G213 -> 0.0049538225 | H213: ='Sep 2025'!H213- 'Oct 2025'!H213 -> 0.00027590562 | I213: ='Sep 2025'!I213- 'Oct 2025'!I213 -> 0 | J213: ='Sep 2025'!J213- 'Oct 2025'!J213 -> 36.2 | K213: ='Sep 2025'!K213- 'Oct 2025'!K213 -> 3.1 | ... R213: ='Sep 2025'!R213- 'Oct 2025'!R213 -> -40.2 | S213: =Q213+R213 -> -44.8 | T213: =AVERAGE(S210:S213) -> -17.775 | U213: ='Sep 2025'!S213- 'Oct 2025'!S213 -> 12.4 | V213: ='Sep 2025'!T213- 'Oct 2025'!T213 -> 0 | W213: ='Sep 2025'!U213- 'Oct 2025'!U213 -> 16.6 | X213: ='Sep 2025'!V213- 'Oct 2025'!V213 -> -0.6 | Y213: ='Sep 2025'!W213- 'Oct 2025'!W213 -> -12.1 | Z213: ='Sep 2025'!X213- 'Oct 2025'!X213 -> 0 | AA213: ='Sep 2025'!Y213- 'Oct 2025'!Y213 -> 0 | AB213: ='Sep 2025'!Z213- 'Oct 2025'!Z213 -> 0 | ... BB213: ='Sep 2025'!AZ213- 'Oct 2025'!AZ213 -> -0.045225 | BC213: =X213+Y213+SUM(AJ213:AK213) -> -3.6 | BD213: =AVERAGE(BC210:BC213) -> -0.825
A214: 2023 Q1 | B214: historical | C214: -1 | D214: ='Sep 2025'!D214- 'Oct 2025'!D214 -> 0.000608439 | E214: ='Sep 2025'!E214- 'Oct 2025'!E214 -> 0.0082385619 | F214: ='Sep 2025'!F214- 'Oct 2025'!F214 -> -0.00062869056 | G214: ='Sep 2025'!G214- 'Oct 2025'!G214 -> 0.0067135188 | H214: ='Sep 2025'!H214- 'Oct 2025'!H214 -> -0.0001357201 | I214: ='Sep 2025'!I214- 'Oct 2025'!I214 -> 0 | J214: ='Sep 2025'!J214- 'Oct 2025'!J214 -> 52 | K214: ='Sep 2025'!K214- 'Oct 2025'!K214 -> -19.2 | ... R214: ='Sep 2025'!R214- 'Oct 2025'!R214 -> -51.1 | S214: =Q214+R214 -> -56.8 | U214: ='Sep 2025'!S214- 'Oct 2025'!S214 -> -15.1 | V214: ='Sep 2025'!T214- 'Oct 2025'!T214 -> 0 | W214: ='Sep 2025'!U214- 'Oct 2025'!U214 -> 15.2 | X214: ='Sep 2025'!V214- 'Oct 2025'!V214 -> 5 | Y214: ='Sep 2025'!W214- 'Oct 2025'!W214 -> -14.4 | Z214: ='Sep 2025'!X214- 'Oct 2025'!X214 -> 0 | AA214: ='Sep 2025'!Y214- 'Oct 2025'!Y214 -> 0 | AB214: ='Sep 2025'!Z214- 'Oct 2025'!Z214 -> 0 | ... BB214: ='Sep 2025'!AZ214- 'Oct 2025'!AZ214 -> -0.351225 | BC214: =X214+Y214+SUM(AJ214:AK214) -> 1.8
A215: 2023 Q2 | B215: historical | C215: -1 | D215: ='Sep 2025'!D215- 'Oct 2025'!D215 -> -0.0020590491 | E215: ='Sep 2025'!E215- 'Oct 2025'!E215 -> 0.0041349386 | F215: ='Sep 2025'!F215- 'Oct 2025'!F215 -> 0.0016035596 | G215: ='Sep 2025'!G215- 'Oct 2025'!G215 -> 0.0036981861 | H215: ='Sep 2025'!H215- 'Oct 2025'!H215 -> 0.00016835997 | I215: ='Sep 2025'!I215- 'Oct 2025'!I215 -> 0 | J215: ='Sep 2025'!J215- 'Oct 2025'!J215 -> 76.3 | K215: ='Sep 2025'!K215- 'Oct 2025'!K215 -> 7.4 | ... R215: ='Sep 2025'!R215- 'Oct 2025'!R215 -> -75.4 | S215: =Q215+R215 -> -77.3 | U215: ='Sep 2025'!S215- 'Oct 2025'!S215 -> -13.9 | V215: ='Sep 2025'!T215- 'Oct 2025'!T215 -> 0 | W215: ='Sep 2025'!U215- 'Oct 2025'!U215 -> 7.8 | X215: ='Sep 2025'!V215- 'Oct 2025'!V215 -> 3.5028571 | Y215: ='Sep 2025'!W215- 'Oct 2025'!W215 -> -15.7 | Z215: ='Sep 2025'!X215- 'Oct 2025'!X215 -> 0 | AA215: ='Sep 2025'!Y215- 'Oct 2025'!Y215 -> 0 | AB215: ='Sep 2025'!Z215- 'Oct 2025'!Z215 -> 0 | ... BB215: ='Sep 2025'!AZ215- 'Oct 2025'!AZ215 -> -1.785825 | BC215: =X215+Y215+SUM(AJ215:AK215) -> 1.5028571
A216: 2023 Q3 | B216: historical | C216: -1 | D216: ='Sep 2025'!D216- 'Oct 2025'!D216 -> 8.147383e-06 | E216: ='Sep 2025'!E216- 'Oct 2025'!E216 -> 0.0049104309 | F216: ='Sep 2025'!F216- 'Oct 2025'!F216 -> -0.0011098203 | G216: ='Sep 2025'!G216- 'Oct 2025'!G216 -> 0.0037621825 | H216: ='Sep 2025'!H216- 'Oct 2025'!H216 -> 6.6117654e-05 | I216: ='Sep 2025'!I216- 'Oct 2025'!I216 -> 0 | J216: ='Sep 2025'!J216- 'Oct 2025'!J216 -> 107.1 | K216: ='Sep 2025'!K216- 'Oct 2025'!K216 -> 32.8 | ... R216: ='Sep 2025'!R216- 'Oct 2025'!R216 -> -80.4 | S216: =Q216+R216 -> -73.2 | U216: ='Sep 2025'!S216- 'Oct 2025'!S216 -> -23.5 | V216: ='Sep 2025'!T216- 'Oct 2025'!T216 -> 0 | W216: ='Sep 2025'!U216- 'Oct 2025'!U216 -> 2.6 | X216: ='Sep 2025'!V216- 'Oct 2025'!V216 -> 2.7028571 | Y216: ='Sep 2025'!W216- 'Oct 2025'!W216 -> -16.3 | Z216: ='Sep 2025'!X216- 'Oct 2025'!X216 -> 0 | AA216: ='Sep 2025'!Y216- 'Oct 2025'!Y216 -> 0 | AB216: ='Sep 2025'!Z216- 'Oct 2025'!Z216 -> 0 | ... BB216: ='Sep 2025'!AZ216- 'Oct 2025'!AZ216 -> -0.9297 | BC216: =X216+Y216+SUM(AJ216:AK216) -> 3.0028571
A217: 2023 Q4 | B217: historical | C217: -1 | D217: ='Sep 2025'!D217- 'Oct 2025'!D217 -> -0.0024057479 | E217: ='Sep 2025'!E217- 'Oct 2025'!E217 -> 0.0017800588 | F217: ='Sep 2025'!F217- 'Oct 2025'!F217 -> 0.00026588903 | G217: ='Sep 2025'!G217- 'Oct 2025'!G217 -> 0.0014693226 | H217: ='Sep 2025'!H217- 'Oct 2025'!H217 -> 0.00041268334 | I217: ='Sep 2025'!I217- 'Oct 2025'!I217 -> 0 | J217: ='Sep 2025'!J217- 'Oct 2025'!J217 -> 127.7 | K217: ='Sep 2025'!K217- 'Oct 2025'!K217 -> 20.4 | ... R217: ='Sep 2025'!R217- 'Oct 2025'!R217 -> -78.1 | S217: =Q217+R217 -> -63.6 | T217: =AVERAGE(S214:S217) -> -67.725 | U217: ='Sep 2025'!S217- 'Oct 2025'!S217 -> -22.1 | V217: ='Sep 2025'!T217- 'Oct 2025'!T217 -> 0 | W217: ='Sep 2025'!U217- 'Oct 2025'!U217 -> 5.8 | X217: ='Sep 2025'!V217- 'Oct 2025'!V217 -> 5.7 | Y217: ='Sep 2025'!W217- 'Oct 2025'!W217 -> -15.3 | Z217: ='Sep 2025'!X217- 'Oct 2025'!X217 -> 0 | AA217: ='Sep 2025'!Y217- 'Oct 2025'!Y217 -> 0 | AB217: ='Sep 2025'!Z217- 'Oct 2025'!Z217 -> 0 | ... BB217: ='Sep 2025'!AZ217- 'Oct 2025'!AZ217 -> 0.0225 | BC217: =X217+Y217+SUM(AJ217:AK217) -> 10.2 | BD217: =AVERAGE(BC214:BC217) -> 4.1264286
A218: 2024 Q1 | B218: historical | C218: -1 | D218: ='Sep 2025'!D218- 'Oct 2025'!D218 -> 0.001502578 | E218: ='Sep 2025'!E218- 'Oct 2025'!E218 -> -0.0015970445 | F218: ='Sep 2025'!F218- 'Oct 2025'!F218 -> -0.0014863472 | G218: ='Sep 2025'!G218- 'Oct 2025'!G218 -> -0.0015728615 | H218: ='Sep 2025'!H218- 'Oct 2025'!H218 -> 0.00039854896 | I218: ='Sep 2025'!I218- 'Oct 2025'!I218 -> 0 | J218: ='Sep 2025'!J218- 'Oct 2025'!J218 -> 84.1 | K218: ='Sep 2025'!K218- 'Oct 2025'!K218 -> 19 | ... R218: ='Sep 2025'!R218- 'Oct 2025'!R218 -> -69.8 | S218: =Q218+R218 -> -76.3 | U218: ='Sep 2025'!S218- 'Oct 2025'!S218 -> 12.4 | V218: ='Sep 2025'!T218- 'Oct 2025'!T218 -> 0 | W218: ='Sep 2025'!U218- 'Oct 2025'!U218 -> 2.8 | X218: ='Sep 2025'!V218- 'Oct 2025'!V218 -> 20.6 | Y218: ='Sep 2025'!W218- 'Oct 2025'!W218 -> -13.9 | Z218: ='Sep 2025'!X218- 'Oct 2025'!X218 -> 0 | AA218: ='Sep 2025'!Y218- 'Oct 2025'!Y218 -> 0 | AB218: ='Sep 2025'!Z218- 'Oct 2025'!Z218 -> 0 | ... BB218: ='Sep 2025'!AZ218- 'Oct 2025'!AZ218 -> 3.153825 | BC218: =X218+Y218+SUM(AJ218:AK218) -> 31.2
A219: 2024 Q2 | B219: historical | C219: -1 | D219: ='Sep 2025'!D219- 'Oct 2025'!D219 -> 0.00060556483 | E219: ='Sep 2025'!E219- 'Oct 2025'!E219 -> -0.0020114728 | F219: ='Sep 2025'!F219- 'Oct 2025'!F219 -> 0.0016481781 | G219: ='Sep 2025'!G219- 'Oct 2025'!G219 -> -0.0013010122 | H219: ='Sep 2025'!H219- 'Oct 2025'!H219 -> 0.00014906837 | I219: ='Sep 2025'!I219- 'Oct 2025'!I219 -> 0 | J219: ='Sep 2025'!J219- 'Oct 2025'!J219 -> 130.3 | K219: ='Sep 2025'!K219- 'Oct 2025'!K219 -> 73.4 | ... R219: ='Sep 2025'!R219- 'Oct 2025'!R219 -> -75.4 | S219: =Q219+R219 -> -36 | U219: ='Sep 2025'!S219- 'Oct 2025'!S219 -> 1.9 | V219: ='Sep 2025'!T219- 'Oct 2025'!T219 -> 0 | W219: ='Sep 2025'!U219- 'Oct 2025'!U219 -> 6.6 | X219: ='Sep 2025'!V219- 'Oct 2025'!V219 -> 25.6 | Y219: ='Sep 2025'!W219- 'Oct 2025'!W219 -> -13 | Z219: ='Sep 2025'!X219- 'Oct 2025'!X219 -> 0 | AA219: ='Sep 2025'!Y219- 'Oct 2025'!Y219 -> 0 | AB219: ='Sep 2025'!Z219- 'Oct 2025'!Z219 -> 0 | ... BB219: ='Sep 2025'!AZ219- 'Oct 2025'!AZ219 -> 10.801125 | BC219: =X219+Y219+SUM(AJ219:AK219) -> 43.7
A220: 2024 Q3 | B220: historical | C220: -1 | D220: ='Sep 2025'!D220- 'Oct 2025'!D220 -> -6.8507042e-05 | E220: ='Sep 2025'!E220- 'Oct 2025'!E220 -> -0.0014976688 | F220: ='Sep 2025'!F220- 'Oct 2025'!F220 -> -0.0014319194 | G220: ='Sep 2025'!G220- 'Oct 2025'!G220 -> -0.0015166583 | H220: ='Sep 2025'!H220- 'Oct 2025'!H220 -> 0.00039289627 | I220: ='Sep 2025'!I220- 'Oct 2025'!I220 -> 0 | J220: ='Sep 2025'!J220- 'Oct 2025'!J220 -> 136.8 | K220: ='Sep 2025'!K220- 'Oct 2025'!K220 -> 94.4 | ... R220: ='Sep 2025'!R220- 'Oct 2025'!R220 -> -77.4 | S220: =Q220+R220 -> -7.2 | U220: ='Sep 2025'!S220- 'Oct 2025'!S220 -> -2.5 | V220: ='Sep 2025'!T220- 'Oct 2025'!T220 -> 0 | W220: ='Sep 2025'!U220- 'Oct 2025'!U220 -> 7.5 | X220: ='Sep 2025'!V220- 'Oct 2025'!V220 -> 29.1 | Y220: ='Sep 2025'!W220- 'Oct 2025'!W220 -> -12.6 | Z220: ='Sep 2025'!X220- 'Oct 2025'!X220 -> 0 | AA220: ='Sep 2025'!Y220- 'Oct 2025'!Y220 -> 0 | AB220: ='Sep 2025'!Z220- 'Oct 2025'!Z220 -> 0 | ... BB220: ='Sep 2025'!AZ220- 'Oct 2025'!AZ220 -> 14.276025 | BC220: =X220+Y220+SUM(AJ220:AK220) -> 53.7
A221: 2024 Q4 | B221: historical | C221: -1 | D221: ='Sep 2025'!D221- 'Oct 2025'!D221 -> -0.00062957716 | E221: ='Sep 2025'!E221- 'Oct 2025'!E221 -> -0.0014557399 | F221: ='Sep 2025'!F221- 'Oct 2025'!F221 -> 0.00034638741 | G221: ='Sep 2025'!G221- 'Oct 2025'!G221 -> -0.0010953122 | H221: ='Sep 2025'!H221- 'Oct 2025'!H221 -> 0.00033017816 | I221: ='Sep 2025'!I221- 'Oct 2025'!I221 -> 0 | J221: ='Sep 2025'!J221- 'Oct 2025'!J221 -> 101.3 | K221: ='Sep 2025'!K221- 'Oct 2025'!K221 -> 95.8 | ... R221: ='Sep 2025'!R221- 'Oct 2025'!R221 -> -83.2 | S221: =Q221+R221 -> -25.8 | T221: =AVERAGE(S218:S221) -> -36.325 | U221: ='Sep 2025'!S221- 'Oct 2025'!S221 -> -3.5 | V221: ='Sep 2025'!T221- 'Oct 2025'!T221 -> 0 | W221: ='Sep 2025'!U221- 'Oct 2025'!U221 -> 10 | X221: ='Sep 2025'!V221- 'Oct 2025'!V221 -> 42.1 | Y221: ='Sep 2025'!W221- 'Oct 2025'!W221 -> -13.4 | Z221: ='Sep 2025'!X221- 'Oct 2025'!X221 -> 0 | AA221: ='Sep 2025'!Y221- 'Oct 2025'!Y221 -> 0 | AB221: ='Sep 2025'!Z221- 'Oct 2025'!Z221 -> 0 | ... BB221: ='Sep 2025'!AZ221- 'Oct 2025'!AZ221 -> 17.860725 | BC221: =X221+Y221+SUM(AJ221:AK221) -> 66.4 | BD221: =AVERAGE(BC218:BC221) -> 48.75
A222: 2025 Q1 | B222: historical | C222: -1 | D222: ='Sep 2025'!D222- 'Oct 2025'!D222 -> 0.00045394116 | E222: ='Sep 2025'!E222- 'Oct 2025'!E222 -> -0.00034221504 | F222: ='Sep 2025'!F222- 'Oct 2025'!F222 -> -0.00072240576 | G222: ='Sep 2025'!G222- 'Oct 2025'!G222 -> -0.00040680989 | H222: ='Sep 2025'!H222- 'Oct 2025'!H222 -> -0.00055355426 | I222: ='Sep 2025'!I222- 'Oct 2025'!I222 -> 0 | J222: ='Sep 2025'!J222- 'Oct 2025'!J222 -> 80.1 | K222: ='Sep 2025'!K222- 'Oct 2025'!K222 -> 93.4 | ... R222: ='Sep 2025'!R222- 'Oct 2025'!R222 -> -90.4 | S222: =Q222+R222 -> -20.2 | U222: ='Sep 2025'!S222- 'Oct 2025'!S222 -> -50.6 | V222: ='Sep 2025'!T222- 'Oct 2025'!T222 -> 0 | W222: ='Sep 2025'!U222- 'Oct 2025'!U222 -> 9.7 | X222: ='Sep 2025'!V222- 'Oct 2025'!V222 -> 50.5 | Y222: ='Sep 2025'!W222- 'Oct 2025'!W222 -> -15.3 | Z222: ='Sep 2025'!X222- 'Oct 2025'!X222 -> 0 | AA222: ='Sep 2025'!Y222- 'Oct 2025'!Y222 -> 0 | AB222: ='Sep 2025'!Z222- 'Oct 2025'!Z222 -> 0 | ... BB222: ='Sep 2025'!AZ222- 'Oct 2025'!AZ222 -> 16.477425 | BC222: =X222+Y222+SUM(AJ222:AK222) -> 55.1
A223: 2025 Q2 | B223: historical | C223: -1 | D223: ='Sep 2025'!D223- 'Oct 2025'!D223 -> -0.00024406833 | E223: ='Sep 2025'!E223- 'Oct 2025'!E223 -> 5.1408191e-05 | F223: ='Sep 2025'!F223- 'Oct 2025'!F223 -> 0.0017257334 | G223: ='Sep 2025'!G223- 'Oct 2025'!G223 -> 0.00036482532 | H223: ='Sep 2025'!H223- 'Oct 2025'!H223 -> 0.00030385517 | I223: ='Sep 2025'!I223- 'Oct 2025'!I223 -> 0 | J223: ='Sep 2025'!J223- 'Oct 2025'!J223 -> 131.8 | K223: ='Sep 2025'!K223- 'Oct 2025'!K223 -> 146 | ... R223: ='Sep 2025'!R223- 'Oct 2025'!R223 -> -99.1 | S223: =Q223+R223 -> -26 | U223: ='Sep 2025'!S223- 'Oct 2025'!S223 -> 469.7 | V223: ='Sep 2025'!T223- 'Oct 2025'!T223 -> 0 | W223: ='Sep 2025'!U223- 'Oct 2025'!U223 -> 183 | X223: ='Sep 2025'!V223- 'Oct 2025'!V223 -> 55.4 | Y223: ='Sep 2025'!W223- 'Oct 2025'!W223 -> -15.6 | Z223: ='Sep 2025'!X223- 'Oct 2025'!X223 -> 0 | AA223: ='Sep 2025'!Y223- 'Oct 2025'!Y223 -> 0 | AB223: ='Sep 2025'!Z223- 'Oct 2025'!Z223 -> 0 | ... BB223: ='Sep 2025'!AZ223- 'Oct 2025'!AZ223 -> 15.8067 | BC223: =X223+Y223+SUM(AJ223:AK223) -> 70.1
A224: 2025 Q3 | B224: projection | C224: 0 | D224: ='Sep 2025'!D224- 'Oct 2025'!D224 -> 0 | E224: ='Sep 2025'!E224- 'Oct 2025'!E224 -> 0 | F224: ='Sep 2025'!F224- 'Oct 2025'!F224 -> 0 | G224: ='Sep 2025'!G224- 'Oct 2025'!G224 -> 0 | H224: ='Sep 2025'!H224- 'Oct 2025'!H224 -> 0 | I224: ='Sep 2025'!I224- 'Oct 2025'!I224 -> 0 | J224: ='Sep 2025'!J224- 'Oct 2025'!J224 -> 133.11478 | K224: ='Sep 2025'!K224- 'Oct 2025'!K224 -> 147.44711 | ... R224: ='Sep 2025'!R224- 'Oct 2025'!R224 -> -105.6159 | S224: =Q224+R224 -> -32.113835 | U224: ='Sep 2025'!S224- 'Oct 2025'!S224 -> -63.612217 | V224: ='Sep 2025'!T224- 'Oct 2025'!T224 -> 0 | W224: ='Sep 2025'!U224- 'Oct 2025'!U224 -> 23.592772 | X224: ='Sep 2025'!V224- 'Oct 2025'!V224 -> 55.659465 | Y224: ='Sep 2025'!W224- 'Oct 2025'!W224 -> -14.601737 | Z224: ='Sep 2025'!X224- 'Oct 2025'!X224 -> 0 | AA224: ='Sep 2025'!Y224- 'Oct 2025'!Y224 -> 0 | AB224: ='Sep 2025'!Z224- 'Oct 2025'!Z224 -> 0 | ... BB224: ='Sep 2025'!AZ224- 'Oct 2025'!AZ224 -> 14.41643 | BC224: =X224+Y224+SUM(AJ224:AK224) -> 73.118605
A225: 2025 Q4 | B225: projection | C225: 0 | D225: ='Sep 2025'!D225- 'Oct 2025'!D225 -> 0 | E225: ='Sep 2025'!E225- 'Oct 2025'!E225 -> 0 | F225: ='Sep 2025'!F225- 'Oct 2025'!F225 -> 0 | G225: ='Sep 2025'!G225- 'Oct 2025'!G225 -> 0 | H225: ='Sep 2025'!H225- 'Oct 2025'!H225 -> 0 | I225: ='Sep 2025'!I225- 'Oct 2025'!I225 -> 0 | J225: ='Sep 2025'!J225- 'Oct 2025'!J225 -> 134.39041 | K225: ='Sep 2025'!K225- 'Oct 2025'!K225 -> 148.84401 | ... R225: ='Sep 2025'!R225- 'Oct 2025'!R225 -> -106.78692 | S225: =Q225+R225 -> -32.978161 | U225: ='Sep 2025'!S225- 'Oct 2025'!S225 -> -63.219165 | V225: ='Sep 2025'!T225- 'Oct 2025'!T225 -> 0 | W225: ='Sep 2025'!U225- 'Oct 2025'!U225 -> 23.580943 | X225: ='Sep 2025'!V225- 'Oct 2025'!V225 -> 55.920227 | Y225: ='Sep 2025'!W225- 'Oct 2025'!W225 -> -14.851518 | Z225: ='Sep 2025'!X225- 'Oct 2025'!X225 -> 0 | AA225: ='Sep 2025'!Y225- 'Oct 2025'!Y225 -> 0 | AB225: ='Sep 2025'!Z225- 'Oct 2025'!Z225 -> 0 | ... BB225: ='Sep 2025'!AZ225- 'Oct 2025'!AZ225 -> 12.60843 | BC225: =X225+Y225+SUM(AJ225:AK225) -> 72.525307
A226: 2026 Q1 | B226: projection | C226: 0 | D226: ='Sep 2025'!D226- 'Oct 2025'!D226 -> 0 | E226: ='Sep 2025'!E226- 'Oct 2025'!E226 -> 0 | F226: ='Sep 2025'!F226- 'Oct 2025'!F226 -> 0 | G226: ='Sep 2025'!G226- 'Oct 2025'!G226 -> 0 | H226: ='Sep 2025'!H226- 'Oct 2025'!H226 -> 0 | I226: ='Sep 2025'!I226- 'Oct 2025'!I226 -> 0 | J226: ='Sep 2025'!J226- 'Oct 2025'!J226 -> 135.70824 | K226: ='Sep 2025'!K226- 'Oct 2025'!K226 -> 150.11784 | ... R226: ='Sep 2025'!R226- 'Oct 2025'!R226 -> -107.87181 | S226: =Q226+R226 -> -33.771792 | U226: ='Sep 2025'!S226- 'Oct 2025'!S226 -> -62.828541 | V226: ='Sep 2025'!T226- 'Oct 2025'!T226 -> 0 | W226: ='Sep 2025'!U226- 'Oct 2025'!U226 -> 23.609471 | X226: ='Sep 2025'!V226- 'Oct 2025'!V226 -> 56.217736 | Y226: ='Sep 2025'!W226- 'Oct 2025'!W226 -> -15.105475 | Z226: ='Sep 2025'!X226- 'Oct 2025'!X226 -> 0 | AA226: ='Sep 2025'!Y226- 'Oct 2025'!Y226 -> 0 | AB226: ='Sep 2025'!Z226- 'Oct 2025'!Z226 -> 0 | ... BB226: ='Sep 2025'!AZ226- 'Oct 2025'!AZ226 -> 14.609532 | BC226: =X226+Y226+SUM(AJ226:AK226) -> 71.943153
A227: 2026 Q2 | B227: projection | C227: 0 | D227: ='Sep 2025'!D227- 'Oct 2025'!D227 -> 0 | E227: ='Sep 2025'!E227- 'Oct 2025'!E227 -> 0 | F227: ='Sep 2025'!F227- 'Oct 2025'!F227 -> 0 | G227: ='Sep 2025'!G227- 'Oct 2025'!G227 -> 0 | H227: ='Sep 2025'!H227- 'Oct 2025'!H227 -> 0 | I227: ='Sep 2025'!I227- 'Oct 2025'!I227 -> 0 | J227: ='Sep 2025'!J227- 'Oct 2025'!J227 -> 137.02216 | K227: ='Sep 2025'!K227- 'Oct 2025'!K227 -> 151.49422 | ... R227: ='Sep 2025'!R227- 'Oct 2025'!R227 -> -108.95956 | S227: =Q227+R227 -> -34.143899 | U227: ='Sep 2025'!S227- 'Oct 2025'!S227 -> -62.440332 | V227: ='Sep 2025'!T227- 'Oct 2025'!T227 -> 0 | W227: ='Sep 2025'!U227- 'Oct 2025'!U227 -> 23.656089 | X227: ='Sep 2025'!V227- 'Oct 2025'!V227 -> 56.481113 | Y227: ='Sep 2025'!W227- 'Oct 2025'!W227 -> -15.363678 | Z227: ='Sep 2025'!X227- 'Oct 2025'!X227 -> 0 | AA227: ='Sep 2025'!Y227- 'Oct 2025'!Y227 -> 0 | AB227: ='Sep 2025'!Z227- 'Oct 2025'!Z227 -> 0 | ... BB227: ='Sep 2025'!AZ227- 'Oct 2025'!AZ227 -> 14.747676 | BC227: =X227+Y227+SUM(AJ227:AK227) -> 71.300691
A228: 2026 Q3 | B228: projection | C228: 0 | D228: ='Sep 2025'!D228- 'Oct 2025'!D228 -> 0 | E228: ='Sep 2025'!E228- 'Oct 2025'!E228 -> 0 | F228: ='Sep 2025'!F228- 'Oct 2025'!F228 -> 0 | G228: ='Sep 2025'!G228- 'Oct 2025'!G228 -> 0 | H228: ='Sep 2025'!H228- 'Oct 2025'!H228 -> 0 | I228: ='Sep 2025'!I228- 'Oct 2025'!I228 -> 0 | J228: ='Sep 2025'!J228- 'Oct 2025'!J228 -> 138.30736 | K228: ='Sep 2025'!K228- 'Oct 2025'!K228 -> 152.69732 | ... R228: ='Sep 2025'!R228- 'Oct 2025'!R228 -> -109.99527 | S228: =Q228+R228 -> -34.455915 | U228: ='Sep 2025'!S228- 'Oct 2025'!S228 -> -62.054521 | V228: ='Sep 2025'!T228- 'Oct 2025'!T228 -> 0 | W228: ='Sep 2025'!U228- 'Oct 2025'!U228 -> 23.632432 | X228: ='Sep 2025'!V228- 'Oct 2025'!V228 -> 56.745806 | Y228: ='Sep 2025'!W228- 'Oct 2025'!W228 -> -15.626195 | Z228: ='Sep 2025'!X228- 'Oct 2025'!X228 -> 0 | AA228: ='Sep 2025'!Y228- 'Oct 2025'!Y228 -> 0 | AB228: ='Sep 2025'!Z228- 'Oct 2025'!Z228 -> 0 | ... BB228: ='Sep 2025'!AZ228- 'Oct 2025'!AZ228 -> 14.265959 | BC228: =X228+Y228+SUM(AJ228:AK228) -> 70.63284
A229: 2026 Q4 | B229: projection | C229: 0 | D229: ='Sep 2025'!D229- 'Oct 2025'!D229 -> 0 | E229: ='Sep 2025'!E229- 'Oct 2025'!E229 -> 0 | F229: ='Sep 2025'!F229- 'Oct 2025'!F229 -> 0 | G229: ='Sep 2025'!G229- 'Oct 2025'!G229 -> 0 | H229: ='Sep 2025'!H229- 'Oct 2025'!H229 -> 0 | I229: ='Sep 2025'!I229- 'Oct 2025'!I229 -> 0 | J229: ='Sep 2025'!J229- 'Oct 2025'!J229 -> 139.59908 | K229: ='Sep 2025'!K229- 'Oct 2025'!K229 -> 154.06026 | ... R229: ='Sep 2025'!R229- 'Oct 2025'!R229 -> -111.06968 | S229: =Q229+R229 -> -34.798469 | U229: ='Sep 2025'!S229- 'Oct 2025'!S229 -> -61.671094 | V229: ='Sep 2025'!T229- 'Oct 2025'!T229 -> 0 | W229: ='Sep 2025'!U229- 'Oct 2025'!U229 -> 23.660959 | X229: ='Sep 2025'!V229- 'Oct 2025'!V229 -> 57.011823 | Y229: ='Sep 2025'!W229- 'Oct 2025'!W229 -> -15.893098 | Z229: ='Sep 2025'!X229- 'Oct 2025'!X229 -> 0 | AA229: ='Sep 2025'!Y229- 'Oct 2025'!Y229 -> 0 | AB229: ='Sep 2025'!Z229- 'Oct 2025'!Z229 -> 0 | ... BB229: ='Sep 2025'!AZ229- 'Oct 2025'!AZ229 -> 14.036081 | BC229: =X229+Y229+SUM(AJ229:AK229) -> 71.271845
