Workbook

Sheet Guide to the FIM Spreadsheet
B1: NOTE: The sheet names that are bolded are the only ones that are read into the code. Do not change the format of these sheets unless you also change the code that imports the data as well.
B3: Guide to the FIM Forecast Spreadsheet
B5: Sheets:
B6: Checklist (New Quarter Release) | C6: Checklist of steps to follow when the BEA releases its advance estimate of a new quarter's data.
B7: Checklist (Monthly Revision) | C7: Checklist of steps to follow for BEA's two revisions of a quarter's data.
B8: Checklist (CBO Budget Release) | C8: Checklist of steps to follow when the CBO releases a new Ten-Year Economic and Budget Projections.
B9: Haver Pivoted | C9: BEA data read in from Haver using our data-raw\haver-pull.R script. This is called by the component sheets to generate our forecasts.
B10: historical overrides | C10: Calls from the Grants forecast sheet. We override BEA data for 2020 consumption grants because BEA puts it all in the first quarter; we spread it out over four. This also is read into the code.
B11: deflators_override | C11: Calls from the Deflators forecast sheet. This is also read into the code.
B12: forecast comparison | C12: This sheet shows how our forecast has changed since the last update.
B13: Monthly Personal Income (MPI) | C13: Monthly BEA Personal Income data we use to help us forecast the upcoming quarter of data before BEA's advance estimate comes out.
B14: forecast | C14: Our projection for the components of the FIM, calling from our forecast sheets; this is what we read into the code.
B15: Deflators | C15: The deflators we use, for reference. Similar to the MPC sheet I think we should either delete or edit for the whole FIM in here.
B16: mpc | C16: MPCs for the spending out of our forecast variables, where applicable. This is not read into the code - just for reference on what our current MPCs are.
B17: Component Sheet: Unemployment Insurance, Grants, Federal and State Purchases, Subsidies, Medicaid, Medicare, Student loans, Social Benefits, Supply Side, IRA, Taxes | C17: Each of these sheets generates our forecast for one (or a few) of the variables that we read into the code in the forecast sheet. This is the main part of the workbook that you will edit each update.
... B23: ARP Quarterly | C23: Quarterly spending out of the ARP; this is where we call scores of ARP components from in other sheets. Generally you won't touch this without Louise.
B25: Conventions (please stick to these when editing the sheet to keep things organized)
B26: Italicized rows in the forecast spreadsheets are called by "forecast" and read into the code; they are the "final output" of each sheet.
B27: All CBO references have a comment with where to find the data that's copy pasted in so we can verify/find it again. I write the name of the release, table and row. It is important to keep these up to date so there isn't confusion about where the numbers come from, since they are hard-coded!
B28: NEVER drag forward a formula without checking how the row's formulas work-- at the moment, sometimes they change within a row.
B29: Any rows with haver codes next to the variable call from Haver Pivoted in the historical period.
B30: Year-quarters in all the main tables of the forecast sheets are in the same columns across sheets (i.e. 2021 Q2 is in column N across sheets for the main forecast tables).

Sheet Checklist (New Quarter Release)
A1: Checklist | B1: Methodology | C1: How to execute | D1: Done?
A2: Setting up
A3: Prepare the Revisions sheet | B3: This sheet allows us to see how the raw inputs to the FIM have changed; it can help us parse out which changes to our forecast are due to BEA data and which are due to our own formulas. | C3: In the Revisions sheet, copy paste the "Current Update" column into the "Last Update" column (make sure you paste it hard-coded using Paste Values). Relabel the columns with the quarter and which revision they represent (initial release, first revision, or second revision). | D3: no
A4: Prepare the Forecast Comparison and Forecast sheets | B4: The forecast comparison sheet shows us how much our forecast (what is read into the code) has changed since the last update, in level and percent differences. | C4: Copy paste the forecast table from the most recent update (Paste Values Only) into the "Previous Forecast" table. In both the forecast and forecast comparison sheets, delete the first column so that the forecast comparison sheet contains the upcoming quarter of data and the forecast going forward. | D4: no
A5: Prepare this month's spreadsheet for a new quarter of data to be read in from Haver. | B5: This is a somewhat complicated part of a new quarter update. Most rows change their formulas from the historical to projection period, so you have to carefully pull forward the historical period to include the new quarter of data. | C5: In each component sheet, drag forward EVERY row that calls Haver Pivoted (you can identify those by the haver codes written next to the variable name) or depends on Haver Pivoted data forward one column into the upcoming quarter. Please change the color formatting and labeling of the historical versus projection periods accordingly to avoid confusion. The new quarters will show either nothing or a #REF error; ignore this. The cells will fill with the new data that we read in when BEA releases the new quarter. DOUBLE CHECK your work-- it is important to ensure that every row that needs to be pulled forward, is. | D5: no
A6: Prepare the Revisions sheet for the new quarter | B6: This sheet we only use for monthly revisions, and not for a new quarter release. However we do need to update what quarter in Haver Pivoted is called in the "Current Update" column. | C6: Clear contents in the Last Update column. Change the formula in the first cell that calls Haver Pivoted in the Current Update column to call from one column over in Haver Pivoted (this is where the next quarter's data will be when we read in the new data). Drag the changed formula down the whole column. Don't worry about DIV0 or REF errors, everything will fill in when Haver Pivoted is updated. | D6: no
A7: Prepare the Historical Overrides and deflators_override sheets | B7: We have a few overrides to historical data that we include in these sheets | C7: In the Historical Overrides sheet, add the new quarter to the last column and drag the formulas to the right. In the deflators_override sheet, delete the first column. Add a new quarter to the last column and drag the formula over to the right. (all the quarters in this sheet should be in the forecast period) | D7: no
A8: Read the BEA news release for the new quarter | B8: The BEA's news release can be really helpful for broadly understanding the BEA's released data for the new quarter, which affects the assumptions we make about the components of the FIM. The technical note is the most useful for detailed information. You'll want to take note of GDP growth, as well as any large components that they note. Sometimes the BEA tables can be useful for finding specific values too. | C8: https://www.bea.gov/news/current-releases | D8: no
A9: Pulling in the new data from Haver | B9: We pull in the latest historical BEA data by running a script to replace the data in Haver Pivoted. This will autofill the spreadsheets where we make our forecast assumptions with the new BEA data. This will also autofill the "Current Update" column in Revisions. | C9: Run fim/data-raw/haver-pull.R. This script automatically pastes new data into the "Haver Pivoted" sheet. The order of the Haver codes should be preserved each update. If you need to pull more variables from Haver make sure they're at the bottom. | D9: no
A10: Update unemployment rate and state and local employment and construction numbers | B10: We use these to gauge our forecast for state purchases. | C10: Update the table in the Federal and State Purchases sheet by dragging the formula to the next column. The formulas call cells from "data/monthly_state_employment.xlsx" which is created from "data-raw/haver-pull.R" | D10: no
A11: Monthly Personal Income Sheet | B11: Before the BEA releases data on a quarter, we can use their monthly estimates to inform our assumptions about the quarter. Don't forget another PCE at the bottom! Drag over cells in yellow before copy pasting (the yellow cell should be the first forecast). | C11: If this table has been released, create a new sheet called MPI with the table. You don't need to include the month to month changes, just the levels. It's helpful to highlight the rows in the table that are relevant to us. | D11: no
A12: Looking over and editing our forecast
A13: Forecast Comparison | B13: Take a look at the forecast comparison sheet. How much has our forecast changed? Are there any components that have changed considerably, that we need to pay attention to?
A14: Component Sheets | B14: Look through each component forecast to see if anything looks strange/hugely different. This is where the archived forecast from last month comes in handy-- you can compare our forecast of this quarter to the data we've just pulled in to track why our forecast has changed. Check formulas, etc.
A15: Show Louise | B15: Walk Louise through the changes-- she typically makes some adjustments to the forecast. Once she signs off on the spreadsheet, you'll run the code to calculate the FIM.
A16: Calculating contributions
A17: At the top of the fiscal_impact script, set overwrite files to TRUE. This will automatically save the forecast sheet for this update in its archival folder (results/update month/input_data).
A18: Calculating the FIM | B18: The fiscal_impact script (the main script we use to calculate the FIM) has five sections: Wrangle data-- here, we read in historical data from the BEA and the latest CBO Ten Year Baseline projections. We prep the historical data to be merged with our forecast by adjusting the BEA categories into the components we use for the FIM (see forecast sheet for those components). We also use the CBO projections to calculate the CBO's potential GDP growth projection for use later in the script. Projection-- in this section we read in the "forecast" sheet from this spreadsheet, merge it with the historical data we cleaned in the previous section, and combine the medicaid and medicare variables into categories of "health outlays", since they have the same MPC and don't need to be kept separate. We keep them apart in the spreadsheet because it's easier to combine them in the code rather than across worksheets. Consumption-- this is where a lot of the FIM methodology gets executed. First we subtract the counterfactual version of the components from our actual forecasted components to get the difference between actual spending and counterfactual spending; then we spread out spending of the net for each component using our MPCs. Contribution-- here we annualize the components and turn them into the GDP growth contributions by dividing by the lag of GDP and adjusting for inflation; then we rename a few variables and sum them into the final FIM categories. Comparison-- this section creates a table and plots with last month's FIM, this month's FIM, and the differences between them. | C18: Open up the fim R project by clicking on the "fim.Rproj" file. Type "CTRL + SHIFT + L" to load the fim package. Open fiscal_impact.R. This is the main script that we use to calculate the FIM.
A19: Generating comparison tables between the previous and new FIMs | B19: The comparison section of fiscal_impact.R renders the update-comparison.rmd file which generates graphs comparing last month and this month's components of the FIM. These help us to check for errors and see how much our forecast has changed since the last update. It outputs to results/{this-month-year}/update-comparison-{this-month-year}.html and a copy named index.html is created in the parent directory. It's called index.html (but colloquially known as the Manu file) so that GitHub knows to use it as a github site. Once you finish running fiscal_impact.R you should commit and push your changes to GitHub. Then make sure that the most recent version of index.html is published at https://github.com/Hutchins-Center/fim (you can find this link under the about page on the FIM's github repo (Hutchins-Center/fim). Share updated link and go through this with Louise. | C19: This step is automated when running fiscal_impact.R
A20: Finalizing update | B20: Once you finalize the update make sure to commit any changes and push them. I recommend labeling this commit '{Year-Quarter} Update finalized' so you can always return to that point in time in the commit history if needed. | C20: git add . git commit -m '{Year-Quarter} Update finalized git push Or your prefferd method for commiting/pushing
A21: When the update is finished, set the top of the fiscal_impact script, set overwrite files to FALSE. This will prevent the saved archival forecast from the update from being overwritten if you change the FIM at all within the same month as the most recent update.
A22: Publishing the FIM
A23: Drafting the text | C23: Former write ups can be found in Hutchins Center Documents/Projects/Fiscal Impact/Write Ups
A24: Fact checking | B24: A different RA should go through the text of the write up and confirm every number/statement using the FIM output files and graphics. | C24: The fim-interactive-month-year.xlsx file and fim-month-year.xlsx files are a good place to look (make sure they are the most up to date version!) and also look at the FIM interactive graphic that we are posting to ensure that our write up is consistent with it.
A25: Wordpress | B25: The FIM interactive and write up is posted on the Brookings website through Wordpress. | C25: See Hutchins Center Documents/Projects/Fiscal Impact/Updating the FIM Website.docx
A26: Newsletter | B26: We send out a newsletter alerting people that the FIM is updated. This gets updated in Hubspot. We typically use a shorter version of the full write up that's posted on the website for this. | C26: Typically an RA will make the initial cut and then run it by David and Stephanie. Ask an RA or someone from Comms to onboard you for using Hubspot if you haven't already. We don't send the email ourselves-- first email a test email to Ashley Schelling from Comms, and once it's approved and edited, Comms will send it out for us.

Sheet Checklist (Monthly Revision)
A1: Checklist | B1: Methodology | C1: How to execute | D1: Done?
A2: Setting up
A3: Prepare the Revisions sheet | B3: This sheet allows us to see how the raw inputs to the FIM have changed; it can help us parse out which changes to our forecast are due to BEA data revisions and which are due to our own formulas. (We don't do this.) | C3: In the Revisions sheet, copy paste the "Current Update" column into the "Last Update" column (make sure you paste it hard-coded using Paste Values). Relabel the columns with the quarter and which revision they represent (initial release, first revision, or second revision). | D3: no
A4: Prepare the Forecast Comparison sheet | B4: This sheet shows us how much our forecast (what is read into the code) has changed since the last update, in level and percent differences. | C4: Copy paste the forecast table from the most recent update (Past Values Only) into the "Previous Forecast" table. Keep the formulas in the first table so the data from Haver can be pulled in. | D4: yes
C5: Drag forward Construction (cpgs), Federal Corporate Income Taxes (gfrcp), and State Corporate Income Taxes (gsrcp) if initial revision (data comes in one month late) ex: February, May, August, November | D5: yes
A6: Read the BEA news release for the revision | B6: The BEA's news release can be really helpful for broadly understanding what data has changed between revisions and why, which affects the assumptions we make about the components of the FIM. The technical note is the most useful for detailed information. You'll want to take note of GDP growth, as well as any relevant explanations for revisions. In a new quarter this will be more extensive. Sometimes the BEA tables can be useful for finding specific values too. | C6: https://www.bea.gov/news/current-releases | D6: yes
A7: Pulling in the new data from Haver | B7: We pull in the latest historical BEA data by running a script to replace the data in Haver Pivoted. This will autofill the spreadsheets where we make our forecast assumptions with the new BEA data. | C7: Run fim/data-raw/haver-pull.R. This script automatically pastes new data into the "Haver Pivoted" sheet. The order of the Haver codes should be preserved each update. If you need to pull more variables from Haver make sure they're at the bottom. Make sure to close the forecast spreadsheet before running! | D7: no
A8: Update unemployment rate and state and local employment and construction numbers | B8: We use these to gauge our forecast for state purchases. | C8: Update the table in the Federal and State Purchases sheet by searching the lasgova, lalgova, and cpgs Haver codes, and entering in the most recent month of data. Note: We don't really look at this, but good to have it updated (?) | D8: no
A9: Revisions Sheet | B9: This sheet provides a quick look at how the BEA revised the variables that we use to make our forecast, and where they are used. It is helpful to anticipate changes in our forecast where the data automatically updates, and to consider when we decide whether to change our forecast assumptions sheet by sheet. | C9: Look through the revisions sheet. Which variables have changed, and which sheets are they called by? What are the biggest changes? Anything surprising? Go over this with Louise, and take note of what has changed to adjust our forecast sheets accordingly. | D9: no
A10: Monthly Personal Income Sheet | B10: Before the BEA releases data on a quarter, we can use their monthly estimates to inform our assumptions about the quarter. | C10: If this table has been released, create a new sheet called "Month" MPI with the table. You don't need to include the month to month changes, just the levels. It's helpful to highlight the rows in the table that are relevant to us. | D10: no
A11: Looking over and editing our forecast
A12: Revisions Sheet | B12: Start with the Revisions sheet. How has BEA revised the data? How should we expect our forecast of each component to change, given their revision?
A13: Forecast Comparison Sheet | B13: Take a look at the forecast comparison sheet. How much has our forecast changed? Are there any components that have changed considerably, that we need to pay attention to? Anything unexpected, given what we saw in the Revisions sheet?
A14: Component Sheets | B14: Look through each component forecast to see if anything looks strange/hugely different. This is where the archived forecast from last month comes in handy-- you can compare our forecast of this quarter to the data we've just pulled in to track why our forecast has changed. Check formulas, etc.
A15: Show Louise | B15: Walk Louise through the changes-- she typically makes some adjustments to the forecast. Once she signs off on the spreadsheet, you'll run the code to calculate the FIM.
A16: Calculating contributions
A17: At the top of the fiscal_impact script, set overwrite files to TRUE. This will automatically save the forecast sheet for this update in its archival folder.
A18: Calculating the FIM | B18: The fiscal_impact script (the main script we use to calcualte the FIM) has five sections: Wrangle data-- here, we read in historical data from the BEA and the latest CBO Ten Year Baseline projections. We prep the historical data to be merged with our forecast by adjusting the BEA categories into the components we use for the FIM (see forecast sheet for those components). We also use the CBO projections to calculate the CBO's potential GDP growth projection for use later in the script. Projection-- in this section we read in the "forecast" sheet from this spreadsheet, merge it with the historical data we cleaned in the previous section, and combine the medicaid and medicare variables into categories of "health outlays", since they have the same MPC and don't need to be kept separate. We keep them apart in the spreadsheet because it's easier to combine them in the code rather than across worksheets. Consumption-- this is where a lot of the FIM methodology gets executed. First we subtract the counterfactual version of the components from our actual forecasted components to get the difference between actual spending and counterfactual spending; then we spread out spending of the net for each component using our MPCs. Contribution-- here we annualize the components and turn them into the GDP growth contributions by dividing by the lag of GDP and adjusting for inflation; then we rename a few variables and sum them into the final FIM categories. Comparison-- this section creates a table and plots with last month's FIM, this month's FIM, and the differences between them. | C18: Open up the fim R project by clicking on the "fim.Rproj" file. Type "CTRL + SHIFT + L" to load the fim package. Open fiscal_impact.R. This is the main script that we use to calculate the FIM.
A19: Generating comparison tables between the previous and new FIMs | B19: The comparison section of fiscal_impact.R renders the update-comparison.rmd file which generates graphs comparing last month and this month's components of the FIM. These help us to check for errors and see how much our forecast has changed since the last update. It outputs to results/{this-month-year}/update-comparison-{this-month-year}.html and a copy named index.html is created in the parent directory. It's called index.html so that GitHub knows to use it as a github site. Once you finish running fiscal_impact.R you should commit and push your changes to GitHub. Then make sure that the most recent version of index.html is published at https://github.com/Hutchins-Center/fim (you can find this link under the about page on the FIM's github repo (Hutchins-Center/fim). Share updated link and go through this with Louise. | C19: This step is automated when running fiscal_impact.R
A20: Finalizing update | B20: Once you finalize the update make sure to commit any changes and push them. I recommend labeling this commit '{Year-Quarter} Update finalized' so you can always return to that point in time in the commit history if needed. | C20: git add . git commit -m '{Year-Quarter} Update finalized git push Or your prefferd method for commiting/pushing
A21: When the update is finished, set the top of the fiscal_impact script, set overwrite files to FALSE. This will prevent the saved archival forecast from the update from being overwritten if you change the FIM at all within the same month as the most recent update.
A22: Publishing the FIM
A23: Drafting the text | B23: For a revision, we'll typically just edit the write up from the first release of quarterly data. | C23: Former write ups can be found in Hutchins Center Documents/Projects/Fiscal Impact/Write Ups
A24: Fact checking | B24: A different RA should go through the text of the write up and confirm every number/statement using the FIM output files and graphics. | C24: The fim-interactive-month-year.xlsx file and fim-month-year.xlsx files are a good place to look (make sure they are the most up to date version!) and also look at the FIM interactive graphic that we are posting to ensure that our write up is consistent with it.
A25: Wordpress | B25: The FIM interactive and write up is posted on the Brookings website through Wordpress. | C25: See Hutchins Center Documents/Projects/Fiscal Impact/Updating the FIM Website.docx

Sheet Checklist (CBO Budget Release)
A1: Checklist | B1: Methodology | C1: How to execute | D1: Done?
A2: Pull updated CBO projections data | B2: CBO releases new Ten-Year Budget and Economic Projections. We use these to update our projections for GDP and inflation, and in a number of the forecast sheets. When the new projections come out, we incorporate them into the sheet and code, and then wait to release the updated FIM until the next monthly update. The inst/extdata/projections.xlsx workbook is updated with the new CBO numbers. The data-raw/projections.R script cleans them to be readable in R. | C2: Update CBO data in inst/extdata/projections.xlsx. Refer to the dictionary sheet to figure out which lines of the CBO update correspond to the Haver codes. Open the FIM project by clicking on the "fim.Rproj" file. Run data-raw/projections.R | D2: no
A3: Prepare the Forecast Comparison sheet | B3: This sheet shows us how much our forecast (what is read into the code) has changed since the last update, in level and percent differences. | C3: Copy past the forecast table from the most recent update (Past Values Only) into the "Previous Forecast" table. | D3: no
A4: Updating the spreadsheet | B4: Throughout the forecast spreadsheets, we use CBO projections to forecast certain FIM components. Every row taken from CBO will be marked as such, with comments indicating which update, table and row the numbers are from to make it easier to find. Replace the CBO numbers with the new forecast, and make sure to change the comments so that they reflect the new row #s. Copy paste the old table/old rows near the table from last update's forecast sheet for comparison. Then, we go through each part of the sheet that uses CBO with Louise, and decide how we want to change the forecast or simply update the old CBO rows with new CBO projections, based on the CBO revisions. Make sure to label the old and new CBO numbers clearly! | C4: You may need to download the latest files at: https://www.cbo.gov/data/budget-economic-data We pull data from the following sheets: "10-Year Budget Projections", "Economic Projections", and "Revenue Projections, by Category" | D4: no
A5: Run the code | B5: Run fiscal_impact.R (the main FIM script). The output will incorporate both the CBO changes to the spreadsheet and the new inflation and GDP forecast. | C5: Run fiscal_impact.R | D5: no
A6: Look at the comparison graphs | B6: Fiscal_impact.R runs and knits compare-update.Rmd. Go over the changes from the last update that are due to the CBO with Louise. Make sure everything looks normal. These changes will be published along with the next monthly update. | C6: Look at the output of index.html | D6: no

Sheet historical overrides
A1: name | B1: variable | C1: 2020 Q2 | D1: 2020 Q3 | E1: 2020 Q4 | F1: 2021 Q1 | G1: 2021 Q2 | H1: 2021 Q3 | I1: 2021 Q4 | J1: 2022 Q1 | K1: 2022 Q2 | L1: 2022 Q3 | M1: 2022 Q4 | N1: 2023 Q1 | O1: 2023 Q2 | P1: 2023 Q3 | Q1: 2023 Q4 | R1: 2024 Q1 | S1: 2024 Q2 | T1: 2024 Q3 | U1: 2024 Q4 | V1: 2025 Q1 | W1: 2025 Q2
A2: Consumption Grants Historical Override | B2: consumption_grants_override | C2: 321.194 | D2: =Grants!K73 -> 68.7 | E2: =Grants!L73 -> 69.4 | F2: =Grants!M73 -> 72.7 | G2: =Grants!N73 -> 46.344 | H2: =Grants!O73 -> 60.044 | I2: =Grants!P73 -> 74.249852 | J2: =Grants!Q73 -> 124.72527 | K2: =Grants!R73 -> 167.27903 | ... W2: =Grants!AD73 -> 158.58562
A3: Federal Social Benefits Historical Override | B3: federal_social_benefits_override | C3: 1649.3 | D3: ='Social Benefits'!K30 -> 53.6 | E3: ='Social Benefits'!L30 -> 55.2 | F3: ='Social Benefits'!M30 -> 54.6 | G3: ='Social Benefits'!N30 -> 21.67816 | H3: ='Social Benefits'!O30 -> 18.32984 | I3: ='Social Benefits'!P30 -> -4.376 | J3: ='Social Benefits'!Q30 -> -3.376 | K3: ='Social Benefits'!R30 -> -2.376 | ... W3: ='Social Benefits'!AD30 -> 106.098
A4: ARP Other Vulnerable Historical Override | B4: federal_other_vulnerable_arp_override | C4: 0 | D4: ='Social Benefits'!K22 -> 0 | E4: ='Social Benefits'!L22 -> 0 | F4: ='Social Benefits'!M22 -> 0 | G4: ='Social Benefits'!N22 -> 33.92184 | H4: ='Social Benefits'!O22 -> 44.96616 | I4: ='Social Benefits'!P22 -> 52.757 | J4: ='Social Benefits'!Q22 -> 52.757 | K4: ='Social Benefits'!R22 -> 52.757 | ... W4: ='Social Benefits'!AD22 -> 2.372
A5: ARP Direct Aid Historical Override | B5: federal_other_direct_aid_arp_override | C5: 160.9 | D5: ='Social Benefits'!K27 -> 0 | E5: ='Social Benefits'!L27 -> 0 | F5: ='Social Benefits'!M27 -> 0 | G5: ='Social Benefits'!N27 -> 0 | H5: ='Social Benefits'!O27 -> 3.104 | I5: ='Social Benefits'!P27 -> 19.719 | J5: ='Social Benefits'!Q27 -> 19.719 | K5: ='Social Benefits'!R27 -> 19.719 | ... W5: ='Social Benefits'!AD27 -> 1.63
A6: ARP Subsidies less Provider Relief and PPP | B6: federal_aid_to_small_businesses_arp_override | C6: 0 | D6: =Subsidies!K45 -> 0 | E6: =Subsidies!L45 -> 0 | F6: =Subsidies!M45 -> 0 | G6: =Subsidies!N45 -> 58.78296 | H6: =Subsidies!O45 -> 267.78904 | I6: =Subsidies!P45 -> 110.248 | J6: =Subsidies!Q45 -> 110.248 | K6: =Subsidies!R45 -> 110.248 | ... W6: =Subsidies!AD45 -> -0.901
A7: Federal Corporate Taxes Advanced Estimate Override | B7: federal_corporate_taxes_override | C7: #REF! | D7: =#REF! -> #REF! | E7: =#REF! -> #REF! | F7: =#REF! -> #REF! | G7: =#REF! -> #REF! | H7: =#REF! -> #REF! | I7: =#REF! -> #REF! | J7: =#REF! -> #REF! | K7: =#REF! -> #REF! | ... W7: =#REF! -> #REF!
A8: State Corporate Taxes Advanced Estimate Override | B8: state_corporate_taxes_override | N8: =forecast!#REF! -> #REF! | O8: =forecast!#REF! -> #REF! | P8: =forecast!#REF! -> #REF! | Q8: =forecast!#REF! -> #REF! | R8: =forecast!#REF! -> #REF! | S8: =forecast!#REF! -> #REF! | T8: =forecast!#REF! -> #REF! | U8: =forecast!#REF! -> #REF! | ... W8: =forecast!#REF! -> #REF!
A9: Investment Grants Override | B9: investment_grants_override | C9: 75.484 | D9: =Grants!K94 -> 5.644 | E9: =Grants!L94 -> 5.668 | F9: =Grants!M94 -> 5.216 | G9: =Grants!N94 -> 6.724 | H9: =Grants!O94 -> 5.7 | I9: =Grants!P94 -> 5.74 | J9: =Grants!Q94 -> 6.208 | K9: =Grants!R94 -> 5.8262857 | ... W9: =Grants!AD94 -> 5.8262857
A10: Supply Side IRA Override | B10: supply_side_ira_override | C10: 0 | D10: 0 | E10: 0 | F10: 0 | G10: 0 | H10: 0 | I10: 0 | J10: 0 | K10: ='Supply Side IRA'!R14 -> 0 | L10: ='Supply Side IRA'!S14 -> 4.7396188 | M10: ='Supply Side IRA'!T14 -> 7.9776987 | N10: ='Supply Side IRA'!U14 -> 30.340947 | O10: ='Supply Side IRA'!V14 -> 46.245323 | P10: ='Supply Side IRA'!W14 -> 62.071265 | Q10: ='Supply Side IRA'!X14 -> 68.31219 | R10: ='Supply Side IRA'!Y14 -> 78.014538 | ... W10: ='Supply Side IRA'!AD14 -> 88.394443
A11: Federal Student Loans Override | B11: federal_student_loans_override | C11: 45 | D11: ='Student loans'!K12 -> 45 | E11: ='Student loans'!L12 -> 45 | F11: ='Student loans'!M12 -> 45 | G11: ='Student loans'!N12 -> 45 | H11: ='Student loans'!O12 -> 45 | I11: ='Student loans'!P12 -> 45 | J11: ='Student loans'!Q12 -> 45 | K11: ='Student loans'!R12 -> 45 | ... W11: ='Student loans'!AD12 -> 2.6696
A12: Uncertainty Override | B12: uncertainty_override | C12: 0 | D12: 0 | E12: 0 | F12: 0 | G12: 0 | H12: 0 | I12: 0 | J12: 0 | K12: 0 | L12: 0 | M12: 0 | N12: 0 | O12: 0 | P12: 0 | Q12: 0 | R12: 0 | S12: 0 | T12: 0 | U12: 0 | V12: 0 | W12: -0.3

Sheet Haver Pivoted
A1: name | B1: 1970 Q1 | C1: 1970 Q2 | D1: 1970 Q3 | E1: 1970 Q4 | F1: 1971 Q1 | G1: 1971 Q2 | H1: 1971 Q3 | I1: 1971 Q4 | J1: 1972 Q1 | K1: 1972 Q2 | L1: 1972 Q3 | M1: 1972 Q4 | N1: 1973 Q1 | O1: 1973 Q2 | P1: 1973 Q3 | Q1: 1973 Q4 | R1: 1974 Q1 | S1: 1974 Q2 | T1: 1974 Q3 | U1: 1974 Q4 | V1: 1975 Q1 | W1: 1975 Q2 | X1: 1975 Q3 | Y1: 1975 Q4 | Z1: 1976 Q1 | AA1: 1976 Q2 | AB1: 1976 Q3 | AC1: 1976 Q4 | AD1: 1977 Q1 | AE1: 1977 Q2 | AF1: 1977 Q3 | AG1: 1977 Q4 | AH1: 1978 Q1 | AI1: 1978 Q2 | AJ1: 1978 Q3 | AK1: 1978 Q4 | AL1: 1979 Q1 | AM1: 1979 Q2 | AN1: 1979 Q3 | AO1: 1979 Q4 | AP1: 1980 Q1 | AQ1: 1980 Q2 | AR1: 1980 Q3 | AS1: 1980 Q4 | AT1: 1981 Q1 | AU1: 1981 Q2 | AV1: 1981 Q3 | AW1: 1981 Q4 | AX1: 1982 Q1 | AY1: 1982 Q2 | AZ1: 1982 Q3 | BA1: 1982 Q4 | BB1: 1983 Q1 | BC1: 1983 Q2 | BD1: 1983 Q3 | BE1: 1983 Q4 | BF1: 1984 Q1 | BG1: 1984 Q2 | BH1: 1984 Q3 | BI1: 1984 Q4 | BJ1: 1985 Q1 | BK1: 1985 Q2 | BL1: 1985 Q3 | BM1: 1985 Q4 | BN1: 1986 Q1 | BO1: 1986 Q2 | BP1: 1986 Q3 | BQ1: 1986 Q4 | BR1: 1987 Q1 | BS1: 1987 Q2 | BT1: 1987 Q3 | BU1: 1987 Q4 | BV1: 1988 Q1 | BW1: 1988 Q2 | BX1: 1988 Q3 | BY1: 1988 Q4 | BZ1: 1989 Q1 | CA1: 1989 Q2 | CB1: 1989 Q3 | CC1: 1989 Q4 | CD1: 1990 Q1 | CE1: 1990 Q2 | CF1: 1990 Q3 | CG1: 1990 Q4 | CH1: 1991 Q1 | CI1: 1991 Q2 | CJ1: 1991 Q3 | CK1: 1991 Q4 | CL1: 1992 Q1 | CM1: 1992 Q2 | CN1: 1992 Q3 | CO1: 1992 Q4 | CP1: 1993 Q1 | CQ1: 1993 Q2 | CR1: 1993 Q3 | CS1: 1993 Q4 | CT1: 1994 Q1 | CU1: 1994 Q2 | CV1: 1994 Q3 | CW1: 1994 Q4 | CX1: 1995 Q1 | CY1: 1995 Q2 | CZ1: 1995 Q3 | DA1: 1995 Q4 | DB1: 1996 Q1 | DC1: 1996 Q2 | DD1: 1996 Q3 | DE1: 1996 Q4 | DF1: 1997 Q1 | DG1: 1997 Q2 | DH1: 1997 Q3 | DI1: 1997 Q4 | DJ1: 1998 Q1 | DK1: 1998 Q2 | DL1: 1998 Q3 | DM1: 1998 Q4 | DN1: 1999 Q1 | DO1: 1999 Q2 | DP1: 1999 Q3 | DQ1: 1999 Q4 | DR1: 2000 Q1 | DS1: 2000 Q2 | DT1: 2000 Q3 | DU1: 2000 Q4 | DV1: 2001 Q1 | DW1: 2001 Q2 | DX1: 2001 Q3 | DY1: 2001 Q4 | DZ1: 2002 Q1 | EA1: 2002 Q2 | EB1: 2002 Q3 | EC1: 2002 Q4 | ED1: 2003 Q1 | EE1: 2003 Q2 | EF1: 2003 Q3 | EG1: 2003 Q4 | EH1: 2004 Q1 | EI1: 2004 Q2 | EJ1: 2004 Q3 | EK1: 2004 Q4 | EL1: 2005 Q1 | EM1: 2005 Q2 | EN1: 2005 Q3 | EO1: 2005 Q4 | EP1: 2006 Q1 | EQ1: 2006 Q2 | ER1: 2006 Q3 | ES1: 2006 Q4 | ET1: 2007 Q1 | EU1: 2007 Q2 | EV1: 2007 Q3 | EW1: 2007 Q4 | EX1: 2008 Q1 | EY1: 2008 Q2 | EZ1: 2008 Q3 | FA1: 2008 Q4 | FB1: 2009 Q1 | FC1: 2009 Q2 | FD1: 2009 Q3 | FE1: 2009 Q4 | FF1: 2010 Q1 | FG1: 2010 Q2 | FH1: 2010 Q3 | FI1: 2010 Q4 | FJ1: 2011 Q1 | FK1: 2011 Q2 | FL1: 2011 Q3 | FM1: 2011 Q4 | FN1: 2012 Q1 | FO1: 2012 Q2 | FP1: 2012 Q3 | FQ1: 2012 Q4 | FR1: 2013 Q1 | FS1: 2013 Q2 | FT1: 2013 Q3 | FU1: 2013 Q4 | FV1: 2014 Q1 | FW1: 2014 Q2 | FX1: 2014 Q3 | FY1: 2014 Q4 | FZ1: 2015 Q1 | GA1: 2015 Q2 | GB1: 2015 Q3 | GC1: 2015 Q4 | GD1: 2016 Q1 | GE1: 2016 Q2 | GF1: 2016 Q3 | GG1: 2016 Q4 | GH1: 2017 Q1 | GI1: 2017 Q2 | GJ1: 2017 Q3 | GK1: 2017 Q4 | GL1: 2018 Q1 | GM1: 2018 Q2 | GN1: 2018 Q3 | GO1: 2018 Q4 | GP1: 2019 Q1 | GQ1: 2019 Q2 | GR1: 2019 Q3 | GS1: 2019 Q4 | GT1: 2020 Q1 | GU1: 2020 Q2 | GV1: 2020 Q3 | GW1: 2020 Q4 | GX1: 2021 Q1 | GY1: 2021 Q2 | GZ1: 2021 Q3 | HA1: 2021 Q4 | HB1: 2022 Q1 | HC1: 2022 Q2 | HD1: 2022 Q3 | HE1: 2022 Q4 | HF1: 2023 Q1 | HG1: 2023 Q2 | HH1: 2023 Q3 | HI1: 2023 Q4 | HJ1: 2024 Q1 | HK1: 2024 Q2 | HL1: 2024 Q3 | HM1: 2024 Q4 | HN1: 2025 Q1 | HO1: 2025 Q2
A2: gdp | B2: 1051.2 | C2: 1067.4 | D2: 1086.1 | E2: 1088.6 | F2: 1135.2 | G2: 1156.3 | H2: 1177.7 | I2: 1190.3 | J2: 1230.6 | K2: 1266.4 | L2: 1290.6 | M2: 1328.9 | N2: 1377.5 | O2: 1413.9 | P2: 1433.8 | Q2: 1476.3 | R2: 1491.2 | S2: 1530.1 | T2: 1560 | U2: 1599.7 | V2: 1616.1 | W2: 1651.9 | X2: 1709.8 | Y2: 1761.8 | Z2: 1820.5 | AA2: 1852.3 | AB2: 1886.6 | AC2: 1934.3 | AD2: 1988.6 | AE2: 2055.9 | AF2: 2118.5 | AG2: 2164.3 | AH2: 2202.8 | AI2: 2331.6 | AJ2: 2395.1 | AK2: 2476.9 | AL2: 2526.6 | AM2: 2591.2 | AN2: 2667.6 | AO2: 2723.9 | AP2: 2789.8 | AQ2: 2797.4 | AR2: 2856.5 | AS2: 2985.6 | AT2: 3124.2 | AU2: 3162.5 | AV2: 3260.6 | AW2: 3280.8 | AX2: 3274.3 | AY2: 3332 | AZ2: 3366.3 | BA2: 3402.6 | BB2: 3473.4 | BC2: 3578.8 | BD2: 3689.2 | BE2: 3794.7 | BF2: 3908.1 | BG2: 4009.6 | BH2: 4084.3 | BI2: 4148.6 | BJ2: 4230.2 | BK2: 4294.9 | BL2: 4386.8 | BM2: 4444.1 | BN2: 4507.9 | BO2: 4545.3 | BP2: 4607.7 | BQ2: 4657.6 | BR2: 4722.2 | BS2: 4806.2 | BT2: 4884.6 | BU2: 5008 | BV2: 5073.4 | BW2: 5190 | BX2: 5282.8 | BY2: 5399.5 | BZ2: 5511.3 | CA2: 5612.5 | CB2: 5695.4 | CC2: 5747.2 | CD2: 5872.7 | CE2: 5960 | CF2: 6015.1 | CG2: 6004.7 | CH2: 6035.2 | CI2: 6126.9 | CJ2: 6205.9 | CK2: 6264.5 | CL2: 6363.1 | CM2: 6470.8 | CN2: 6566.6 | CO2: 6680.8 | CP2: 6729.5 | CQ2: 6808.9 | CR2: 6882.1 | CS2: 7013.7 | CT2: 7115.7 | CU2: 7246.9 | CV2: 7331.1 | CW2: 7455.3 | CX2: 7522.3 | CY2: 7581 | CZ2: 7683.1 | DA2: 7772.6 | DB2: 7868.5 | DC2: 8032.8 | DD2: 8131.4 | DE2: 8259.8 | DF2: 8362.7 | DG2: 8518.8 | DH2: 8662.8 | DI2: 8765.9 | DJ2: 8866.5 | DK2: 8969.7 | DL2: 9121.1 | DM2: 9294 | DN2: 9411.7 | DO2: 9526.2 | DP2: 9686.6 | DQ2: 9900.2 | DR2: 10002.2 | DS2: 10247.7 | DT2: 10318.2 | DU2: 10435.7 | DV2: 10470.2 | DW2: 10599 | DX2: 10598 | DY2: 10660.5 | DZ2: 10783.5 | EA2: 10887.5 | EB2: 10984 | EC2: 11061.4 | ED2: 11174.1 | EE2: 11312.8 | EF2: 11566.7 | EG2: 11772.2 | EH2: 11923.4 | EI2: 12112.8 | EJ2: 12305.3 | EK2: 12527.2 | EL2: 12767.3 | EM2: 12922.7 | EN2: 13142.6 | EO2: 13324.2 | EP2: 13599.2 | EQ2: 13753.4 | ER2: 13870.2 | ES2: 14039.6 | ET2: 14215.7 | EU2: 14402.1 | EV2: 14564.1 | EW2: 14715.1 | EX2: 14706.5 | EY2: 14865.7 | EZ2: 14899 | FA2: 14608.2 | FB2: 14430.9 | FC2: 14381.2 | FD2: 14448.9 | FE2: 14651.2 | FF2: 14764.6 | FG2: 14980.2 | FH2: 15141.6 | FI2: 15309.5 | FJ2: 15351.4 | FK2: 15557.5 | FL2: 15647.7 | FM2: 15842.3 | FN2: 16068.8 | FO2: 16207.1 | FP2: 16319.5 | FQ2: 16420.4 | FR2: 16648.2 | FS2: 16728.7 | FT2: 16953.8 | FU2: 17192 | FV2: 17197.7 | FW2: 17518.5 | FX2: 17804.2 | FY2: 17912.1 | FZ2: 18063.5 | GA2: 18279.8 | GB2: 18401.6 | GC2: 18435.1 | GD2: 18525.9 | GE2: 18711.7 | GF2: 18892.6 | GG2: 19089.4 | GH2: 19280.1 | GI2: 19438.6 | GJ2: 19692.6 | GK2: 20037.1 | GL2: 20328.6 | GM2: 20580.9 | GN2: 20798.7 | GO2: 20917.9 | GP2: 21111.6 | GQ2: 21397.9 | GR2: 21717.2 | GS2: 21933.2 | GT2: 21727.7 | GU2: 19935.4 | GV2: 21684.6 | GW2: 22068.8 | GX2: 22656.8 | GY2: 23368.9 | GZ2: 23922 | HA2: 24777 | HB2: 25215.5 | HC2: 25805.8 | HD2: 26272 | HE2: 26734.3 | HF2: 27164.4 | HG2: 27453.8 | HH2: 27967.7 | HI2: 28297 | HJ2: 28624.1 | HK2: 29016.7 | HL2: 29374.9 | HM2: 29723.9 | HN2: 29962 | HO2: 30353.9
A3: gdph | B3: 5300.7 | C3: 5308.2 | D3: 5357.1 | E3: 5299.7 | F3: 5443.6 | G3: 5473.1 | H3: 5518.1 | I3: 5531 | J3: 5632.6 | K3: 5760.5 | L3: 5814.9 | M3: 5912.2 | N3: 6058.5 | O3: 6124.5 | P3: 6092.3 | Q3: 6150.1 | R3: 6097.3 | S3: 6111.8 | T3: 6054 | U3: 6030.5 | V3: 5957 | W3: 5999.6 | X3: 6102.3 | Y3: 6184.5 | Z3: 6323.6 | AA3: 6370 | AB3: 6404.9 | AC3: 6451.2 | AD3: 6527.7 | AE3: 6654.5 | AF3: 6774.5 | AG3: 6774.6 | AH3: 6796.3 | AI3: 7058.9 | AJ3: 7129.9 | AK3: 7225.8 | AL3: 7238.7 | AM3: 7246.5 | AN3: 7300.3 | AO3: 7318.5 | AP3: 7341.6 | AQ3: 7190.3 | AR3: 7181.7 | AS3: 7315.7 | AT3: 7459 | AU3: 7403.7 | AV3: 7492.4 | AW3: 7410.8 | AX3: 7295.6 | AY3: 7328.9 | AZ3: 7300.9 | BA3: 7303.8 | BB3: 7400.1 | BC3: 7568.5 | BD3: 7719.7 | BE3: 7880.8 | BF3: 8034.8 | BG3: 8173.7 | BH3: 8252.5 | BI3: 8320.2 | BJ3: 8400.8 | BK3: 8474.8 | BL3: 8604.2 | BM3: 8668.2 | BN3: 8749.1 | BO3: 8788.5 | BP3: 8872.6 | BQ3: 8920.2 | BR3: 8986.4 | BS3: 9083.3 | BT3: 9162 | BU3: 9319.3 | BV3: 9367.5 | BW3: 9490.6 | BX3: 9546.2 | BY3: 9673.4 | BZ3: 9771.7 | CA3: 9846.3 | CB3: 9919.2 | CC3: 9938.8 | CD3: 10047.4 | CE3: 10083.9 | CF3: 10090.6 | CG3: 9998.7 | CH3: 9951.9 | CI3: 10029.5 | CJ3: 10080.2 | CK3: 10115.3 | CL3: 10236.4 | CM3: 10347.4 | CN3: 10449.7 | CO3: 10558.6 | CP3: 10576.3 | CQ3: 10637.8 | CR3: 10688.6 | CS3: 10834 | CT3: 10939.1 | CU3: 11087.4 | CV3: 11152.2 | CW3: 11279.9 | CX3: 11320 | CY3: 11353.7 | CZ3: 11450.3 | DA3: 11528.1 | DB3: 11614.4 | DC3: 11808.1 | DD3: 11914.1 | DE3: 12037.8 | DF3: 12115.5 | DG3: 12317.2 | DH3: 12471 | DI3: 12577.5 | DJ3: 12703.7 | DK3: 12821.3 | DL3: 12982.8 | DM3: 13191.7 | DN3: 13315.6 | DO3: 13426.7 | DP3: 13604.8 | DQ3: 13828 | DR3: 13878.1 | DS3: 14130.9 | DT3: 14145.3 | DU3: 14229.8 | DV3: 14183.1 | DW3: 14271.7 | DX3: 14214.5 | DY3: 14253.6 | DZ3: 14372.8 | EA3: 14460.8 | EB3: 14519.6 | EC3: 14537.6 | ED3: 14614.1 | EE3: 14743.6 | EF3: 14988.8 | EG3: 15162.8 | EH3: 15248.7 | EI3: 15366.9 | EJ3: 15512.6 | EK3: 15670.9 | EL3: 15844.7 | EM3: 15922.8 | EN3: 16047.6 | EO3: 16136.7 | EP3: 16353.8 | EQ3: 16396.2 | ER3: 16420.7 | ES3: 16561.9 | ET3: 16611.7 | EU3: 16713.3 | EV3: 16809.6 | EW3: 16915.2 | EX3: 16843 | EY3: 16943.3 | EZ3: 16854.3 | FA3: 16485.4 | FB3: 16298.3 | FC3: 16269.1 | FD3: 16326.3 | FE3: 16502.8 | FF3: 16582.7 | FG3: 16743.2 | FH3: 16872.3 | FI3: 16960.9 | FJ3: 16920.6 | FK3: 17035.1 | FL3: 17031.3 | FM3: 17222.6 | FN3: 17367 | FO3: 17444.5 | FP3: 17469.7 | FQ3: 17489.9 | FR3: 17662.4 | FS3: 17709.7 | FT3: 17860.5 | FU3: 18016.1 | FV3: 17954 | FW3: 18185.9 | FX3: 18406.9 | FY3: 18500 | FZ3: 18666.6 | GA3: 18782.2 | GB3: 18857.4 | GC3: 18892.2 | GD3: 19001.7 | GE3: 19062.7 | GF3: 19197.9 | GG3: 19304.4 | GH3: 19398.3 | GI3: 19506.9 | GJ3: 19660.8 | GK3: 19882.4 | GL3: 20044.1 | GM3: 20150.5 | GN3: 20276.2 | GO3: 20304.9 | GP3: 20431.6 | GQ3: 20602.3 | GR3: 20843.3 | GS3: 20985.4 | GT3: 20693.2 | GU3: 19056.6 | GV3: 20548.8 | GW3: 20771.7 | GX3: 21058.4 | GY3: 21389 | GZ3: 21571.4 | HA3: 21960.4 | HB3: 21903.9 | HC3: 21919.2 | HD3: 22066.8 | HE3: 22249.5 | HF3: 22403.4 | HG3: 22539.4 | HH3: 22780.9 | HI3: 22960.6 | HJ3: 23053.5 | HK3: 23223.9 | HL3: 23400.3 | HM3: 23542.3 | HN3: 23512.7 | HO3: 23703.8
A4: jgdp | B4: 19.823 | C4: 20.109 | D4: 20.274 | E4: 20.539 | F4: 20.85 | G4: 21.13 | H4: 21.343 | I4: 21.52 | J4: 21.865 | K4: 21.999 | L4: 22.198 | M4: 22.45 | N4: 22.735 | O4: 23.111 | P4: 23.553 | Q4: 23.961 | R4: 24.446 | S4: 24.989 | T4: 25.759 | U4: 26.541 | V4: 27.141 | W4: 27.534 | X4: 28.021 | Y4: 28.489 | Z4: 28.8 | AA4: 29.088 | AB4: 29.459 | AC4: 29.96 | AD4: 30.443 | AE4: 30.925 | AF4: 31.351 | AG4: 31.875 | AH4: 32.397 | AI4: 33.043 | AJ4: 33.626 | AK4: 34.291 | AL4: 34.931 | AM4: 35.775 | AN4: 36.522 | AO4: 37.188 | AP4: 38.001 | AQ4: 38.903 | AR4: 39.77 | AS4: 40.825 | AT4: 41.907 | AU4: 42.694 | AV4: 43.524 | AW4: 44.243 | AX4: 44.877 | AY4: 45.473 | AZ4: 46.104 | BA4: 46.571 | BB4: 46.943 | BC4: 47.291 | BD4: 47.794 | BE4: 48.151 | BF4: 48.626 | BG4: 49.063 | BH4: 49.506 | BI4: 49.852 | BJ4: 50.363 | BK4: 50.66 | BL4: 50.997 | BM4: 51.262 | BN4: 51.515 | BO4: 51.695 | BP4: 51.941 | BQ4: 52.25 | BR4: 52.554 | BS4: 52.911 | BT4: 53.32 | BU4: 53.72 | BV4: 54.135 | BW4: 54.676 | BX4: 55.345 | BY4: 55.854 | BZ4: 56.392 | CA4: 57.002 | CB4: 57.425 | CC4: 57.817 | CD4: 58.447 | CE4: 59.101 | CF4: 59.612 | CG4: 60.067 | CH4: 60.651 | CI4: 61.088 | CJ4: 61.557 | CK4: 61.915 | CL4: 62.162 | CM4: 62.533 | CN4: 62.833 | CO4: 63.275 | CP4: 63.652 | CQ4: 64.027 | CR4: 64.349 | CS4: 64.727 | CT4: 65.058 | CU4: 65.369 | CV4: 65.717 | CW4: 66.083 | CX4: 66.46 | CY4: 66.785 | CZ4: 67.084 | DA4: 67.401 | DB4: 67.712 | DC4: 67.988 | DD4: 68.318 | DE4: 68.607 | DF4: 68.915 | DG4: 69.258 | DH4: 69.464 | DI4: 69.713 | DJ4: 69.783 | DK4: 69.964 | DL4: 70.235 | DM4: 70.424 | DN4: 70.615 | DO4: 70.934 | DP4: 71.207 | DQ4: 71.581 | DR4: 72.058 | DS4: 72.491 | DT4: 72.945 | DU4: 73.341 | DV4: 73.843 | DW4: 74.335 | DX4: 74.56 | DY4: 74.801 | DZ4: 74.998 | EA4: 75.295 | EB4: 75.633 | EC4: 76.073 | ED4: 76.482 | EE4: 76.746 | EF4: 77.185 | EG4: 77.633 | EH4: 78.191 | EI4: 78.825 | EJ4: 79.323 | EK4: 79.936 | EL4: 80.55 | EM4: 81.137 | EN4: 81.905 | EO4: 82.557 | EP4: 83.135 | EQ4: 83.871 | ER4: 84.486 | ES4: 84.806 | ET4: 85.655 | EU4: 86.201 | EV4: 86.568 | EW4: 86.982 | EX4: 87.359 | EY4: 87.678 | EZ4: 88.361 | FA4: 88.511 | FB4: 88.536 | FC4: 88.418 | FD4: 88.474 | FE4: 88.798 | FF4: 89.018 | FG4: 89.431 | FH4: 89.755 | FI4: 90.27 | FJ4: 90.71 | FK4: 91.363 | FL4: 91.84 | FM4: 91.951 | FN4: 92.495 | FO4: 92.881 | FP4: 93.459 | FQ4: 93.869 | FR4: 94.204 | FS4: 94.474 | FT4: 94.989 | FU4: 95.477 | FV4: 95.84 | FW4: 96.343 | FX4: 96.762 | FY4: 96.8 | FZ4: 96.742 | GA4: 97.302 | GB4: 97.536 | GC4: 97.527 | GD4: 97.468 | GE4: 98.108 | GF4: 98.372 | GG4: 98.884 | GH4: 99.389 | GI4: 99.656 | GJ4: 100.174 | GK4: 100.78 | GL4: 101.428 | GM4: 102.14 | GN4: 102.586 | GO4: 103.005 | GP4: 103.332 | GQ4: 103.855 | GR4: 104.196 | GS4: 104.543 | GT4: 105.001 | GU4: 104.651 | GV4: 105.574 | GW4: 106.293 | GX4: 107.645 | GY4: 109.278 | GZ4: 110.931 | HA4: 112.836 | HB4: 115.16 | HC4: 117.76 | HD4: 119.073 | HE4: 120.173 | HF4: 121.247 | HG4: 121.809 | HH4: 122.785 | HI4: 123.247 | HJ4: 124.168 | HK4: 124.942 | HL4: 125.543 | HM4: 126.27 | HN4: 127.441 | HO4: 128.063
A5: c | B5: 631.7 | C5: 641.6 | D5: 653.5 | E5: 660.2 | F5: 679.2 | G5: 693.2 | H5: 705.6 | I5: 721.7 | J5: 738.9 | K5: 757.4 | L5: 775.8 | M5: 800.5 | N5: 825 | O5: 840.5 | P5: 858.9 | Q5: 873.9 | R5: 891.9 | S5: 920.4 | T5: 949.3 | U5: 959.1 | V5: 985.2 | W5: 1013.6 | X5: 1047.2 | Y5: 1076.2 | Z5: 1109.9 | AA5: 1129.5 | AB5: 1158.8 | AC5: 1192.4 | AD5: 1228.2 | AE5: 1256 | AF5: 1286.9 | AG5: 1324.8 | AH5: 1354.1 | AI5: 1411.4 | AJ5: 1442.2 | AK5: 1481.4 | AL5: 1517.1 | AM5: 1557.6 | AN5: 1611.9 | AO5: 1655 | AP5: 1702.3 | AQ5: 1704.7 | AR5: 1763.8 | AS5: 1831.9 | AT5: 1885.7 | AU5: 1917.5 | AV5: 1958.1 | AW5: 1974.4 | AX5: 2014.2 | AY5: 2039.6 | AZ5: 2085.7 | BA5: 2145.6 | BB5: 2184.6 | BC5: 2249.4 | BD5: 2319.9 | BE5: 2372.5 | BF5: 2418.2 | BG5: 2475.9 | BH5: 2513.5 | BI5: 2561.8 | BJ5: 2636 | BK5: 2681.8 | BL5: 2754.1 | BM5: 2779.4 | BN5: 2823.6 | BO5: 2851.5 | BP5: 2917.2 | BQ5: 2952.8 | BR5: 2983.5 | BS5: 3053.3 | BT5: 3117.4 | BU5: 3150.9 | BV5: 3231.9 | BW5: 3291.7 | BX5: 3361.9 | BY5: 3434.5 | BZ5: 3490.2 | CA5: 3553.8 | CB5: 3609.4 | CC5: 3653.7 | CD5: 3737.9 | CE5: 3783.4 | CF5: 3846.7 | CG5: 3867.9 | CH5: 3873.6 | CI5: 3926.9 | CJ5: 3973.3 | CK5: 4000 | CL5: 4100.4 | CM5: 4155.7 | CN5: 4227 | CO5: 4307.2 | CP5: 4349.5 | CQ5: 4418.6 | CR5: 4487.2 | CS5: 4552.7 | CT5: 4621.2 | CU5: 4683.2 | CV5: 4752.8 | CW5: 4826.7 | CX5: 4862.4 | CY5: 4933.6 | CZ5: 4998.7 | DA5: 5055.7 | DB5: 5130.6 | DC5: 5220.5 | DD5: 5274.5 | DE5: 5352.8 | DF5: 5433.1 | DG5: 5471.3 | DH5: 5579.2 | DI5: 5663.6 | DJ5: 5721.3 | DK5: 5832.6 | DL5: 5926.8 | DM5: 6028.2 | DN5: 6102 | DO5: 6230.6 | DP5: 6335.3 | DQ5: 6467 | DR5: 6618.2 | DS5: 6711.9 | DT5: 6820 | DU5: 6918.6 | DV5: 6995.3 | DW5: 7042.3 | DX5: 7070.3 | DY5: 7187.3 | DZ5: 7217.7 | EA5: 7308 | EB5: 7397.1 | EC5: 7473 | ED5: 7567.2 | EE5: 7661.5 | EF5: 7820.9 | EG5: 7913.5 | EH5: 8048.8 | EI5: 8147.1 | EJ5: 8283.3 | EK5: 8448.6 | EL5: 8551.7 | EM5: 8701.1 | EN5: 8868.1 | EO5: 8955.3 | EP5: 9100.2 | EQ5: 9227.6 | ER5: 9353.8 | ES5: 9427.4 | ET5: 9572.1 | EU5: 9678.7 | EV5: 9798.4 | EW5: 9937.1 | EX5: 10004.4 | EY5: 10129.9 | EZ5: 10159.1 | FA5: 9906.9 | FB5: 9815 | FC5: 9805.5 | FD5: 9939.4 | FE5: 10005 | FF5: 10101.8 | FG5: 10208.1 | FH5: 10300.8 | FI5: 10430.3 | FJ5: 10558.2 | FK5: 10673 | FL5: 10755 | FM5: 10809.2 | FN5: 10959.3 | FO5: 11005.1 | FP5: 11059.4 | FQ5: 11165.7 | FR5: 11277.7 | FS5: 11315.7 | FT5: 11408.4 | FU5: 11551.2 | FV5: 11646 | FW5: 11810.5 | FX5: 11959.8 | FY5: 12081.6 | FZ5: 12119.8 | GA5: 12264.1 | GB5: 12382.5 | GC5: 12423.4 | GD5: 12523.2 | GE5: 12665.1 | GF5: 12797.1 | GG5: 12922 | GH5: 13097.3 | GI5: 13188.7 | GJ5: 13325.1 | GK5: 13551.4 | GL5: 13745.1 | GM5: 13891.3 | GN5: 14002.2 | GO5: 14099.2 | GP5: 14150.2 | GQ5: 14350.7 | GR5: 14548.3 | GS5: 14701 | GT5: 14496.2 | GU5: 13175.6 | GV5: 14478 | GW5: 14752.7 | GX5: 15259.4 | GY5: 16016.3 | GZ5: 16363.9 | HA5: 16816.1 | HB5: 17175.1 | HC5: 17603.8 | HD5: 17876.2 | HE5: 18108.3 | HF5: 18506.2 | HG5: 18685.7 | HH5: 18929 | HI5: 19170.2 | HJ5: 19424.8 | HK5: 19682.7 | HL5: 19938.4 | HM5: 20255.5 | HN5: 20461.6 | HO5: 20643.9
A6: ch | B6: 3248.9 | C6: 3263.6 | D6: 3292.2 | E6: 3283.2 | F6: 3346.3 | G6: 3377 | H6: 3403.9 | I6: 3460.4 | J6: 3506.1 | K6: 3572.8 | L6: 3627.9 | M6: 3713 | N6: 3780.8 | O6: 3779.1 | P6: 3792.4 | Q6: 3781.1 | R6: 3747.3 | S6: 3760.8 | T6: 3776.9 | U6: 3721.7 | V6: 3752.9 | W6: 3814.7 | X6: 3868.9 | Y6: 3910.5 | Z6: 3988.7 | AA6: 4025.4 | AB6: 4067.8 | AC6: 4120.5 | AD6: 4169.1 | AE6: 4191.7 | AF6: 4231.3 | AG6: 4295 | AH6: 4319.1 | AI6: 4411.4 | AJ6: 4430 | AK6: 4465.7 | AL6: 4488.8 | AM6: 4485.9 | AN6: 4529.6 | AO6: 4540.8 | AP6: 4534.3 | AQ6: 4432.2 | AR6: 4480.8 | AS6: 4541.4 | AT6: 4556.6 | AU6: 4556.9 | AV6: 4578 | AW6: 4546.7 | AX6: 4580.2 | AY6: 4594.1 | AZ6: 4624.9 | BA6: 4706 | BB6: 4752.5 | BC6: 4849.3 | BD6: 4936.2 | BE6: 5014.9 | BF6: 5056.5 | BG6: 5127.3 | BH6: 5165.4 | BI6: 5232.3 | BJ6: 5321.2 | BK6: 5370 | BL6: 5472 | BM6: 5483.9 | BN6: 5531.8 | BO6: 5592.1 | BP6: 5691 | BQ6: 5725.8 | BR6: 5731.2 | BS6: 5809.4 | BT6: 5875.6 | BU6: 5888.1 | BV6: 5992.1 | BW6: 6036.4 | BX6: 6090 | BY6: 6159.2 | BZ6: 6187.8 | CA6: 6216.7 | CB6: 6276.9 | CC6: 6304.2 | CD6: 6357.2 | CE6: 6376.6 | CF6: 6401.8 | CG6: 6353.1 | CH6: 6329.2 | CI6: 6381.7 | CJ6: 6413.5 | CK6: 6410.3 | CL6: 6530.3 | CM6: 6574.7 | CN6: 6645.1 | CO6: 6724.3 | CP6: 6750.1 | CQ6: 6811.5 | CR6: 6887.3 | CS6: 6947.8 | CT6: 7027.3 | CU6: 7081.9 | CV6: 7135.9 | CW6: 7213.1 | CX6: 7231 | CY6: 7294.4 | CZ6: 7360.5 | DA6: 7411.9 | DB6: 7480.2 | DC6: 7560.7 | DD6: 7606.5 | DE6: 7667.1 | DF6: 7747.9 | DG6: 7782.8 | DH6: 7915.4 | DI6: 8010 | DJ6: 8091 | DK6: 8233.5 | DL6: 8340.8 | DM6: 8461.3 | DN6: 8548.2 | DO6: 8679.1 | DP6: 8776.7 | DQ6: 8905.1 | DR6: 9039.7 | DS6: 9124.2 | DT6: 9211.6 | DU6: 9292.1 | DV6: 9325.8 | DW6: 9344.5 | DX6: 9377 | DY6: 9528.3 | DZ6: 9549.5 | EA6: 9597.8 | EB6: 9665 | EC6: 9718.7 | ED6: 9766.6 | EE6: 9878.4 | EF6: 10018.1 | EG6: 10087.1 | EH6: 10181.1 | EI6: 10236.7 | EJ6: 10356.9 | EK6: 10474.1 | EL6: 10540.6 | EM6: 10657.4 | EN6: 10745.9 | EO6: 10765.7 | EP6: 10883.1 | EQ6: 10939.5 | ER6: 11009.7 | ES6: 11114.8 | ET6: 11183.3 | EU6: 11212.7 | EV6: 11287.5 | EW6: 11331.9 | EX6: 11316.4 | EY6: 11347.6 | EZ6: 11260.1 | FA6: 11158.8 | FB6: 11130.5 | FC6: 11075.7 | FD6: 11150.2 | FE6: 11137.9 | FF6: 11202.5 | FG6: 11303 | FH6: 11383.6 | FI6: 11453.4 | FJ6: 11497.1 | FK6: 11509 | FL6: 11544 | FM6: 11563.9 | FN6: 11647.3 | FO6: 11667.8 | FP6: 11691.4 | FQ6: 11738 | FR6: 11814.3 | FS6: 11848.1 | FT6: 11896.3 | FU6: 12001 | FV6: 12044.2 | FW6: 12159.9 | FX6: 12280.1 | FY6: 12421.6 | FZ6: 12516.9 | GA6: 12603.1 | GB6: 12691.8 | GC6: 12743.4 | GD6: 12839.6 | GE6: 12903.3 | GF6: 12993.1 | GG6: 13060.1 | GH6: 13160.5 | GI6: 13225.7 | GJ6: 13315.4 | GK6: 13460.9 | GL6: 13558.4 | GM6: 13631 | GN6: 13693.8 | GO6: 13736.6 | GP6: 13758.3 | GQ6: 13875.7 | GR6: 14033.2 | GS6: 14125.3 | GT6: 13885.9 | GU6: 12671.9 | GV6: 13813 | GW6: 14008.1 | GX6: 14328.6 | GY6: 14809.1 | GZ6: 14924.3 | HA6: 15086.9 | HB6: 15123.4 | HC6: 15219.9 | HD6: 15277.6 | HE6: 15324 | HF6: 15510.2 | HG6: 15548.5 | HH6: 15646.7 | HI6: 15781.4 | HJ6: 15856.9 | HK6: 15967.3 | HL6: 16113 | HM6: 16273.2 | HN6: 16291.8 | HO6: 16355.4
A7: jc | B7: 19.444 | C7: 19.659 | D7: 19.851 | E7: 20.108 | F7: 20.299 | G7: 20.53 | H7: 20.732 | I7: 20.86 | J7: 21.08 | K7: 21.202 | L7: 21.388 | M7: 21.562 | N7: 21.823 | O7: 22.242 | P7: 22.647 | Q7: 23.11 | R7: 23.798 | S7: 24.472 | T7: 25.132 | U7: 25.771 | V7: 26.256 | W7: 26.578 | X7: 27.076 | Y7: 27.53 | Z7: 27.833 | AA7: 28.066 | AB7: 28.492 | AC7: 28.942 | AD7: 29.465 | AE7: 29.969 | AF7: 30.42 | AG7: 30.852 | AH7: 31.358 | AI7: 32.002 | AJ7: 32.564 | AK7: 33.179 | AL7: 33.804 | AM7: 34.728 | AN7: 35.59 | AO7: 36.451 | AP7: 37.545 | AQ7: 38.464 | AR7: 39.364 | AS7: 40.338 | AT7: 41.384 | AU7: 42.078 | AV7: 42.772 | AW7: 43.427 | AX7: 43.979 | AY7: 44.402 | AZ7: 45.103 | BA7: 45.601 | BB7: 45.978 | BC7: 46.398 | BD7: 47.008 | BE7: 47.318 | BF7: 47.83 | BG7: 48.293 | BH7: 48.666 | BI7: 48.966 | BJ7: 49.544 | BK7: 49.945 | BL7: 50.337 | BM7: 50.688 | BN7: 51.047 | BO7: 50.993 | BP7: 51.263 | BQ7: 51.573 | BR7: 52.061 | BS7: 52.564 | BT7: 53.062 | BU7: 53.52 | BV7: 53.943 | BW7: 54.539 | BX7: 55.211 | BY7: 55.769 | BZ7: 56.41 | CA7: 57.17 | CB7: 57.507 | CC7: 57.959 | CD7: 58.799 | CE7: 59.333 | CF7: 60.087 | CG7: 60.882 | CH7: 61.202 | CI7: 61.536 | CJ7: 61.954 | CK7: 62.404 | CL7: 62.795 | CM7: 63.212 | CN7: 63.615 | CO7: 64.059 | CP7: 64.441 | CQ7: 64.874 | CR7: 65.155 | CS7: 65.531 | CT7: 65.766 | CU7: 66.133 | CV7: 66.607 | CW7: 66.92 | CX7: 67.247 | CY7: 67.639 | CZ7: 67.915 | DA7: 68.214 | DB7: 68.593 | DC7: 69.052 | DD7: 69.346 | DE7: 69.819 | DF7: 70.127 | DG7: 70.303 | DH7: 70.488 | DI7: 70.71 | DJ7: 70.715 | DK7: 70.843 | DL7: 71.062 | DM7: 71.249 | DN7: 71.39 | DO7: 71.796 | DP7: 72.191 | DQ7: 72.629 | DR7: 73.219 | DS7: 73.568 | DT7: 74.042 | DU7: 74.46 | DV7: 75.012 | DW7: 75.363 | DX7: 75.401 | DY7: 75.432 | DZ7: 75.584 | EA7: 76.145 | EB7: 76.539 | EC7: 76.896 | ED7: 77.484 | EE7: 77.562 | EF7: 78.073 | EG7: 78.457 | EH7: 79.062 | EI7: 79.594 | EJ7: 79.985 | EK7: 80.669 | EL7: 81.138 | EM7: 81.65 | EN7: 82.532 | EO7: 83.189 | EP7: 83.621 | EQ7: 84.355 | ER7: 84.962 | ES7: 84.822 | ET7: 85.597 | EU7: 86.324 | EV7: 86.812 | EW7: 87.694 | EX7: 88.408 | EY7: 89.269 | EZ7: 90.221 | FA7: 88.781 | FB7: 88.181 | FC7: 88.532 | FD7: 89.142 | FE7: 89.83 | FF7: 90.177 | FG7: 90.317 | FH7: 90.49 | FI7: 91.07 | FJ7: 91.835 | FK7: 92.738 | FL7: 93.167 | FM7: 93.475 | FN7: 94.094 | FO7: 94.321 | FP7: 94.595 | FQ7: 95.126 | FR7: 95.459 | FS7: 95.508 | FT7: 95.901 | FU7: 96.254 | FV7: 96.696 | FW7: 97.129 | FX7: 97.394 | FY7: 97.265 | FZ7: 96.829 | GA7: 97.312 | GB7: 97.565 | GC7: 97.49 | GD7: 97.538 | GE7: 98.157 | GF7: 98.496 | GG7: 98.947 | GH7: 99.524 | GI7: 99.724 | GJ7: 100.076 | GK7: 100.676 | GL7: 101.38 | GM7: 101.912 | GN7: 102.254 | GO7: 102.642 | GP7: 102.851 | GQ7: 103.426 | GR7: 103.675 | GS7: 104.083 | GT7: 104.404 | GU7: 103.988 | GV7: 104.832 | GW7: 105.34 | GX7: 106.529 | GY7: 108.188 | GZ7: 109.681 | HA7: 111.491 | HB7: 113.585 | HC7: 115.672 | HD7: 117.014 | HE7: 118.172 | HF7: 119.32 | HG7: 120.182 | HH7: 120.983 | HI7: 121.48 | HJ7: 122.507 | HK7: 123.275 | HL7: 123.747 | HM7: 124.478 | HN7: 125.601 | HO7: 126.227
A8: jgf | B8: 17.722 | C8: 17.956 | D8: 18.263 | E8: 18.495 | F8: 19.081 | G8: 19.437 | H8: 19.719 | I8: 20.122 | J8: 20.953 | K8: 21.166 | L8: 21.34 | M8: 21.804 | N8: 22.155 | O8: 22.54 | P8: 23.006 | Q8: 23.498 | R8: 23.739 | S8: 24.168 | T8: 24.874 | U8: 25.7 | V8: 26.167 | W8: 26.546 | X8: 26.904 | Y8: 27.522 | Z8: 27.924 | AA8: 28.158 | AB8: 28.481 | AC8: 29.242 | AD8: 29.656 | AE8: 29.993 | AF8: 30.141 | AG8: 31.014 | AH8: 31.369 | AI8: 31.985 | AJ8: 32.52 | AK8: 33.081 | AL8: 33.691 | AM8: 34.2 | AN8: 34.998 | AO8: 35.768 | AP8: 36.475 | AQ8: 37.885 | AR8: 38.269 | AS8: 39.421 | AT8: 40.209 | AU8: 41.144 | AV8: 42.046 | AW8: 42.852 | AX8: 43.536 | AY8: 44.399 | AZ8: 44.771 | BA8: 45.3 | BB8: 45.385 | BC8: 45.735 | BD8: 46.242 | BE8: 46.544 | BF8: 47.147 | BG8: 47.617 | BH8: 48.325 | BI8: 48.92 | BJ8: 48.725 | BK8: 48.84 | BL8: 49.101 | BM8: 49.423 | BN8: 49.298 | BO8: 49.175 | BP8: 49.245 | BQ8: 49.3 | BR8: 49.217 | BS8: 49.45 | BT8: 49.808 | BU8: 49.912 | BV8: 50.593 | BW8: 51.09 | BX8: 51.382 | BY8: 51.796 | BZ8: 52.18 | CA8: 52.563 | CB8: 52.825 | CC8: 53.014 | CD8: 53.386 | CE8: 54.303 | CF8: 54.376 | CG8: 55.023 | CH8: 55.517 | CI8: 55.79 | CJ8: 56.508 | CK8: 57.079 | CL8: 57.163 | CM8: 57.371 | CN8: 57.872 | CO8: 58.235 | CP8: 58.381 | CQ8: 58.637 | CR8: 59.062 | CS8: 59.591 | CT8: 59.865 | CU8: 60.367 | CV8: 60.713 | CW8: 61.212 | CX8: 61.728 | CY8: 62.139 | CZ8: 62.461 | DA8: 63.323 | DB8: 63.472 | DC8: 63.132 | DD8: 63.499 | DE8: 63.716 | DF8: 63.934 | DG8: 64.354 | DH8: 64.503 | DI8: 64.954 | DJ8: 64.682 | DK8: 65.099 | DL8: 65.524 | DM8: 65.735 | DN8: 65.947 | DO8: 66.503 | DP8: 67.106 | DQ8: 67.931 | DR8: 68.593 | DS8: 68.856 | DT8: 69.349 | DU8: 69.662 | DV8: 69.782 | DW8: 70.148 | DX8: 70.597 | DY8: 71.055 | DZ8: 71.515 | EA8: 72.191 | EB8: 72.811 | EC8: 74.161 | ED8: 74.965 | EE8: 75.499 | EF8: 76.182 | EG8: 76.752 | EH8: 77.405 | EI8: 78.077 | EJ8: 78.792 | EK8: 79.559 | EL8: 80.606 | EM8: 81.333 | EN8: 82.182 | EO8: 82.772 | EP8: 83.469 | EQ8: 84.051 | ER8: 84.673 | ES8: 85.114 | ET8: 85.842 | EU8: 86.528 | EV8: 87.124 | EW8: 87.822 | EX8: 88.563 | EY8: 89.47 | EZ8: 90.141 | FA8: 89.712 | FB8: 88.959 | FC8: 88.975 | FD8: 89.247 | FE8: 89.933 | FF8: 90.506 | FG8: 91.2 | FH8: 91.562 | FI8: 92.307 | FJ8: 93.136 | FK8: 93.979 | FL8: 94.306 | FM8: 94.18 | FN8: 94.506 | FO8: 94.715 | FP8: 94.897 | FQ8: 95.013 | FR8: 94.947 | FS8: 95.102 | FT8: 95.436 | FU8: 96.904 | FV8: 96.649 | FW8: 97.057 | FX8: 97.513 | FY8: 97.642 | FZ8: 97.452 | GA8: 97.641 | GB8: 97.73 | GC8: 97.611 | GD8: 97.503 | GE8: 98.022 | GF8: 98.404 | GG8: 98.891 | GH8: 99.36 | GI8: 99.682 | GJ8: 100.12 | GK8: 100.838 | GL8: 101.798 | GM8: 102.497 | GN8: 103.027 | GO8: 103.778 | GP8: 104.731 | GQ8: 104.034 | GR8: 104.131 | GS8: 104.51 | GT8: 104.826 | GU8: 104.893 | GV8: 105.466 | GW8: 106.253 | GX8: 107.069 | GY8: 108.223 | GZ8: 109.501 | HA8: 110.856 | HB8: 112.633 | HC8: 114.685 | HD8: 116.184 | HE8: 117.371 | HF8: 118.61 | HG8: 119.635 | HH8: 120.759 | HI8: 121.899 | HJ8: 122.967 | HK8: 123.825 | HL8: 124.576 | HM8: 125.398 | HN8: 127.141 | HO8: 129.343
A9: jgs | B9: 12.676 | C9: 12.944 | D9: 13.178 | E9: 13.428 | F9: 13.733 | G9: 13.981 | H9: 14.178 | I9: 14.333 | J9: 14.654 | K9: 14.827 | L9: 15.052 | M9: 15.259 | N9: 15.559 | O9: 15.836 | P9: 16.049 | Q9: 16.353 | R9: 16.828 | S9: 17.413 | T9: 18.048 | U9: 18.579 | V9: 18.953 | W9: 19.329 | X9: 19.576 | Y9: 19.826 | Z9: 20.05 | AA9: 20.293 | AB9: 20.444 | AC9: 20.689 | AD9: 21.079 | AE9: 21.456 | AF9: 21.821 | AG9: 22.189 | AH9: 22.503 | AI9: 22.879 | AJ9: 23.227 | AK9: 23.56 | AL9: 24.121 | AM9: 24.673 | AN9: 25.509 | AO9: 26.007 | AP9: 26.684 | AQ9: 27.417 | AR9: 28.208 | AS9: 28.976 | AT9: 29.917 | AU9: 30.562 | AV9: 30.977 | AW9: 31.466 | AX9: 31.997 | AY9: 32.511 | AZ9: 33.021 | BA9: 33.441 | BB9: 33.681 | BC9: 34.051 | BD9: 34.381 | BE9: 34.642 | BF9: 35.145 | BG9: 35.479 | BH9: 35.81 | BI9: 36.166 | BJ9: 36.593 | BK9: 36.953 | BL9: 37.259 | BM9: 37.604 | BN9: 37.76 | BO9: 37.927 | BP9: 38.255 | BQ9: 38.741 | BR9: 39.295 | BS9: 39.776 | BT9: 40.252 | BU9: 40.491 | BV9: 40.699 | BW9: 41.096 | BX9: 41.443 | BY9: 41.918 | BZ9: 42.469 | CA9: 43.046 | CB9: 43.45 | CC9: 44.011 | CD9: 44.634 | CE9: 45.094 | CF9: 45.707 | CG9: 46.427 | CH9: 46.622 | CI9: 46.904 | CJ9: 47.29 | CK9: 47.703 | CL9: 48.043 | CM9: 48.617 | CN9: 48.975 | CO9: 49.31 | CP9: 49.597 | CQ9: 49.889 | CR9: 50.031 | CS9: 50.283 | CT9: 50.694 | CU9: 50.975 | CV9: 51.421 | CW9: 51.857 | CX9: 52.146 | CY9: 52.542 | CZ9: 52.758 | DA9: 52.96 | DB9: 53.489 | DC9: 53.561 | DD9: 53.899 | DE9: 54.286 | DF9: 54.646 | DG9: 54.823 | DH9: 55.061 | DI9: 55.493 | DJ9: 55.567 | DK9: 55.813 | DL9: 56.231 | DM9: 56.701 | DN9: 57.135 | DO9: 57.909 | DP9: 58.604 | DQ9: 59.277 | DR9: 60.034 | DS9: 60.672 | DT9: 61.324 | DU9: 62.09 | DV9: 62.832 | DW9: 63.077 | DX9: 63.241 | DY9: 63.363 | DZ9: 63.736 | EA9: 64.311 | EB9: 64.778 | EC9: 65.325 | ED9: 66.256 | EE9: 66.307 | EF9: 66.747 | EG9: 67.273 | EH9: 68.131 | EI9: 69.108 | EJ9: 70.224 | EK9: 71.439 | EL9: 72.086 | EM9: 73.01 | EN9: 74.18 | EO9: 75.391 | EP9: 75.93 | EQ9: 77.103 | ER9: 77.886 | ES9: 78.708 | ET9: 80.214 | EU9: 81.083 | EV9: 81.971 | EW9: 83.146 | EX9: 84.486 | EY9: 85.669 | EZ9: 86.827 | FA9: 85.784 | FB9: 84.68 | FC9: 84.875 | FD9: 85.317 | FE9: 85.932 | FF9: 86.789 | FG9: 87.373 | FH9: 87.834 | FI9: 88.573 | FJ9: 89.474 | FK9: 90.562 | FL9: 91.025 | FM9: 90.913 | FN9: 92.015 | FO9: 92.024 | FP9: 92.572 | FQ9: 93.706 | FR9: 94.775 | FS9: 95.259 | FT9: 96.013 | FU9: 96.568 | FV9: 97.34 | FW9: 97.642 | FX9: 98.161 | FY9: 98.075 | FZ9: 97.174 | GA9: 97.783 | GB9: 97.845 | GC9: 97.467 | GD9: 96.685 | GE9: 97.416 | GF9: 97.722 | GG9: 98.198 | GH9: 99.104 | GI9: 99.283 | GJ9: 100.164 | GK9: 101.448 | GL9: 102.759 | GM9: 103.807 | GN9: 104.739 | GO9: 105.197 | GP9: 104.686 | GQ9: 105.473 | GR9: 105.887 | GS9: 106.506 | GT9: 107.881 | GU9: 107.74 | GV9: 109.033 | GW9: 110.37 | GX9: 112.819 | GY9: 115.044 | GZ9: 116.893 | HA9: 119.203 | HB9: 121.961 | HC9: 126.102 | HD9: 126.283 | HE9: 126.64 | HF9: 125.974 | HG9: 124.8 | HH9: 126.041 | HI9: 126.006 | HJ9: 127.205 | HK9: 127.72 | HL9: 128.476 | HM9: 129.044 | HN9: 130.293 | HO9: 130.63
